Workbook

Sheet Executive Summary
B2: THE PRICE OF WAITING
B3: Healthcare Service Utilization Workbook · Williams Favour Ifunanya · Favour's Analytics & Research
B4: Portfolio project · Synthetic data (180 visits, Jan–Sep 2026) · Excel
B6: TOTAL VISITS | C6: AVG WAIT (MIN) | D6: AVG TREATMENT COST | E6: AVG SATISFACTION | F6: FOLLOW-UP COMPLETION
B7: =COUNTA('Patient Data'!$A$2:$A$181) -> 180 | C7: =AVERAGE('Patient Data'!$J$2:$J$181) -> 48.116667 | D7: =AVERAGE('Patient Data'!$L$2:$L$181) -> 88563.322 | E7: =AVERAGE('Patient Data'!$O$2:$O$181) -> 4.3388889 | F7: =SUM('Patient Data'!$V$2:$V$181)/SUM('Patient Data'!$U$2:$U$181) -> 0.75
B9: THE OPERATIONAL QUESTION
B10: Where do waiting times, costs and missed follow-ups concentrate across departments and locations, does waiting cost patient satisfaction, and which fixes are worth testing first?
B12: WHAT THE DATA SAYS (live formulas)
B13: ="1. Waiting hurts: the correlation between waiting time and satisfaction is "&TEXT(Insights!D22,"0.00")&", and each extra 10 minutes goes with "&TEXT(ABS(Insights!D23),"0.00")&" points lower satisfaction." -> 1. Waiting hurts: the correlation between waiting time and satisfaction is -0.62, and each extra 10 minutes goes with 0.19 points lower satisfaction.
B14: ="2. Satisfaction falls from "&TEXT(Insights!E18,"0.0")&" for waits up to 30 minutes to "&TEXT(Insights!E21,"0.0")&" for waits over 90 minutes." -> 2. Satisfaction falls from 4.8 for waits up to 30 minutes to 3.5 for waits over 90 minutes.
B15: ="3. Hotspot: "&INDEX(Insights!B7:B12,MATCH(MAX(Insights!D7:D12),Insights!D7:D12,0))&" waits longest ("&TEXT(MAX(Insights!D7:D12),"0")&" min on average), and "&TEXT(INDEX(Insights!E7:E12,MATCH(MAX(Insights!D7:D12),Insights!D7:D12,0)),"0%")&" of its visits exceed the "&'Scenario Lab'!C5&"-minute limit." -> 3. Hotspot: Emergency waits longest (75 min on average), and 81% of its visits exceed the 60-minute limit.
B16: ="4. Follow-up gap: completion is "&TEXT(Insights!I13,"0%")&" overall, lowest in "&INDEX(Insights!B7:B12,MATCH(MIN(Insights!I7:I12),Insights!I7:I12,0))&" ("&TEXT(MIN(Insights!I7:I12),"0%")&") and in "&INDEX(Insights!B27:B31,MATCH(MIN(Insights!F27:F31),Insights!F27:F31,0))&" ("&TEXT(MIN(Insights!F27:F31),"0%")&")." -> 4. Follow-up gap: completion is 75% overall, lowest in General Medicine (61%) and in Gwarinpa (67%).
B17: ="5. Cost: "&INDEX(Insights!B7:B12,MATCH(MAX(Insights!G7:G12),Insights!G7:G12,0))&" averages ₦"&TEXT(MAX(Insights!G7:G12)/1000,"#,##0")&"K per visit, "&TEXT(MAX(Insights!G7:G12)/MIN(Insights!G7:G12),"0.0")&"x the cheapest department." -> 5. Cost: Surgery averages ₦221K per visit, 4.5x the cheapest department.
B18: ="6. Scorecard: "&COUNTIF(Insights!J7:J12,"RED")&" department(s) RED, "&COUNTIF(Insights!J7:J12,"AMBER")&" AMBER and "&COUNTIF(Insights!J7:J12,"GREEN")&" GREEN against the targets in the Scenario Lab." -> 6. Scorecard: 3 department(s) RED, 1 AMBER and 2 GREEN against the targets in the Scenario Lab.
B20: THREE RECOMMENDATIONS (tested in the Scenario Lab)
B21: Cut excess waiting where it concentrates | C21: ="Remove "&TEXT('Scenario Lab'!C6,"0%")&" of waiting above "&'Scenario Lab'!C5&" min: average wait falls "&TEXT('Scenario Lab'!C15,"0.0")&" min and satisfaction is predicted to rise about "&TEXT('Scenario Lab'!C20,"0.00")&" points (association-based estimate)." -> Remove 50% of waiting above 60 min: average wait falls 2.0 min and satisfaction is predicted to rise about 0.04 points (association-based estimate).
B22: Close the follow-up gap | C22: ="Reaching "&TEXT('Scenario Lab'!C7,"0%")&" completion needs "&'Scenario Lab'!F31&" more completed follow-ups. Start with reminders and scheduling in the lowest departments and locations." -> Reaching 75% completion needs 6 more completed follow-ups. Start with reminders and scheduling in the lowest departments and locations.
B23: Fix the data, then monitor monthly | C23: ="Review the "&COUNTIF('Patient Data'!$W$2:$W$181,"Review")&" flagged records, then track wait, satisfaction and follow-up completion each month against the targets." -> Review the 14 flagged records, then track wait, satisfaction and follow-up completion each month against the targets.
B25: WORKBOOK GUIDE (tap to jump)
B26: Dashboard | C26: Interactive KPIs and charts with Department, Location, Visit Type filters
B27: Insights | C27: Scorecard, waiting vs satisfaction, follow-up, hotspot map, trends, age and diagnosis
B28: Scenario Lab | C28: Set targets and test the waiting-time and follow-up fixes
B29: Patient Data | C29: 180 synthetic visits with calculated columns (filters on)
B30: Quality & Method | C30: Checks, what was added, limitations and privacy
B31: Data note: all records are synthetic and created for portfolio demonstration; no real patient data is used and this is not a clinical study.

Sheet Dashboard
B2: HEALTHCARE SERVICE UTILIZATION DASHBOARD
B3: Synthetic dataset · 180 visits · Jan–Sep 2026 · No real patient data · Use the yellow dropdowns to filter every KPI and chart
B5: DEPARTMENT | C5: All | E5: LOCATION | F5: All | H5: VISIT TYPE | I5: All | Q5: =IF($C$5="All","*",$C$5) -> *
Q6: =IF($F$5="All","*",$F$5) -> *
B7: TOTAL VISITS | D7: AVG WAIT (MIN) | F7: AVG TREATMENT COST | H7: AVG SATISFACTION | J7: FOLLOW-UP COMPLETION | L7: OVER WAIT LIMIT | Q7: =IF($I$5="All","*",$I$5) -> *
B8: =COUNTIFS('Patient Data'!$G$2:$G$181,$Q$5,'Patient Data'!$F$2:$F$181,$Q$6,'Patient Data'!$H$2:$H$181,$Q$7) -> 180 | D8: =IFERROR(AVERAGEIFS('Patient Data'!$J$2:$J$181,'Patient Data'!$G$2:$G$181,$Q$5,'Patient Data'!$F$2:$F$181,$Q$6,'Patient Data'!$H$2:$H$181,$Q$7),0) -> 48.116667 | F8: =IFERROR(AVERAGEIFS('Patient Data'!$L$2:$L$181,'Patient Data'!$G$2:$G$181,$Q$5,'Patient Data'!$F$2:$F$181,$Q$6,'Patient Data'!$H$2:$H$181,$Q$7),0) -> 88563.322 | H8: =IFERROR(AVERAGEIFS('Patient Data'!$O$2:$O$181,'Patient Data'!$G$2:$G$181,$Q$5,'Patient Data'!$F$2:$F$181,$Q$6,'Patient Data'!$H$2:$H$181,$Q$7),0) -> 4.3388889 | J8: =IFERROR(SUMIFS('Patient Data'!$V$2:$V$181,'Patient Data'!$G$2:$G$181,$Q$5,'Patient Data'!$F$2:$F$181,$Q$6,'Patient Data'!$H$2:$H$181,$Q$7)/SUMIFS('Patient Data'!$U$2:$U$181,'Patient Data'!$G$2:$G$181,$Q$5,'Patient Data'!$F$2:$F$181,$Q$6,'Patient Data'!$H$2:$H$181,$Q$7),0) -> 0.75 | L8: =IF(B8=0,0,SUMIFS('Patient Data'!$T$2:$T$181,'Patient Data'!$G$2:$G$181,$Q$5,'Patient Data'!$F$2:$F$181,$Q$6,'Patient Data'!$H$2:$H$181,$Q$7)/B8) -> 0.27222222
B9: ="Share of all visits: "&TEXT(B8/COUNTA('Patient Data'!$A$2:$A$181),"0%") -> Share of all visits: 100% | D9: ="Overall: "&TEXT(AVERAGE('Patient Data'!$J$2:$J$181),"0.0")&" min" -> Overall: 48.1 min | F9: ="Overall: ₦"&TEXT(AVERAGE('Patient Data'!$L$2:$L$181),"#,##0") -> Overall: ₦88,563 | H9: ="Overall: "&TEXT(AVERAGE('Patient Data'!$O$2:$O$181),"0.00")&" / 5" -> Overall: 4.34 / 5 | J9: ="Overall: "&TEXT(SUM('Patient Data'!$V$2:$V$181)/SUM('Patient Data'!$U$2:$U$181),"0%") -> Overall: 75% | L9: ="Limit: "&'Scenario Lab'!$C$5&" min · overall "&TEXT(SUM('Patient Data'!$T$2:$T$181)/COUNTA('Patient Data'!$A$2:$A$181),"0%") -> Limit: 60 min · overall 27%
B43: WHAT THE DATA SAYS (updates with your filters)
B44: =IF(SUM(C54:C62)=0,"No visits match this filter.","Rhythm: "&INDEX(B54:B62,MATCH(MAX(C54:C62),C54:C62,0))&" is the busiest month ("&MAX(C54:C62)&" visits) and "&INDEX(B54:B62,MATCH(MAX(D54:D62),D54:D62,0))&" has the longest average wait ("&TEXT(MAX(D54:D62),"0")&" min).") -> Rhythm: May is the busiest month (26 visits) and Apr has the longest average wait (60 min).
B45: =IF(SUM(H54:H57)=0,"","Waiting vs satisfaction: patients seen within 30 min rate care "&TEXT(I54,"0.0")&"; at 31–60 min "&TEXT(I55,"0.0")&"; at 61–90 min "&TEXT(I56,"0.0")&"; over 90 min "&TEXT(I57,"0.0")&" (0.0 = no visits in that band).") -> Waiting vs satisfaction: patients seen within 30 min rate care 4.8; at 31–60 min 4.4; at 61–90 min 3.9; over 90 min 3.5 (0.0 = no visits in that band).
B46: =IF(SUM(C65:C70)=0,"","Departments: "&INDEX(B65:B70,MATCH(MAX(D65:D70),D65:D70,0))&" has the longest average wait ("&TEXT(MAX(D65:D70),"0")&" min).") -> Departments: Emergency has the longest average wait (75 min).
B47: =IF(SUM(H65:H69)=0,"","Follow-up: completion ranges from "&TEXT(SMALL(I65:I69,COUNTIF(H65:H69,0)+1),"0%")&" to "&TEXT(MAX(I65:I69),"0%")&" across locations in this view.") -> Follow-up: completion ranges from 67% to 83% across locations in this view.
B52: CHART DATA (filter-driven · feeds the charts above)
B53: Month | C53: Visits | D53: Avg Wait (min) | E53: Avg Satisfaction | G53: Wait Band | H53: Visits | I53: Avg Satisfaction | J53: Share
A54: 1 | B54: Jan | C54: =COUNTIFS('Patient Data'!$G$2:$G$181,$Q$5,'Patient Data'!$F$2:$F$181,$Q$6,'Patient Data'!$H$2:$H$181,$Q$7,'Patient Data'!$Q$2:$Q$181,$A54) -> 14 | D54: =IFERROR(AVERAGEIFS('Patient Data'!$J$2:$J$181,'Patient Data'!$G$2:$G$181,$Q$5,'Patient Data'!$F$2:$F$181,$Q$6,'Patient Data'!$H$2:$H$181,$Q$7,'Patient Data'!$Q$2:$Q$181,$A54),0) -> 45.571429 | E54: =IFERROR(AVERAGEIFS('Patient Data'!$O$2:$O$181,'Patient Data'!$G$2:$G$181,$Q$5,'Patient Data'!$F$2:$F$181,$Q$6,'Patient Data'!$H$2:$H$181,$Q$7,'Patient Data'!$Q$2:$Q$181,$A54),0) -> 4.0714286 | G54: Up to 30 | H54: =COUNTIFS('Patient Data'!$G$2:$G$181,$Q$5,'Patient Data'!$F$2:$F$181,$Q$6,'Patient Data'!$H$2:$H$181,$Q$7,'Patient Data'!$S$2:$S$181,$G54) -> 41 | I54: =IFERROR(AVERAGEIFS('Patient Data'!$O$2:$O$181,'Patient Data'!$G$2:$G$181,$Q$5,'Patient Data'!$F$2:$F$181,$Q$6,'Patient Data'!$H$2:$H$181,$Q$7,'Patient Data'!$S$2:$S$181,$G54),0) -> 4.804878 | J54: =IF(SUM($H$54:$H$57)=0,0,H54/SUM($H$54:$H$57)) -> 0.22777778
A55: 2 | B55: Feb | C55: =COUNTIFS('Patient Data'!$G$2:$G$181,$Q$5,'Patient Data'!$F$2:$F$181,$Q$6,'Patient Data'!$H$2:$H$181,$Q$7,'Patient Data'!$Q$2:$Q$181,$A55) -> 17 | D55: =IFERROR(AVERAGEIFS('Patient Data'!$J$2:$J$181,'Patient Data'!$G$2:$G$181,$Q$5,'Patient Data'!$F$2:$F$181,$Q$6,'Patient Data'!$H$2:$H$181,$Q$7,'Patient Data'!$Q$2:$Q$181,$A55),0) -> 40.352941 | E55: =IFERROR(AVERAGEIFS('Patient Data'!$O$2:$O$181,'Patient Data'!$G$2:$G$181,$Q$5,'Patient Data'!$F$2:$F$181,$Q$6,'Patient Data'!$H$2:$H$181,$Q$7,'Patient Data'!$Q$2:$Q$181,$A55),0) -> 4.7058824 | G55: 31–60 | H55: =COUNTIFS('Patient Data'!$G$2:$G$181,$Q$5,'Patient Data'!$F$2:$F$181,$Q$6,'Patient Data'!$H$2:$H$181,$Q$7,'Patient Data'!$S$2:$S$181,$G55) -> 90 | I55: =IFERROR(AVERAGEIFS('Patient Data'!$O$2:$O$181,'Patient Data'!$G$2:$G$181,$Q$5,'Patient Data'!$F$2:$F$181,$Q$6,'Patient Data'!$H$2:$H$181,$Q$7,'Patient Data'!$S$2:$S$181,$G55),0) -> 4.3888889 | J55: =IF(SUM($H$54:$H$57)=0,0,H55/SUM($H$54:$H$57)) -> 0.5
A56: 3 | B56: Mar | C56: =COUNTIFS('Patient Data'!$G$2:$G$181,$Q$5,'Patient Data'!$F$2:$F$181,$Q$6,'Patient Data'!$H$2:$H$181,$Q$7,'Patient Data'!$Q$2:$Q$181,$A56) -> 22 | D56: =IFERROR(AVERAGEIFS('Patient Data'!$J$2:$J$181,'Patient Data'!$G$2:$G$181,$Q$5,'Patient Data'!$F$2:$F$181,$Q$6,'Patient Data'!$H$2:$H$181,$Q$7,'Patient Data'!$Q$2:$Q$181,$A56),0) -> 45.272727 | E56: =IFERROR(AVERAGEIFS('Patient Data'!$O$2:$O$181,'Patient Data'!$G$2:$G$181,$Q$5,'Patient Data'!$F$2:$F$181,$Q$6,'Patient Data'!$H$2:$H$181,$Q$7,'Patient Data'!$Q$2:$Q$181,$A56),0) -> 4.3181818 | G56: 61–90 | H56: =COUNTIFS('Patient Data'!$G$2:$G$181,$Q$5,'Patient Data'!$F$2:$F$181,$Q$6,'Patient Data'!$H$2:$H$181,$Q$7,'Patient Data'!$S$2:$S$181,$G56) -> 43 | I56: =IFERROR(AVERAGEIFS('Patient Data'!$O$2:$O$181,'Patient Data'!$G$2:$G$181,$Q$5,'Patient Data'!$F$2:$F$181,$Q$6,'Patient Data'!$H$2:$H$181,$Q$7,'Patient Data'!$S$2:$S$181,$G56),0) -> 3.9069767 | J56: =IF(SUM($H$54:$H$57)=0,0,H56/SUM($H$54:$H$57)) -> 0.23888889
A57: 4 | B57: Apr | C57: =COUNTIFS('Patient Data'!$G$2:$G$181,$Q$5,'Patient Data'!$F$2:$F$181,$Q$6,'Patient Data'!$H$2:$H$181,$Q$7,'Patient Data'!$Q$2:$Q$181,$A57) -> 15 | D57: =IFERROR(AVERAGEIFS('Patient Data'!$J$2:$J$181,'Patient Data'!$G$2:$G$181,$Q$5,'Patient Data'!$F$2:$F$181,$Q$6,'Patient Data'!$H$2:$H$181,$Q$7,'Patient Data'!$Q$2:$Q$181,$A57),0) -> 59.6 | E57: =IFERROR(AVERAGEIFS('Patient Data'!$O$2:$O$181,'Patient Data'!$G$2:$G$181,$Q$5,'Patient Data'!$F$2:$F$181,$Q$6,'Patient Data'!$H$2:$H$181,$Q$7,'Patient Data'!$Q$2:$Q$181,$A57),0) -> 4 | G57: Over 90 | H57: =COUNTIFS('Patient Data'!$G$2:$G$181,$Q$5,'Patient Data'!$F$2:$F$181,$Q$6,'Patient Data'!$H$2:$H$181,$Q$7,'Patient Data'!$S$2:$S$181,$G57) -> 6 | I57: =IFERROR(AVERAGEIFS('Patient Data'!$O$2:$O$181,'Patient Data'!$G$2:$G$181,$Q$5,'Patient Data'!$F$2:$F$181,$Q$6,'Patient Data'!$H$2:$H$181,$Q$7,'Patient Data'!$S$2:$S$181,$G57),0) -> 3.5 | J57: =IF(SUM($H$54:$H$57)=0,0,H57/SUM($H$54:$H$57)) -> 0.033333333
A58: 5 | B58: May | C58: =COUNTIFS('Patient Data'!$G$2:$G$181,$Q$5,'Patient Data'!$F$2:$F$181,$Q$6,'Patient Data'!$H$2:$H$181,$Q$7,'Patient Data'!$Q$2:$Q$181,$A58) -> 26 | D58: =IFERROR(AVERAGEIFS('Patient Data'!$J$2:$J$181,'Patient Data'!$G$2:$G$181,$Q$5,'Patient Data'!$F$2:$F$181,$Q$6,'Patient Data'!$H$2:$H$181,$Q$7,'Patient Data'!$Q$2:$Q$181,$A58),0) -> 55.269231 | E58: =IFERROR(AVERAGEIFS('Patient Data'!$O$2:$O$181,'Patient Data'!$G$2:$G$181,$Q$5,'Patient Data'!$F$2:$F$181,$Q$6,'Patient Data'!$H$2:$H$181,$Q$7,'Patient Data'!$Q$2:$Q$181,$A58),0) -> 4.3076923
A59: 6 | B59: Jun | C59: =COUNTIFS('Patient Data'!$G$2:$G$181,$Q$5,'Patient Data'!$F$2:$F$181,$Q$6,'Patient Data'!$H$2:$H$181,$Q$7,'Patient Data'!$Q$2:$Q$181,$A59) -> 18 | D59: =IFERROR(AVERAGEIFS('Patient Data'!$J$2:$J$181,'Patient Data'!$G$2:$G$181,$Q$5,'Patient Data'!$F$2:$F$181,$Q$6,'Patient Data'!$H$2:$H$181,$Q$7,'Patient Data'!$Q$2:$Q$181,$A59),0) -> 56 | E59: =IFERROR(AVERAGEIFS('Patient Data'!$O$2:$O$181,'Patient Data'!$G$2:$G$181,$Q$5,'Patient Data'!$F$2:$F$181,$Q$6,'Patient Data'!$H$2:$H$181,$Q$7,'Patient Data'!$Q$2:$Q$181,$A59),0) -> 4.1111111
A60: 7 | B60: Jul | C60: =COUNTIFS('Patient Data'!$G$2:$G$181,$Q$5,'Patient Data'!$F$2:$F$181,$Q$6,'Patient Data'!$H$2:$H$181,$Q$7,'Patient Data'!$Q$2:$Q$181,$A60) -> 21 | D60: =IFERROR(AVERAGEIFS('Patient Data'!$J$2:$J$181,'Patient Data'!$G$2:$G$181,$Q$5,'Patient Data'!$F$2:$F$181,$Q$6,'Patient Data'!$H$2:$H$181,$Q$7,'Patient Data'!$Q$2:$Q$181,$A60),0) -> 44.52381 | E60: =IFERROR(AVERAGEIFS('Patient Data'!$O$2:$O$181,'Patient Data'!$G$2:$G$181,$Q$5,'Patient Data'!$F$2:$F$181,$Q$6,'Patient Data'!$H$2:$H$181,$Q$7,'Patient Data'!$Q$2:$Q$181,$A60),0) -> 4.5238095
A61: 8 | B61: Aug | C61: =COUNTIFS('Patient Data'!$G$2:$G$181,$Q$5,'Patient Data'!$F$2:$F$181,$Q$6,'Patient Data'!$H$2:$H$181,$Q$7,'Patient Data'!$Q$2:$Q$181,$A61) -> 25 | D61: =IFERROR(AVERAGEIFS('Patient Data'!$J$2:$J$181,'Patient Data'!$G$2:$G$181,$Q$5,'Patient Data'!$F$2:$F$181,$Q$6,'Patient Data'!$H$2:$H$181,$Q$7,'Patient Data'!$Q$2:$Q$181,$A61),0) -> 44.44 | E61: =IFERROR(AVERAGEIFS('Patient Data'!$O$2:$O$181,'Patient Data'!$G$2:$G$181,$Q$5,'Patient Data'!$F$2:$F$181,$Q$6,'Patient Data'!$H$2:$H$181,$Q$7,'Patient Data'!$Q$2:$Q$181,$A61),0) -> 4.4
A62: 9 | B62: Sep | C62: =COUNTIFS('Patient Data'!$G$2:$G$181,$Q$5,'Patient Data'!$F$2:$F$181,$Q$6,'Patient Data'!$H$2:$H$181,$Q$7,'Patient Data'!$Q$2:$Q$181,$A62) -> 22 | D62: =IFERROR(AVERAGEIFS('Patient Data'!$J$2:$J$181,'Patient Data'!$G$2:$G$181,$Q$5,'Patient Data'!$F$2:$F$181,$Q$6,'Patient Data'!$H$2:$H$181,$Q$7,'Patient Data'!$Q$2:$Q$181,$A62),0) -> 43.454545 | E62: =IFERROR(AVERAGEIFS('Patient Data'!$O$2:$O$181,'Patient Data'!$G$2:$G$181,$Q$5,'Patient Data'!$F$2:$F$181,$Q$6,'Patient Data'!$H$2:$H$181,$Q$7,'Patient Data'!$Q$2:$Q$181,$A62),0) -> 4.4545455
B64: Department | C64: Visits | D64: Avg Wait (min) | E64: Avg Satisfaction | G64: Location | H64: Visits | I64: Follow-up Completion | J64: Avg Wait (min)
B65: Emergency | C65: =COUNTIFS('Patient Data'!$F$2:$F$181,$Q$6,'Patient Data'!$H$2:$H$181,$Q$7,'Patient Data'!$G$2:$G$181,$B65) -> 27 | D65: =IFERROR(AVERAGEIFS('Patient Data'!$J$2:$J$181,'Patient Data'!$F$2:$F$181,$Q$6,'Patient Data'!$H$2:$H$181,$Q$7,'Patient Data'!$G$2:$G$181,$B65),0) -> 74.962963 | E65: =IFERROR(AVERAGEIFS('Patient Data'!$O$2:$O$181,'Patient Data'!$F$2:$F$181,$Q$6,'Patient Data'!$H$2:$H$181,$Q$7,'Patient Data'!$G$2:$G$181,$B65),0) -> 4 | G65: Abuja | H65: =COUNTIFS('Patient Data'!$G$2:$G$181,$Q$5,'Patient Data'!$H$2:$H$181,$Q$7,'Patient Data'!$F$2:$F$181,$G65) -> 39 | I65: =IFERROR(SUMIFS('Patient Data'!$V$2:$V$181,'Patient Data'!$G$2:$G$181,$Q$5,'Patient Data'!$H$2:$H$181,$Q$7,'Patient Data'!$F$2:$F$181,$G65)/SUMIFS('Patient Data'!$U$2:$U$181,'Patient Data'!$G$2:$G$181,$Q$5,'Patient Data'!$H$2:$H$181,$Q$7,'Patient Data'!$F$2:$F$181,$G65),0) -> 0.82608696 | J65: =IFERROR(AVERAGEIFS('Patient Data'!$J$2:$J$181,'Patient Data'!$G$2:$G$181,$Q$5,'Patient Data'!$H$2:$H$181,$Q$7,'Patient Data'!$F$2:$F$181,$G65),0) -> 45.717949
B66: General Medicine | C66: =COUNTIFS('Patient Data'!$F$2:$F$181,$Q$6,'Patient Data'!$H$2:$H$181,$Q$7,'Patient Data'!$G$2:$G$181,$B66) -> 41 | D66: =IFERROR(AVERAGEIFS('Patient Data'!$J$2:$J$181,'Patient Data'!$F$2:$F$181,$Q$6,'Patient Data'!$H$2:$H$181,$Q$7,'Patient Data'!$G$2:$G$181,$B66),0) -> 46.731707 | E66: =IFERROR(AVERAGEIFS('Patient Data'!$O$2:$O$181,'Patient Data'!$F$2:$F$181,$Q$6,'Patient Data'!$H$2:$H$181,$Q$7,'Patient Data'!$G$2:$G$181,$B66),0) -> 4.3170732 | G66: Gwarinpa | H66: =COUNTIFS('Patient Data'!$G$2:$G$181,$Q$5,'Patient Data'!$H$2:$H$181,$Q$7,'Patient Data'!$F$2:$F$181,$G66) -> 31 | I66: =IFERROR(SUMIFS('Patient Data'!$V$2:$V$181,'Patient Data'!$G$2:$G$181,$Q$5,'Patient Data'!$H$2:$H$181,$Q$7,'Patient Data'!$F$2:$F$181,$G66)/SUMIFS('Patient Data'!$U$2:$U$181,'Patient Data'!$G$2:$G$181,$Q$5,'Patient Data'!$H$2:$H$181,$Q$7,'Patient Data'!$F$2:$F$181,$G66),0) -> 0.66666667 | J66: =IFERROR(AVERAGEIFS('Patient Data'!$J$2:$J$181,'Patient Data'!$G$2:$G$181,$Q$5,'Patient Data'!$H$2:$H$181,$Q$7,'Patient Data'!$F$2:$F$181,$G66),0) -> 58.193548
B67: Maternal Health | C67: =COUNTIFS('Patient Data'!$F$2:$F$181,$Q$6,'Patient Data'!$H$2:$H$181,$Q$7,'Patient Data'!$G$2:$G$181,$B67) -> 26 | D67: =IFERROR(AVERAGEIFS('Patient Data'!$J$2:$J$181,'Patient Data'!$F$2:$F$181,$Q$6,'Patient Data'!$H$2:$H$181,$Q$7,'Patient Data'!$G$2:$G$181,$B67),0) -> 49 | E67: =IFERROR(AVERAGEIFS('Patient Data'!$O$2:$O$181,'Patient Data'!$F$2:$F$181,$Q$6,'Patient Data'!$H$2:$H$181,$Q$7,'Patient Data'!$G$2:$G$181,$B67),0) -> 4.3076923 | G67: Kubwa | H67: =COUNTIFS('Patient Data'!$G$2:$G$181,$Q$5,'Patient Data'!$H$2:$H$181,$Q$7,'Patient Data'!$F$2:$F$181,$G67) -> 34 | I67: =IFERROR(SUMIFS('Patient Data'!$V$2:$V$181,'Patient Data'!$G$2:$G$181,$Q$5,'Patient Data'!$H$2:$H$181,$Q$7,'Patient Data'!$F$2:$F$181,$G67)/SUMIFS('Patient Data'!$U$2:$U$181,'Patient Data'!$G$2:$G$181,$Q$5,'Patient Data'!$H$2:$H$181,$Q$7,'Patient Data'!$F$2:$F$181,$G67),0) -> 0.7826087 | J67: =IFERROR(AVERAGEIFS('Patient Data'!$J$2:$J$181,'Patient Data'!$G$2:$G$181,$Q$5,'Patient Data'!$H$2:$H$181,$Q$7,'Patient Data'!$F$2:$F$181,$G67),0) -> 38.176471
B68: Outpatient | C68: =COUNTIFS('Patient Data'!$F$2:$F$181,$Q$6,'Patient Data'!$H$2:$H$181,$Q$7,'Patient Data'!$G$2:$G$181,$B68) -> 41 | D68: =IFERROR(AVERAGEIFS('Patient Data'!$J$2:$J$181,'Patient Data'!$F$2:$F$181,$Q$6,'Patient Data'!$H$2:$H$181,$Q$7,'Patient Data'!$G$2:$G$181,$B68),0) -> 34.829268 | E68: =IFERROR(AVERAGEIFS('Patient Data'!$O$2:$O$181,'Patient Data'!$F$2:$F$181,$Q$6,'Patient Data'!$H$2:$H$181,$Q$7,'Patient Data'!$G$2:$G$181,$B68),0) -> 4.5609756 | G68: Kuje | H68: =COUNTIFS('Patient Data'!$G$2:$G$181,$Q$5,'Patient Data'!$H$2:$H$181,$Q$7,'Patient Data'!$F$2:$F$181,$G68) -> 34 | I68: =IFERROR(SUMIFS('Patient Data'!$V$2:$V$181,'Patient Data'!$G$2:$G$181,$Q$5,'Patient Data'!$H$2:$H$181,$Q$7,'Patient Data'!$F$2:$F$181,$G68)/SUMIFS('Patient Data'!$U$2:$U$181,'Patient Data'!$G$2:$G$181,$Q$5,'Patient Data'!$H$2:$H$181,$Q$7,'Patient Data'!$F$2:$F$181,$G68),0) -> 0.66666667 | J68: =IFERROR(AVERAGEIFS('Patient Data'!$J$2:$J$181,'Patient Data'!$G$2:$G$181,$Q$5,'Patient Data'!$H$2:$H$181,$Q$7,'Patient Data'!$F$2:$F$181,$G68),0) -> 46.294118
B69: Pediatrics | C69: =COUNTIFS('Patient Data'!$F$2:$F$181,$Q$6,'Patient Data'!$H$2:$H$181,$Q$7,'Patient Data'!$G$2:$G$181,$B69) -> 30 | D69: =IFERROR(AVERAGEIFS('Patient Data'!$J$2:$J$181,'Patient Data'!$F$2:$F$181,$Q$6,'Patient Data'!$H$2:$H$181,$Q$7,'Patient Data'!$G$2:$G$181,$B69),0) -> 37.1 | E69: =IFERROR(AVERAGEIFS('Patient Data'!$O$2:$O$181,'Patient Data'!$F$2:$F$181,$Q$6,'Patient Data'!$H$2:$H$181,$Q$7,'Patient Data'!$G$2:$G$181,$B69),0) -> 4.6333333 | G69: Nyanya | H69: =COUNTIFS('Patient Data'!$G$2:$G$181,$Q$5,'Patient Data'!$H$2:$H$181,$Q$7,'Patient Data'!$F$2:$F$181,$G69) -> 42 | I69: =IFERROR(SUMIFS('Patient Data'!$V$2:$V$181,'Patient Data'!$G$2:$G$181,$Q$5,'Patient Data'!$H$2:$H$181,$Q$7,'Patient Data'!$F$2:$F$181,$G69)/SUMIFS('Patient Data'!$U$2:$U$181,'Patient Data'!$G$2:$G$181,$Q$5,'Patient Data'!$H$2:$H$181,$Q$7,'Patient Data'!$F$2:$F$181,$G69),0) -> 0.7826087 | J69: =IFERROR(AVERAGEIFS('Patient Data'!$J$2:$J$181,'Patient Data'!$G$2:$G$181,$Q$5,'Patient Data'!$H$2:$H$181,$Q$7,'Patient Data'!$F$2:$F$181,$G69),0) -> 52.428571
B70: Surgery | C70: =COUNTIFS('Patient Data'!$F$2:$F$181,$Q$6,'Patient Data'!$H$2:$H$181,$Q$7,'Patient Data'!$G$2:$G$181,$B70) -> 15 | D70: =IFERROR(AVERAGEIFS('Patient Data'!$J$2:$J$181,'Patient Data'!$F$2:$F$181,$Q$6,'Patient Data'!$H$2:$H$181,$Q$7,'Patient Data'!$G$2:$G$181,$B70),0) -> 60.4 | E70: =IFERROR(AVERAGEIFS('Patient Data'!$O$2:$O$181,'Patient Data'!$F$2:$F$181,$Q$6,'Patient Data'!$H$2:$H$181,$Q$7,'Patient Data'!$G$2:$G$181,$B70),0) -> 3.8666667

Sheet Insights
B2: INSIGHTS · Where waiting, cost and follow-up gaps concentrate
B3: Whole-dataset analysis (not filtered). Every number is a live formula on the Patient Data tab; targets come from the Scenario Lab.
B5: 1 · Department scorecard (RAG status against Scenario Lab targets)
B6: Department | C6: Visits | D6: Avg Wait (min) | E6: % Over Wait Limit | F6: Avg Satisfaction | G6: Avg Cost | H6: Follow-ups Due | I6: Follow-up Completion | J6: Status
B7: Emergency | C7: =COUNTIFS('Patient Data'!$G$2:$G$181,$B7) -> 27 | D7: =AVERAGEIFS('Patient Data'!$J$2:$J$181,'Patient Data'!$G$2:$G$181,$B7) -> 74.962963 | E7: =SUMIFS('Patient Data'!$T$2:$T$181,'Patient Data'!$G$2:$G$181,$B7)/C7 -> 0.81481481 | F7: =AVERAGEIFS('Patient Data'!$O$2:$O$181,'Patient Data'!$G$2:$G$181,$B7) -> 4 | G7: =AVERAGEIFS('Patient Data'!$L$2:$L$181,'Patient Data'!$G$2:$G$181,$B7) -> 116318.19 | H7: =SUMIFS('Patient Data'!$U$2:$U$181,'Patient Data'!$G$2:$G$181,$B7) -> 13 | I7: =IF(H7=0,0,SUMIFS('Patient Data'!$V$2:$V$181,'Patient Data'!$G$2:$G$181,$B7)/H7) -> 0.84615385 | J7: =IF((F7<'Scenario Lab'!$C$8)+(I7<'Scenario Lab'!$C$7)+(E7>'Scenario Lab'!$C$9)=0,"GREEN",IF((F7<'Scenario Lab'!$C$8)+(I7<'Scenario Lab'!$C$7)+(E7>'Scenario Lab'!$C$9)=1,"AMBER","RED")) -> RED
B8: General Medicine | C8: =COUNTIFS('Patient Data'!$G$2:$G$181,$B8) -> 41 | D8: =AVERAGEIFS('Patient Data'!$J$2:$J$181,'Patient Data'!$G$2:$G$181,$B8) -> 46.731707 | E8: =SUMIFS('Patient Data'!$T$2:$T$181,'Patient Data'!$G$2:$G$181,$B8)/C8 -> 0.2195122 | F8: =AVERAGEIFS('Patient Data'!$O$2:$O$181,'Patient Data'!$G$2:$G$181,$B8) -> 4.3170732 | G8: =AVERAGEIFS('Patient Data'!$L$2:$L$181,'Patient Data'!$G$2:$G$181,$B8) -> 71076.927 | H8: =SUMIFS('Patient Data'!$U$2:$U$181,'Patient Data'!$G$2:$G$181,$B8) -> 23 | I8: =IF(H8=0,0,SUMIFS('Patient Data'!$V$2:$V$181,'Patient Data'!$G$2:$G$181,$B8)/H8) -> 0.60869565 | J8: =IF((F8<'Scenario Lab'!$C$8)+(I8<'Scenario Lab'!$C$7)+(E8>'Scenario Lab'!$C$9)=0,"GREEN",IF((F8<'Scenario Lab'!$C$8)+(I8<'Scenario Lab'!$C$7)+(E8>'Scenario Lab'!$C$9)=1,"AMBER","RED")) -> RED
B9: Maternal Health | C9: =COUNTIFS('Patient Data'!$G$2:$G$181,$B9) -> 26 | D9: =AVERAGEIFS('Patient Data'!$J$2:$J$181,'Patient Data'!$G$2:$G$181,$B9) -> 49 | E9: =SUMIFS('Patient Data'!$T$2:$T$181,'Patient Data'!$G$2:$G$181,$B9)/C9 -> 0.19230769 | F9: =AVERAGEIFS('Patient Data'!$O$2:$O$181,'Patient Data'!$G$2:$G$181,$B9) -> 4.3076923 | G9: =AVERAGEIFS('Patient Data'!$L$2:$L$181,'Patient Data'!$G$2:$G$181,$B9) -> 99431.462 | H9: =SUMIFS('Patient Data'!$U$2:$U$181,'Patient Data'!$G$2:$G$181,$B9) -> 17 | I9: =IF(H9=0,0,SUMIFS('Patient Data'!$V$2:$V$181,'Patient Data'!$G$2:$G$181,$B9)/H9) -> 0.76470588 | J9: =IF((F9<'Scenario Lab'!$C$8)+(I9<'Scenario Lab'!$C$7)+(E9>'Scenario Lab'!$C$9)=0,"GREEN",IF((F9<'Scenario Lab'!$C$8)+(I9<'Scenario Lab'!$C$7)+(E9>'Scenario Lab'!$C$9)=1,"AMBER","RED")) -> GREEN
B10: Outpatient | C10: =COUNTIFS('Patient Data'!$G$2:$G$181,$B10) -> 41 | D10: =AVERAGEIFS('Patient Data'!$J$2:$J$181,'Patient Data'!$G$2:$G$181,$B10) -> 34.829268 | E10: =SUMIFS('Patient Data'!$T$2:$T$181,'Patient Data'!$G$2:$G$181,$B10)/C10 -> 0.024390244 | F10: =AVERAGEIFS('Patient Data'!$O$2:$O$181,'Patient Data'!$G$2:$G$181,$B10) -> 4.5609756 | G10: =AVERAGEIFS('Patient Data'!$L$2:$L$181,'Patient Data'!$G$2:$G$181,$B10) -> 49574.756 | H10: =SUMIFS('Patient Data'!$U$2:$U$181,'Patient Data'!$G$2:$G$181,$B10) -> 27 | I10: =IF(H10=0,0,SUMIFS('Patient Data'!$V$2:$V$181,'Patient Data'!$G$2:$G$181,$B10)/H10) -> 0.7037037 | J10: =IF((F10<'Scenario Lab'!$C$8)+(I10<'Scenario Lab'!$C$7)+(E10>'Scenario Lab'!$C$9)=0,"GREEN",IF((F10<'Scenario Lab'!$C$8)+(I10<'Scenario Lab'!$C$7)+(E10>'Scenario Lab'!$C$9)=1,"AMBER","RED")) -> AMBER
B11: Pediatrics | C11: =COUNTIFS('Patient Data'!$G$2:$G$181,$B11) -> 30 | D11: =AVERAGEIFS('Patient Data'!$J$2:$J$181,'Patient Data'!$G$2:$G$181,$B11) -> 37.1 | E11: =SUMIFS('Patient Data'!$T$2:$T$181,'Patient Data'!$G$2:$G$181,$B11)/C11 -> 0.13333333 | F11: =AVERAGEIFS('Patient Data'!$O$2:$O$181,'Patient Data'!$G$2:$G$181,$B11) -> 4.6333333 | G11: =AVERAGEIFS('Patient Data'!$L$2:$L$181,'Patient Data'!$G$2:$G$181,$B11) -> 65194.767 | H11: =SUMIFS('Patient Data'!$U$2:$U$181,'Patient Data'!$G$2:$G$181,$B11) -> 18 | I11: =IF(H11=0,0,SUMIFS('Patient Data'!$V$2:$V$181,'Patient Data'!$G$2:$G$181,$B11)/H11) -> 0.77777778 | J11: =IF((F11<'Scenario Lab'!$C$8)+(I11<'Scenario Lab'!$C$7)+(E11>'Scenario Lab'!$C$9)=0,"GREEN",IF((F11<'Scenario Lab'!$C$8)+(I11<'Scenario Lab'!$C$7)+(E11>'Scenario Lab'!$C$9)=1,"AMBER","RED")) -> GREEN
B12: Surgery | C12: =COUNTIFS('Patient Data'!$G$2:$G$181,$B12) -> 15 | D12: =AVERAGEIFS('Patient Data'!$J$2:$J$181,'Patient Data'!$G$2:$G$181,$B12) -> 60.4 | E12: =SUMIFS('Patient Data'!$T$2:$T$181,'Patient Data'!$G$2:$G$181,$B12)/C12 -> 0.53333333 | F12: =AVERAGEIFS('Patient Data'!$O$2:$O$181,'Patient Data'!$G$2:$G$181,$B12) -> 3.8666667 | G12: =AVERAGEIFS('Patient Data'!$L$2:$L$181,'Patient Data'!$G$2:$G$181,$B12) -> 220868.47 | H12: =SUMIFS('Patient Data'!$U$2:$U$181,'Patient Data'!$G$2:$G$181,$B12) -> 10 | I12: =IF(H12=0,0,SUMIFS('Patient Data'!$V$2:$V$181,'Patient Data'!$G$2:$G$181,$B12)/H12) -> 1 | J12: =IF((F12<'Scenario Lab'!$C$8)+(I12<'Scenario Lab'!$C$7)+(E12>'Scenario Lab'!$C$9)=0,"GREEN",IF((F12<'Scenario Lab'!$C$8)+(I12<'Scenario Lab'!$C$7)+(E12>'Scenario Lab'!$C$9)=1,"AMBER","RED")) -> RED
B13: All departments | C13: =SUM(C7:C12) -> 180 | D13: =AVERAGE('Patient Data'!$J$2:$J$181) -> 48.116667 | E13: =SUM('Patient Data'!$T$2:$T$181)/C13 -> 0.27222222 | F13: =AVERAGE('Patient Data'!$O$2:$O$181) -> 4.3388889 | G13: =AVERAGE('Patient Data'!$L$2:$L$181) -> 88563.322 | H13: =SUM(H7:H12) -> 108 | I13: =SUM('Patient Data'!$V$2:$V$181)/H13 -> 0.75
B14: Status = number of targets missed: satisfaction below target, follow-up completion below target, or too many visits over the wait limit (0 = GREEN, 1 = AMBER, 2+ = RED).
B16: 2 · Does waiting cost satisfaction?
B17: Wait Band (min) | C17: Visits | D17: Share of Visits | E17: Avg Satisfaction | F17: Avg Cost | G17: Follow-up Completion
B18: Up to 30 | C18: =COUNTIFS('Patient Data'!$S$2:$S$181,$B18) -> 41 | D18: =C18/COUNTA('Patient Data'!$A$2:$A$181) -> 0.22777778 | E18: =AVERAGEIFS('Patient Data'!$O$2:$O$181,'Patient Data'!$S$2:$S$181,$B18) -> 4.804878 | F18: =AVERAGEIFS('Patient Data'!$L$2:$L$181,'Patient Data'!$S$2:$S$181,$B18) -> 66293.756 | G18: =IFERROR(SUMIFS('Patient Data'!$V$2:$V$181,'Patient Data'!$S$2:$S$181,$B18)/SUMIFS('Patient Data'!$U$2:$U$181,'Patient Data'!$S$2:$S$181,$B18),0) -> 0.73913043
B19: 31–60 | C19: =COUNTIFS('Patient Data'!$S$2:$S$181,$B19) -> 90 | D19: =C19/COUNTA('Patient Data'!$A$2:$A$181) -> 0.5 | E19: =AVERAGEIFS('Patient Data'!$O$2:$O$181,'Patient Data'!$S$2:$S$181,$B19) -> 4.3888889 | F19: =AVERAGEIFS('Patient Data'!$L$2:$L$181,'Patient Data'!$S$2:$S$181,$B19) -> 86118.2 | G19: =IFERROR(SUMIFS('Patient Data'!$V$2:$V$181,'Patient Data'!$S$2:$S$181,$B19)/SUMIFS('Patient Data'!$U$2:$U$181,'Patient Data'!$S$2:$S$181,$B19),0) -> 0.68333333
B20: 61–90 | C20: =COUNTIFS('Patient Data'!$S$2:$S$181,$B20) -> 43 | D20: =C20/COUNTA('Patient Data'!$A$2:$A$181) -> 0.23888889 | E20: =AVERAGEIFS('Patient Data'!$O$2:$O$181,'Patient Data'!$S$2:$S$181,$B20) -> 3.9069767 | F20: =AVERAGEIFS('Patient Data'!$L$2:$L$181,'Patient Data'!$S$2:$S$181,$B20) -> 110495.33 | G20: =IFERROR(SUMIFS('Patient Data'!$V$2:$V$181,'Patient Data'!$S$2:$S$181,$B20)/SUMIFS('Patient Data'!$U$2:$U$181,'Patient Data'!$S$2:$S$181,$B20),0) -> 0.9047619
B21: Over 90 | C21: =COUNTIFS('Patient Data'!$S$2:$S$181,$B21) -> 6 | D21: =C21/COUNTA('Patient Data'!$A$2:$A$181) -> 0.033333333 | E21: =AVERAGEIFS('Patient Data'!$O$2:$O$181,'Patient Data'!$S$2:$S$181,$B21) -> 3.5 | F21: =AVERAGEIFS('Patient Data'!$L$2:$L$181,'Patient Data'!$S$2:$S$181,$B21) -> 120236.17 | G21: =IFERROR(SUMIFS('Patient Data'!$V$2:$V$181,'Patient Data'!$S$2:$S$181,$B21)/SUMIFS('Patient Data'!$U$2:$U$181,'Patient Data'!$S$2:$S$181,$B21),0) -> 1
B22: Correlation: wait vs satisfaction | D22: =CORREL('Patient Data'!$J$2:$J$181,'Patient Data'!$O$2:$O$181) -> -0.61578341 | E22: Association in a synthetic sample, not proof of cause. Scores only range 3–5.
B23: Satisfaction change per extra 10 min | D23: =SLOPE('Patient Data'!$O$2:$O$181,'Patient Data'!$J$2:$J$181)*10 -> -0.18660152
B25: 3 · Follow-up completion by location
B26: Location | C26: Visits | D26: Follow-ups Due | E26: Completed | F26: Completion | G26: Avg Wait (min) | H26: Avg Satisfaction
B27: Abuja | C27: =COUNTIFS('Patient Data'!$F$2:$F$181,$B27) -> 39 | D27: =SUMIFS('Patient Data'!$U$2:$U$181,'Patient Data'!$F$2:$F$181,$B27) -> 23 | E27: =SUMIFS('Patient Data'!$V$2:$V$181,'Patient Data'!$F$2:$F$181,$B27) -> 19 | F27: =IF(D27=0,0,E27/D27) -> 0.82608696 | G27: =AVERAGEIFS('Patient Data'!$J$2:$J$181,'Patient Data'!$F$2:$F$181,$B27) -> 45.717949 | H27: =AVERAGEIFS('Patient Data'!$O$2:$O$181,'Patient Data'!$F$2:$F$181,$B27) -> 4.3846154
B28: Gwarinpa | C28: =COUNTIFS('Patient Data'!$F$2:$F$181,$B28) -> 31 | D28: =SUMIFS('Patient Data'!$U$2:$U$181,'Patient Data'!$F$2:$F$181,$B28) -> 18 | E28: =SUMIFS('Patient Data'!$V$2:$V$181,'Patient Data'!$F$2:$F$181,$B28) -> 12 | F28: =IF(D28=0,0,E28/D28) -> 0.66666667 | G28: =AVERAGEIFS('Patient Data'!$J$2:$J$181,'Patient Data'!$F$2:$F$181,$B28) -> 58.193548 | H28: =AVERAGEIFS('Patient Data'!$O$2:$O$181,'Patient Data'!$F$2:$F$181,$B28) -> 4.3225806
B29: Kubwa | C29: =COUNTIFS('Patient Data'!$F$2:$F$181,$B29) -> 34 | D29: =SUMIFS('Patient Data'!$U$2:$U$181,'Patient Data'!$F$2:$F$181,$B29) -> 23 | E29: =SUMIFS('Patient Data'!$V$2:$V$181,'Patient Data'!$F$2:$F$181,$B29) -> 18 | F29: =IF(D29=0,0,E29/D29) -> 0.7826087 | G29: =AVERAGEIFS('Patient Data'!$J$2:$J$181,'Patient Data'!$F$2:$F$181,$B29) -> 38.176471 | H29: =AVERAGEIFS('Patient Data'!$O$2:$O$181,'Patient Data'!$F$2:$F$181,$B29) -> 4.3823529
B30: Kuje | C30: =COUNTIFS('Patient Data'!$F$2:$F$181,$B30) -> 34 | D30: =SUMIFS('Patient Data'!$U$2:$U$181,'Patient Data'!$F$2:$F$181,$B30) -> 21 | E30: =SUMIFS('Patient Data'!$V$2:$V$181,'Patient Data'!$F$2:$F$181,$B30) -> 14 | F30: =IF(D30=0,0,E30/D30) -> 0.66666667 | G30: =AVERAGEIFS('Patient Data'!$J$2:$J$181,'Patient Data'!$F$2:$F$181,$B30) -> 46.294118 | H30: =AVERAGEIFS('Patient Data'!$O$2:$O$181,'Patient Data'!$F$2:$F$181,$B30) -> 4.3823529
B31: Nyanya | C31: =COUNTIFS('Patient Data'!$F$2:$F$181,$B31) -> 42 | D31: =SUMIFS('Patient Data'!$U$2:$U$181,'Patient Data'!$F$2:$F$181,$B31) -> 23 | E31: =SUMIFS('Patient Data'!$V$2:$V$181,'Patient Data'!$F$2:$F$181,$B31) -> 18 | F31: =IF(D31=0,0,E31/D31) -> 0.7826087 | G31: =AVERAGEIFS('Patient Data'!$J$2:$J$181,'Patient Data'!$F$2:$F$181,$B31) -> 52.428571 | H31: =AVERAGEIFS('Patient Data'!$O$2:$O$181,'Patient Data'!$F$2:$F$181,$B31) -> 4.2380952
B33: 4 · Hotspot map: average wait (min) by department and location
B34: Department | C34: Abuja | D34: Gwarinpa | E34: Kubwa | F34: Kuje | G34: Nyanya | H34: All locations
B35: Emergency | C35: =IFERROR(AVERAGEIFS('Patient Data'!$J$2:$J$181,'Patient Data'!$G$2:$G$181,$B35,'Patient Data'!$F$2:$F$181,C$34),0) -> 57 | D35: =IFERROR(AVERAGEIFS('Patient Data'!$J$2:$J$181,'Patient Data'!$G$2:$G$181,$B35,'Patient Data'!$F$2:$F$181,D$34),0) -> 77.111111 | E35: =IFERROR(AVERAGEIFS('Patient Data'!$J$2:$J$181,'Patient Data'!$G$2:$G$181,$B35,'Patient Data'!$F$2:$F$181,E$34),0) -> 61 | F35: =IFERROR(AVERAGEIFS('Patient Data'!$J$2:$J$181,'Patient Data'!$G$2:$G$181,$B35,'Patient Data'!$F$2:$F$181,F$34),0) -> 74.8 | G35: =IFERROR(AVERAGEIFS('Patient Data'!$J$2:$J$181,'Patient Data'!$G$2:$G$181,$B35,'Patient Data'!$F$2:$F$181,G$34),0) -> 79.555556 | H35: =AVERAGEIFS('Patient Data'!$J$2:$J$181,'Patient Data'!$G$2:$G$181,$B35) -> 74.962963
B36: General Medicine | C36: =IFERROR(AVERAGEIFS('Patient Data'!$J$2:$J$181,'Patient Data'!$G$2:$G$181,$B36,'Patient Data'!$F$2:$F$181,C$34),0) -> 41.727273 | D36: =IFERROR(AVERAGEIFS('Patient Data'!$J$2:$J$181,'Patient Data'!$G$2:$G$181,$B36,'Patient Data'!$F$2:$F$181,D$34),0) -> 56.166667 | E36: =IFERROR(AVERAGEIFS('Patient Data'!$J$2:$J$181,'Patient Data'!$G$2:$G$181,$B36,'Patient Data'!$F$2:$F$181,E$34),0) -> 25.666667 | F36: =IFERROR(AVERAGEIFS('Patient Data'!$J$2:$J$181,'Patient Data'!$G$2:$G$181,$B36,'Patient Data'!$F$2:$F$181,F$34),0) -> 48 | G36: =IFERROR(AVERAGEIFS('Patient Data'!$J$2:$J$181,'Patient Data'!$G$2:$G$181,$B36,'Patient Data'!$F$2:$F$181,G$34),0) -> 50.916667 | H36: =AVERAGEIFS('Patient Data'!$J$2:$J$181,'Patient Data'!$G$2:$G$181,$B36) -> 46.731707
B37: Maternal Health | C37: =IFERROR(AVERAGEIFS('Patient Data'!$J$2:$J$181,'Patient Data'!$G$2:$G$181,$B37,'Patient Data'!$F$2:$F$181,C$34),0) -> 56.333333 | D37: =IFERROR(AVERAGEIFS('Patient Data'!$J$2:$J$181,'Patient Data'!$G$2:$G$181,$B37,'Patient Data'!$F$2:$F$181,D$34),0) -> 55.5 | E37: =IFERROR(AVERAGEIFS('Patient Data'!$J$2:$J$181,'Patient Data'!$G$2:$G$181,$B37,'Patient Data'!$F$2:$F$181,E$34),0) -> 41.8 | F37: =IFERROR(AVERAGEIFS('Patient Data'!$J$2:$J$181,'Patient Data'!$G$2:$G$181,$B37,'Patient Data'!$F$2:$F$181,F$34),0) -> 42.857143 | G37: =IFERROR(AVERAGEIFS('Patient Data'!$J$2:$J$181,'Patient Data'!$G$2:$G$181,$B37,'Patient Data'!$F$2:$F$181,G$34),0) -> 47 | H37: =AVERAGEIFS('Patient Data'!$J$2:$J$181,'Patient Data'!$G$2:$G$181,$B37) -> 49
B38: Outpatient | C38: =IFERROR(AVERAGEIFS('Patient Data'!$J$2:$J$181,'Patient Data'!$G$2:$G$181,$B38,'Patient Data'!$F$2:$F$181,C$34),0) -> 36.384615 | D38: =IFERROR(AVERAGEIFS('Patient Data'!$J$2:$J$181,'Patient Data'!$G$2:$G$181,$B38,'Patient Data'!$F$2:$F$181,D$34),0) -> 41 | E38: =IFERROR(AVERAGEIFS('Patient Data'!$J$2:$J$181,'Patient Data'!$G$2:$G$181,$B38,'Patient Data'!$F$2:$F$181,E$34),0) -> 29.307692 | F38: =IFERROR(AVERAGEIFS('Patient Data'!$J$2:$J$181,'Patient Data'!$G$2:$G$181,$B38,'Patient Data'!$F$2:$F$181,F$34),0) -> 38.4 | G38: =IFERROR(AVERAGEIFS('Patient Data'!$J$2:$J$181,'Patient Data'!$G$2:$G$181,$B38,'Patient Data'!$F$2:$F$181,G$34),0) -> 37 | H38: =AVERAGEIFS('Patient Data'!$J$2:$J$181,'Patient Data'!$G$2:$G$181,$B38) -> 34.829268
B39: Pediatrics | C39: =IFERROR(AVERAGEIFS('Patient Data'!$J$2:$J$181,'Patient Data'!$G$2:$G$181,$B39,'Patient Data'!$F$2:$F$181,C$34),0) -> 50.166667 | D39: =IFERROR(AVERAGEIFS('Patient Data'!$J$2:$J$181,'Patient Data'!$G$2:$G$181,$B39,'Patient Data'!$F$2:$F$181,D$34),0) -> 25.5 | E39: =IFERROR(AVERAGEIFS('Patient Data'!$J$2:$J$181,'Patient Data'!$G$2:$G$181,$B39,'Patient Data'!$F$2:$F$181,E$34),0) -> 33.857143 | F39: =IFERROR(AVERAGEIFS('Patient Data'!$J$2:$J$181,'Patient Data'!$G$2:$G$181,$B39,'Patient Data'!$F$2:$F$181,F$34),0) -> 29.571429 | G39: =IFERROR(AVERAGEIFS('Patient Data'!$J$2:$J$181,'Patient Data'!$G$2:$G$181,$B39,'Patient Data'!$F$2:$F$181,G$34),0) -> 39.625 | H39: =AVERAGEIFS('Patient Data'!$J$2:$J$181,'Patient Data'!$G$2:$G$181,$B39) -> 37.1
B40: Surgery | C40: =IFERROR(AVERAGEIFS('Patient Data'!$J$2:$J$181,'Patient Data'!$G$2:$G$181,$B40,'Patient Data'!$F$2:$F$181,C$34),0) -> 77.5 | D40: =IFERROR(AVERAGEIFS('Patient Data'!$J$2:$J$181,'Patient Data'!$G$2:$G$181,$B40,'Patient Data'!$F$2:$F$181,D$34),0) -> 53.2 | E40: =IFERROR(AVERAGEIFS('Patient Data'!$J$2:$J$181,'Patient Data'!$G$2:$G$181,$B40,'Patient Data'!$F$2:$F$181,E$34),0) -> 70.333333 | F40: =IFERROR(AVERAGEIFS('Patient Data'!$J$2:$J$181,'Patient Data'!$G$2:$G$181,$B40,'Patient Data'!$F$2:$F$181,F$34),0) -> 69 | G40: =IFERROR(AVERAGEIFS('Patient Data'!$J$2:$J$181,'Patient Data'!$G$2:$G$181,$B40,'Patient Data'!$F$2:$F$181,G$34),0) -> 51.25 | H40: =AVERAGEIFS('Patient Data'!$J$2:$J$181,'Patient Data'!$G$2:$G$181,$B40) -> 60.4
B42: 5 · Monthly trend
B43: Month | C43: Visits | D43: Avg Wait (min) | E43: Avg Satisfaction | F43: Treatment Cost | G43: Visits vs Prior Month
A44: 1 | B44: Jan | C44: =COUNTIFS('Patient Data'!$Q$2:$Q$181,$A44) -> 14 | D44: =AVERAGEIFS('Patient Data'!$J$2:$J$181,'Patient Data'!$Q$2:$Q$181,$A44) -> 45.571429 | E44: =AVERAGEIFS('Patient Data'!$O$2:$O$181,'Patient Data'!$Q$2:$Q$181,$A44) -> 4.0714286 | F44: =SUMIFS('Patient Data'!$L$2:$L$181,'Patient Data'!$Q$2:$Q$181,$A44) -> 1180231
A45: 2 | B45: Feb | C45: =COUNTIFS('Patient Data'!$Q$2:$Q$181,$A45) -> 17 | D45: =AVERAGEIFS('Patient Data'!$J$2:$J$181,'Patient Data'!$Q$2:$Q$181,$A45) -> 40.352941 | E45: =AVERAGEIFS('Patient Data'!$O$2:$O$181,'Patient Data'!$Q$2:$Q$181,$A45) -> 4.7058824 | F45: =SUMIFS('Patient Data'!$L$2:$L$181,'Patient Data'!$Q$2:$Q$181,$A45) -> 1514699 | G45: =C45/C44-1 -> 0.21428571
A46: 3 | B46: Mar | C46: =COUNTIFS('Patient Data'!$Q$2:$Q$181,$A46) -> 22 | D46: =AVERAGEIFS('Patient Data'!$J$2:$J$181,'Patient Data'!$Q$2:$Q$181,$A46) -> 45.272727 | E46: =AVERAGEIFS('Patient Data'!$O$2:$O$181,'Patient Data'!$Q$2:$Q$181,$A46) -> 4.3181818 | F46: =SUMIFS('Patient Data'!$L$2:$L$181,'Patient Data'!$Q$2:$Q$181,$A46) -> 1764642 | G46: =C46/C45-1 -> 0.29411765
...

Sheet Scenario Lab
B2: SCENARIO LAB · Set targets, test the fix
B3: Change the yellow cells (blue text = your inputs). Everything recalculates. Estimates describe this synthetic dataset and show association, not clinical cause.
B4: 1 · Targets and levers
B5: Maximum acceptable waiting time (min) | C5: 60 | D5: Visits above this count as "over the wait limit"
B6: Share of excess waiting removed by process changes | C6: 0.5 | D6: Applied to minutes above the limit only
B7: Follow-up completion target | C7: 0.75 | D7: Default = current overall rate; raise it to test a stretch goal
B8: Satisfaction target (avg, 1-5) | C8: 4.3 | D8: Used by the department scorecard
B9: Max acceptable share of visits over the wait limit | C9: 0.2 | D9: Used by the department scorecard
B11: 2 · Waiting-time scenario
B12: Visits over the wait limit (now) | C12: =SUM('Patient Data'!$T$2:$T$181) -> 49
B13: Share of visits over the limit (now) | C13: =C12/COUNTA('Patient Data'!$A$2:$A$181) -> 0.27222222
B14: Average wait now (min) | C14: =AVERAGE('Patient Data'!$J$2:$J$181) -> 48.116667
B15: Average minutes removed per visit | C15: =$C$6*SUMPRODUCT(('Patient Data'!$J$2:$J$181>$C$5)*('Patient Data'!$J$2:$J$181-$C$5))/COUNTA('Patient Data'!$A$2:$A$181) -> 1.95
B16: Average wait after (min) | C16: =C14-C15 -> 46.166667
B17: Average satisfaction now | C17: =AVERAGE('Patient Data'!$O$2:$O$181) -> 4.3388889
B18: Observed link: satisfaction points per extra minute waited | C18: =SLOPE('Patient Data'!$O$2:$O$181,'Patient Data'!$J$2:$J$181) -> -0.018660152
B19: Predicted satisfaction after | C19: =MIN(5,C17-C18*C15) -> 4.3752762
B20: Predicted satisfaction gain (points) | C20: =C19-C17 -> 0.036387296 | D20: ← headline
B21: Method: gain = observed slope x average minutes removed. It assumes the wait/satisfaction link in this sample holds if waits fall.
B23: 3 · Follow-up gap by department (target set above)
B24: Department | C24: Follow-ups Due | D24: Completed | E24: Completion Rate | F24: Extra Completions Needed
B25: Emergency | C25: =SUMIFS('Patient Data'!$U$2:$U$181,'Patient Data'!$G$2:$G$181,$B25) -> 13 | D25: =SUMIFS('Patient Data'!$V$2:$V$181,'Patient Data'!$G$2:$G$181,$B25) -> 11 | E25: =IF(C25=0,0,D25/C25) -> 0.84615385 | F25: =MAX(0,ROUNDUP($C$7*C25-D25,0)) -> 0
B26: General Medicine | C26: =SUMIFS('Patient Data'!$U$2:$U$181,'Patient Data'!$G$2:$G$181,$B26) -> 23 | D26: =SUMIFS('Patient Data'!$V$2:$V$181,'Patient Data'!$G$2:$G$181,$B26) -> 14 | E26: =IF(C26=0,0,D26/C26) -> 0.60869565 | F26: =MAX(0,ROUNDUP($C$7*C26-D26,0)) -> 4
B27: Maternal Health | C27: =SUMIFS('Patient Data'!$U$2:$U$181,'Patient Data'!$G$2:$G$181,$B27) -> 17 | D27: =SUMIFS('Patient Data'!$V$2:$V$181,'Patient Data'!$G$2:$G$181,$B27) -> 13 | E27: =IF(C27=0,0,D27/C27) -> 0.76470588 | F27: =MAX(0,ROUNDUP($C$7*C27-D27,0)) -> 0
B28: Outpatient | C28: =SUMIFS('Patient Data'!$U$2:$U$181,'Patient Data'!$G$2:$G$181,$B28) -> 27 | D28: =SUMIFS('Patient Data'!$V$2:$V$181,'Patient Data'!$G$2:$G$181,$B28) -> 19 | E28: =IF(C28=0,0,D28/C28) -> 0.7037037 | F28: =MAX(0,ROUNDUP($C$7*C28-D28,0)) -> 2
B29: Pediatrics | C29: =SUMIFS('Patient Data'!$U$2:$U$181,'Patient Data'!$G$2:$G$181,$B29) -> 18 | D29: =SUMIFS('Patient Data'!$V$2:$V$181,'Patient Data'!$G$2:$G$181,$B29) -> 14 | E29: =IF(C29=0,0,D29/C29) -> 0.77777778 | F29: =MAX(0,ROUNDUP($C$7*C29-D29,0)) -> 0
B30: Surgery | C30: =SUMIFS('Patient Data'!$U$2:$U$181,'Patient Data'!$G$2:$G$181,$B30) -> 10 | D30: =SUMIFS('Patient Data'!$V$2:$V$181,'Patient Data'!$G$2:$G$181,$B30) -> 10 | E30: =IF(C30=0,0,D30/C30) -> 1 | F30: =MAX(0,ROUNDUP($C$7*C30-D30,0)) -> 0
B31: Total | C31: =SUM(C25:C30) -> 108 | D31: =SUM(D25:D30) -> 81 | E31: =IF(C31=0,0,D31/C31) -> 0.75 | F31: =SUM(F25:F30) -> 6
B33: 4 · Sensitivity: predicted satisfaction gain (points) for different wait limits and process-change strength
B34: Wait limit (min) ↓ | Excess waiting removed → | C34: 0.25 | D34: 0.5 | E34: 0.75 | F34: 1
B35: 90 | C35: =MIN(5-AVERAGE('Patient Data'!$O$2:$O$181),-SLOPE('Patient Data'!$O$2:$O$181,'Patient Data'!$J$2:$J$181)*C$34*SUMPRODUCT(('Patient Data'!$J$2:$J$181>$B35)*('Patient Data'!$J$2:$J$181-$B35))/COUNTA('Patient Data'!$A$2:$A$181)) -> 0.0010366751 | D35: =MIN(5-AVERAGE('Patient Data'!$O$2:$O$181),-SLOPE('Patient Data'!$O$2:$O$181,'Patient Data'!$J$2:$J$181)*D$34*SUMPRODUCT(('Patient Data'!$J$2:$J$181>$B35)*('Patient Data'!$J$2:$J$181-$B35))/COUNTA('Patient Data'!$A$2:$A$181)) -> 0.0020733502 | E35: =MIN(5-AVERAGE('Patient Data'!$O$2:$O$181),-SLOPE('Patient Data'!$O$2:$O$181,'Patient Data'!$J$2:$J$181)*E$34*SUMPRODUCT(('Patient Data'!$J$2:$J$181>$B35)*('Patient Data'!$J$2:$J$181-$B35))/COUNTA('Patient Data'!$A$2:$A$181)) -> 0.0031100253 | F35: =MIN(5-AVERAGE('Patient Data'!$O$2:$O$181),-SLOPE('Patient Data'!$O$2:$O$181,'Patient Data'!$J$2:$J$181)*F$34*SUMPRODUCT(('Patient Data'!$J$2:$J$181>$B35)*('Patient Data'!$J$2:$J$181-$B35))/COUNTA('Patient Data'!$A$2:$A$181)) -> 0.0041467005
B36: 75 | C36: =MIN(5-AVERAGE('Patient Data'!$O$2:$O$181),-SLOPE('Patient Data'!$O$2:$O$181,'Patient Data'!$J$2:$J$181)*C$34*SUMPRODUCT(('Patient Data'!$J$2:$J$181>$B36)*('Patient Data'!$J$2:$J$181-$B36))/COUNTA('Patient Data'!$A$2:$A$181)) -> 0.0058053806 | D36: =MIN(5-AVERAGE('Patient Data'!$O$2:$O$181),-SLOPE('Patient Data'!$O$2:$O$181,'Patient Data'!$J$2:$J$181)*D$34*SUMPRODUCT(('Patient Data'!$J$2:$J$181>$B36)*('Patient Data'!$J$2:$J$181-$B36))/COUNTA('Patient Data'!$A$2:$A$181)) -> 0.011610761 | E36: =MIN(5-AVERAGE('Patient Data'!$O$2:$O$181),-SLOPE('Patient Data'!$O$2:$O$181,'Patient Data'!$J$2:$J$181)*E$34*SUMPRODUCT(('Patient Data'!$J$2:$J$181>$B36)*('Patient Data'!$J$2:$J$181-$B36))/COUNTA('Patient Data'!$A$2:$A$181)) -> 0.017416142 | F36: =MIN(5-AVERAGE('Patient Data'!$O$2:$O$181),-SLOPE('Patient Data'!$O$2:$O$181,'Patient Data'!$J$2:$J$181)*F$34*SUMPRODUCT(('Patient Data'!$J$2:$J$181>$B36)*('Patient Data'!$J$2:$J$181-$B36))/COUNTA('Patient Data'!$A$2:$A$181)) -> 0.023221523
B37: 60 | C37: =MIN(5-AVERAGE('Patient Data'!$O$2:$O$181),-SLOPE('Patient Data'!$O$2:$O$181,'Patient Data'!$J$2:$J$181)*C$34*SUMPRODUCT(('Patient Data'!$J$2:$J$181>$B37)*('Patient Data'!$J$2:$J$181-$B37))/COUNTA('Patient Data'!$A$2:$A$181)) -> 0.018193648 | D37: =MIN(5-AVERAGE('Patient Data'!$O$2:$O$181),-SLOPE('Patient Data'!$O$2:$O$181,'Patient Data'!$J$2:$J$181)*D$34*SUMPRODUCT(('Patient Data'!$J$2:$J$181>$B37)*('Patient Data'!$J$2:$J$181-$B37))/COUNTA('Patient Data'!$A$2:$A$181)) -> 0.036387296 | E37: =MIN(5-AVERAGE('Patient Data'!$O$2:$O$181),-SLOPE('Patient Data'!$O$2:$O$181,'Patient Data'!$J$2:$J$181)*E$34*SUMPRODUCT(('Patient Data'!$J$2:$J$181>$B37)*('Patient Data'!$J$2:$J$181-$B37))/COUNTA('Patient Data'!$A$2:$A$181)) -> 0.054580945 | F37: =MIN(5-AVERAGE('Patient Data'!$O$2:$O$181),-SLOPE('Patient Data'!$O$2:$O$181,'Patient Data'!$J$2:$J$181)*F$34*SUMPRODUCT(('Patient Data'!$J$2:$J$181>$B37)*('Patient Data'!$J$2:$J$181-$B37))/COUNTA('Patient Data'!$A$2:$A$181)) -> 0.072774593
B38: 45 | C38: =MIN(5-AVERAGE('Patient Data'!$O$2:$O$181),-SLOPE('Patient Data'!$O$2:$O$181,'Patient Data'!$J$2:$J$181)*C$34*SUMPRODUCT(('Patient Data'!$J$2:$J$181>$B38)*('Patient Data'!$J$2:$J$181-$B38))/COUNTA('Patient Data'!$A$2:$A$181)) -> 0.046391211 | D38: =MIN(5-AVERAGE('Patient Data'!$O$2:$O$181),-SLOPE('Patient Data'!$O$2:$O$181,'Patient Data'!$J$2:$J$181)*D$34*SUMPRODUCT(('Patient Data'!$J$2:$J$181>$B38)*('Patient Data'!$J$2:$J$181-$B38))/COUNTA('Patient Data'!$A$2:$A$181)) -> 0.092782423 | E38: =MIN(5-AVERAGE('Patient Data'!$O$2:$O$181),-SLOPE('Patient Data'!$O$2:$O$181,'Patient Data'!$J$2:$J$181)*E$34*SUMPRODUCT(('Patient Data'!$J$2:$J$181>$B38)*('Patient Data'!$J$2:$J$181-$B38))/COUNTA('Patient Data'!$A$2:$A$181)) -> 0.13917363 | F38: =MIN(5-AVERAGE('Patient Data'!$O$2:$O$181),-SLOPE('Patient Data'!$O$2:$O$181,'Patient Data'!$J$2:$J$181)*F$34*SUMPRODUCT(('Patient Data'!$J$2:$J$181>$B38)*('Patient Data'!$J$2:$J$181-$B38))/COUNTA('Patient Data'!$A$2:$A$181)) -> 0.18556485
B39: 30 | C39: =MIN(5-AVERAGE('Patient Data'!$O$2:$O$181),-SLOPE('Patient Data'!$O$2:$O$181,'Patient Data'!$J$2:$J$181)*C$34*SUMPRODUCT(('Patient Data'!$J$2:$J$181>$B39)*('Patient Data'!$J$2:$J$181-$B39))/COUNTA('Patient Data'!$A$2:$A$181)) -> 0.093015675 | D39: =MIN(5-AVERAGE('Patient Data'!$O$2:$O$181),-SLOPE('Patient Data'!$O$2:$O$181,'Patient Data'!$J$2:$J$181)*D$34*SUMPRODUCT(('Patient Data'!$J$2:$J$181>$B39)*('Patient Data'!$J$2:$J$181-$B39))/COUNTA('Patient Data'!$A$2:$A$181)) -> 0.18603135 | E39: =MIN(5-AVERAGE('Patient Data'!$O$2:$O$181),-SLOPE('Patient Data'!$O$2:$O$181,'Patient Data'!$J$2:$J$181)*E$34*SUMPRODUCT(('Patient Data'!$J$2:$J$181>$B39)*('Patient Data'!$J$2:$J$181-$B39))/COUNTA('Patient Data'!$A$2:$A$181)) -> 0.27904702 | F39: =MIN(5-AVERAGE('Patient Data'!$O$2:$O$181),-SLOPE('Patient Data'!$O$2:$O$181,'Patient Data'!$J$2:$J$181)*F$34*SUMPRODUCT(('Patient Data'!$J$2:$J$181>$B39)*('Patient Data'!$J$2:$J$181-$B39))/COUNTA('Patient Data'!$A$2:$A$181)) -> 0.3720627
B40: Reading it: a tighter wait limit with stronger process change gives a bigger predicted gain, but it also needs more staffing or queue redesign.

Sheet Patient Data
A1: Patient ID | B1: Visit ID | C1: Visit Date | D1: Age | E1: Gender | F1: Location | G1: Department | H1: Visit Type | I1: Diagnosis Category | J1: Waiting Time (min) | K1: Length of Stay (days) | L1: Treatment Cost (₦) | M1: Follow-up Required | N1: Follow-up Completed | O1: Satisfaction (1-5) | P1: Outcome | Q1: Month No | R1: Age Group | S1: Wait Band | T1: Over Wait Limit | U1: Follow-up Due | V1: Follow-up Done | W1: Review Flag
A2: P0001 | B2: V0001 | C2: 46036 | D2: 25 | E2: Female | F2: Abuja | G2: Maternal Health | H2: Follow-up | I2: Maternal/Child Health | J2: 57 | K2: 3.6 | L2: 146776 | M2: Yes | N2: Yes | O2: 4 | P2: Discharged | Q2: =MONTH(C2) -> 1 | R2: =IF(D2<=14,"1–14",IF(D2<=24,"15–24",IF(D2<=44,"25–44",IF(D2<=64,"45–64","65+")))) -> 25–44 | S2: =IF(J2<=30,"Up to 30",IF(J2<=60,"31–60",IF(J2<=90,"61–90","Over 90"))) -> 31–60 | T2: =IF(J2>'Scenario Lab'!$C$5,1,0) -> 0 | U2: =IF(M2="Yes",1,0) -> 1 | V2: =IF(AND(M2="Yes",N2="Yes"),1,0) -> 1 | W2: =IF(AND(G2="Maternal Health",E2="Male",D2>=15),"Review","OK") -> OK
A3: P0002 | B3: V0002 | C3: 46102 | D3: 31 | E3: Female | F3: Kuje | G3: Maternal Health | H3: Emergency | I3: Maternal/Child Health | J3: 30 | K3: 2.6 | L3: 143358 | M3: No | N3: N/A | O3: 5 | P3: Discharged | Q3: =MONTH(C3) -> 3 | R3: =IF(D3<=14,"1–14",IF(D3<=24,"15–24",IF(D3<=44,"25–44",IF(D3<=64,"45–64","65+")))) -> 25–44 | S3: =IF(J3<=30,"Up to 30",IF(J3<=60,"31–60",IF(J3<=90,"61–90","Over 90"))) -> Up to 30 | T3: =IF(J3>'Scenario Lab'!$C$5,1,0) -> 0 | U3: =IF(M3="Yes",1,0) -> 0 | V3: =IF(AND(M3="Yes",N3="Yes"),1,0) -> 0 | W3: =IF(AND(G3="Maternal Health",E3="Male",D3>=15),"Review","OK") -> OK
A4: P0003 | B4: V0003 | C4: 46173 | D4: 36 | E4: Male | F4: Abuja | G4: General Medicine | H4: Outpatient | I4: Respiratory | J4: 40 | K4: 0.2 | L4: 70673 | M4: Yes | N4: No | O4: 5 | P4: Discharged | Q4: =MONTH(C4) -> 5 | R4: =IF(D4<=14,"1–14",IF(D4<=24,"15–24",IF(D4<=44,"25–44",IF(D4<=64,"45–64","65+")))) -> 25–44 | S4: =IF(J4<=30,"Up to 30",IF(J4<=60,"31–60",IF(J4<=90,"61–90","Over 90"))) -> 31–60 | T4: =IF(J4>'Scenario Lab'!$C$5,1,0) -> 0 | U4: =IF(M4="Yes",1,0) -> 1 | V4: =IF(AND(M4="Yes",N4="Yes"),1,0) -> 0 | W4: =IF(AND(G4="Maternal Health",E4="Male",D4>=15),"Review","OK") -> OK
A5: P0004 | B5: V0004 | C5: 46209 | D5: 8 | E5: Female | F5: Abuja | G5: Outpatient | H5: Outpatient | I5: Malaria/Fever | J5: 13 | K5: 0.2 | L5: 41665 | M5: Yes | N5: Yes | O5: 5 | P5: Follow-up | Q5: =MONTH(C5) -> 7 | R5: =IF(D5<=14,"1–14",IF(D5<=24,"15–24",IF(D5<=44,"25–44",IF(D5<=64,"45–64","65+")))) -> 1–14 | S5: =IF(J5<=30,"Up to 30",IF(J5<=60,"31–60",IF(J5<=90,"61–90","Over 90"))) -> Up to 30 | T5: =IF(J5>'Scenario Lab'!$C$5,1,0) -> 0 | U5: =IF(M5="Yes",1,0) -> 1 | V5: =IF(AND(M5="Yes",N5="Yes"),1,0) -> 1 | W5: =IF(AND(G5="Maternal Health",E5="Male",D5>=15),"Review","OK") -> OK
A6: P0005 | B6: V0005 | C6: 46135 | D6: 18 | E6: Female | F6: Nyanya | G6: General Medicine | H6: Follow-up | I6: Hypertension | J6: 66 | K6: 0.1 | L6: 47045 | M6: No | N6: N/A | O6: 4 | P6: Follow-up | Q6: =MONTH(C6) -> 4 | R6: =IF(D6<=14,"1–14",IF(D6<=24,"15–24",IF(D6<=44,"25–44",IF(D6<=64,"45–64","65+")))) -> 15–24 | S6: =IF(J6<=30,"Up to 30",IF(J6<=60,"31–60",IF(J6<=90,"61–90","Over 90"))) -> 61–90 | T6: =IF(J6>'Scenario Lab'!$C$5,1,0) -> 1 | U6: =IF(M6="Yes",1,0) -> 0 | V6: =IF(AND(M6="Yes",N6="Yes"),1,0) -> 0 | W6: =IF(AND(G6="Maternal Health",E6="Male",D6>=15),"Review","OK") -> OK
A7: P0006 | B7: V0006 | C7: 46257 | D7: 32 | E7: Female | F7: Gwarinpa | G7: Surgery | H7: Outpatient | I7: Malaria/Fever | J7: 41 | K7: 4 | L7: 302528 | M7: Yes | N7: Yes | O7: 4 | P7: Admitted | Q7: =MONTH(C7) -> 8 | R7: =IF(D7<=14,"1–14",IF(D7<=24,"15–24",IF(D7<=44,"25–44",IF(D7<=64,"45–64","65+")))) -> 25–44 | S7: =IF(J7<=30,"Up to 30",IF(J7<=60,"31–60",IF(J7<=90,"61–90","Over 90"))) -> 31–60 | T7: =IF(J7>'Scenario Lab'!$C$5,1,0) -> 0 | U7: =IF(M7="Yes",1,0) -> 1 | V7: =IF(AND(M7="Yes",N7="Yes"),1,0) -> 1 | W7: =IF(AND(G7="Maternal Health",E7="Male",D7>=15),"Review","OK") -> OK
A8: P0007 | B8: V0007 | C8: 46101 | D8: 56 | E8: Male | F8: Nyanya | G8: General Medicine | H8: Outpatient | I8: Diabetes | J8: 68 | K8: 0.4 | L8: 67101 | M8: Yes | N8: No | O8: 4 | P8: Admitted | Q8: =MONTH(C8) -> 3 | R8: =IF(D8<=14,"1–14",IF(D8<=24,"15–24",IF(D8<=44,"25–44",IF(D8<=64,"45–64","65+")))) -> 45–64 | S8: =IF(J8<=30,"Up to 30",IF(J8<=60,"31–60",IF(J8<=90,"61–90","Over 90"))) -> 61–90 | T8: =IF(J8>'Scenario Lab'!$C$5,1,0) -> 1 | U8: =IF(M8="Yes",1,0) -> 1 | V8: =IF(AND(M8="Yes",N8="Yes"),1,0) -> 0 | W8: =IF(AND(G8="Maternal Health",E8="Male",D8>=15),"Review","OK") -> OK
A9: P0008 | B9: V0008 | C9: 46081 | D9: 20 | E9: Male | F9: Kuje | G9: Maternal Health | H9: Emergency | I9: Maternal/Child Health | J9: 38 | K9: 0.7 | L9: 82076 | M9: No | N9: N/A | O9: 5 | P9: Follow-up | Q9: =MONTH(C9) -> 2 | R9: =IF(D9<=14,"1–14",IF(D9<=24,"15–24",IF(D9<=44,"25–44",IF(D9<=64,"45–64","65+")))) -> 15–24 | S9: =IF(J9<=30,"Up to 30",IF(J9<=60,"31–60",IF(J9<=90,"61–90","Over 90"))) -> 31–60 | T9: =IF(J9>'Scenario Lab'!$C$5,1,0) -> 0 | U9: =IF(M9="Yes",1,0) -> 0 | V9: =IF(AND(M9="Yes",N9="Yes"),1,0) -> 0 | W9: =IF(AND(G9="Maternal Health",E9="Male",D9>=15),"Review","OK") -> Review
A10: P0009 | B10: V0009 | C10: 46282 | D10: 59 | E10: Male | F10: Abuja | G10: Surgery | H10: Outpatient | I10: Malaria/Fever | J10: 62 | K10: 0 | L10: 168981 | M10: No | N10: N/A | O10: 3 | P10: Follow-up | Q10: =MONTH(C10) -> 9 | R10: =IF(D10<=14,"1–14",IF(D10<=24,"15–24",IF(D10<=44,"25–44",IF(D10<=64,"45–64","65+")))) -> 45–64 | S10: =IF(J10<=30,"Up to 30",IF(J10<=60,"31–60",IF(J10<=90,"61–90","Over 90"))) -> 61–90 | T10: =IF(J10>'Scenario Lab'!$C$5,1,0) -> 1 | U10: =IF(M10="Yes",1,0) -> 0 | V10: =IF(AND(M10="Yes",N10="Yes"),1,0) -> 0 | W10: =IF(AND(G10="Maternal Health",E10="Male",D10>=15),"Review","OK") -> OK
A11: P0010 | B11: V0010 | C11: 46080 | D11: 46 | E11: Female | F11: Kubwa | G11: Outpatient | H11: Outpatient | I11: Malaria/Fever | J11: 25 | K11: 5.1 | L11: 94859 | M11: No | N11: N/A | O11: 4 | P11: Discharged | Q11: =MONTH(C11) -> 2 | R11: =IF(D11<=14,"1–14",IF(D11<=24,"15–24",IF(D11<=44,"25–44",IF(D11<=64,"45–64","65+")))) -> 45–64 | S11: =IF(J11<=30,"Up to 30",IF(J11<=60,"31–60",IF(J11<=90,"61–90","Over 90"))) -> Up to 30 | T11: =IF(J11>'Scenario Lab'!$C$5,1,0) -> 0 | U11: =IF(M11="Yes",1,0) -> 0 | V11: =IF(AND(M11="Yes",N11="Yes"),1,0) -> 0 | W11: =IF(AND(G11="Maternal Health",E11="Male",D11>=15),"Review","OK") -> OK
A12: P0011 | B12: V0011 | C12: 46088 | D12: 61 | E12: Male | F12: Kubwa | G12: Outpatient | H12: Outpatient | I12: Maternal/Child Health | J12: 14 | K12: 4.9 | L12: 85502 | M12: Yes | N12: No | O12: 5 | P12: Follow-up | Q12: =MONTH(C12) -> 3 | R12: =IF(D12<=14,"1–14",IF(D12<=24,"15–24",IF(D12<=44,"25–44",IF(D12<=64,"45–64","65+")))) -> 45–64 | S12: =IF(J12<=30,"Up to 30",IF(J12<=60,"31–60",IF(J12<=90,"61–90","Over 90"))) -> Up to 30 | T12: =IF(J12>'Scenario Lab'!$C$5,1,0) -> 0 | U12: =IF(M12="Yes",1,0) -> 1 | V12: =IF(AND(M12="Yes",N12="Yes"),1,0) -> 0 | W12: =IF(AND(G12="Maternal Health",E12="Male",D12>=15),"Review","OK") -> OK
A13: P0012 | B13: V0012 | C13: 46287 | D13: 34 | E13: Male | F13: Kubwa | G13: Maternal Health | H13: Routine Check | I13: Maternal/Child Health | J13: 51 | K13: 2.1 | L13: 97774 | M13: Yes | N13: Yes | O13: 4 | P13: Discharged | Q13: =MONTH(C13) -> 9 | R13: =IF(D13<=14,"1–14",IF(D13<=24,"15–24",IF(D13<=44,"25–44",IF(D13<=64,"45–64","65+")))) -> 25–44 | S13: =IF(J13<=30,"Up to 30",IF(J13<=60,"31–60",IF(J13<=90,"61–90","Over 90"))) -> 31–60 | T13: =IF(J13>'Scenario Lab'!$C$5,1,0) -> 0 | U13: =IF(M13="Yes",1,0) -> 1 | V13: =IF(AND(M13="Yes",N13="Yes"),1,0) -> 1 | W13: =IF(AND(G13="Maternal Health",E13="Male",D13>=15),"Review","OK") -> Review
... A181: P0180 | B181: V0180 | C181: 46276 | D181: 42 | E181: Male | F181: Nyanya | G181: Emergency | H181: Emergency | I181: Respiratory | J181: 72 | K181: 0 | L181: 113798 | M181: No | N181: N/A | O181: 5 | P181: Discharged | Q181: =MONTH(C181) -> 9 | R181: =IF(D181<=14,"1–14",IF(D181<=24,"15–24",IF(D181<=44,"25–44",IF(D181<=64,"45–64","65+")))) -> 25–44 | S181: =IF(J181<=30,"Up to 30",IF(J181<=60,"31–60",IF(J181<=90,"61–90","Over 90"))) -> 61–90 | T181: =IF(J181>'Scenario Lab'!$C$5,1,0) -> 1 | U181: =IF(M181="Yes",1,0) -> 0 | V181: =IF(AND(M181="Yes",N181="Yes"),1,0) -> 0 | W181: =IF(AND(G181="Maternal Health",E181="Male",D181>=15),"Review","OK") -> OK

Sheet Quality & Method
B2: QUALITY & METHOD · Why you can trust these numbers
B4: 1 · Automated checks
B5: Check | C5: This workbook | D5: Reference | E5: Status | F5: Source of reference
B6: Total visits ties to original dashboard | C6: =COUNTA('Patient Data'!$A$2:$A$181) -> 180 | D6: 180 | E6: =IF(ABS(C6-D6)<=0,"PASS","CHECK") -> PASS | F6: Original file, Dashboard tab
B7: Unique patients ties to original | C7: =SUMPRODUCT(1/COUNTIF('Patient Data'!$A$2:$A$181,'Patient Data'!$A$2:$A$181)) -> 180 | D7: 180 | E7: =IF(ABS(C7-D7)<=0.001,"PASS","CHECK") -> PASS | F7: Original file, Dashboard tab
B8: Visit IDs are unique | C8: =SUMPRODUCT(1/COUNTIF('Patient Data'!$B$2:$B$181,'Patient Data'!$B$2:$B$181)) -> 180 | D8: 180 | E8: =IF(ABS(C8-D8)<=0.001,"PASS","CHECK") -> PASS | F8: Expected: every visit ID appears once
B9: Average wait ties to original (min) | C9: =AVERAGE('Patient Data'!$J$2:$J$181) -> 48.116667 | D9: 48.1 | E9: =IF(ABS(C9-D9)<=0.05,"PASS","CHECK") -> PASS | F9: Original Dashboard (shown to 1 decimal)
B10: Average treatment cost ties to original | C10: =AVERAGE('Patient Data'!$L$2:$L$181) -> 88563.322 | D10: 88563 | E10: =IF(ABS(C10-D10)<=1,"PASS","CHECK") -> PASS | F10: Original Dashboard (rounded)
B11: Average satisfaction ties to original | C11: =AVERAGE('Patient Data'!$O$2:$O$181) -> 4.3388889 | D11: 4.34 | E11: =IF(ABS(C11-D11)<=0.005,"PASS","CHECK") -> PASS | F11: Original Dashboard (2 decimals)
B12: Follow-up completion ties to original | C12: =SUM('Patient Data'!$V$2:$V$181)/SUM('Patient Data'!$U$2:$U$181) -> 0.75 | D12: 0.75 | E12: =IF(ABS(C12-D12)<=0.0001,"PASS","CHECK") -> PASS | F12: Original Dashboard
B13: Emergency visits (visit type) ties to original | C13: =COUNTIFS('Patient Data'!$H$2:$H$181,"Emergency") -> 53 | D13: 53 | E13: =IF(ABS(C13-D13)<=0,"PASS","CHECK") -> PASS | F13: Original Dashboard
B14: Average length of stay ties to original (days) | C14: =AVERAGE('Patient Data'!$K$2:$K$181) -> 1.5027778 | D14: 1.5 | E14: =IF(ABS(C14-D14)<=0.05,"PASS","CHECK") -> PASS | F14: Original Dashboard (1 decimal)
B15: Department visits add up to total | C15: =Insights!C13 -> 180 | D15: =COUNTA('Patient Data'!$A$2:$A$181) -> 180 | E15: =IF(ABS(C15-D15)<=0,"PASS","CHECK") -> PASS | F15: Insights vs Patient Data
B16: Age-group visits add up to total | C16: =SUM(Insights!C57:C61) -> 180 | D16: =COUNTA('Patient Data'!$A$2:$A$181) -> 180 | E16: =IF(ABS(C16-D16)<=0,"PASS","CHECK") -> PASS | F16: Original age bands reproduced
B17: Diagnosis visits add up to total | C17: =SUM(Insights!C65:C71) -> 180 | D17: =COUNTA('Patient Data'!$A$2:$A$181) -> 180 | E17: =IF(ABS(C17-D17)<=0,"PASS","CHECK") -> PASS | F17: Insights vs Patient Data
B18: Follow-up logic: "No" never has a completion status | C18: =COUNTIFS('Patient Data'!$M$2:$M$181,"No",'Patient Data'!$N$2:$N$181,"<>N/A") -> 0 | D18: 0 | E18: =IF(ABS(C18-D18)<=0,"PASS","CHECK") -> PASS | F18: Required = No should read N/A
B19: Satisfaction scores all between 1 and 5 | C19: =COUNTIFS('Patient Data'!$O$2:$O$181,">=1",'Patient Data'!$O$2:$O$181,"<=5") -> 180 | D19: 180 | E19: =IF(ABS(C19-D19)<=0,"PASS","CHECK") -> PASS | F19: Valid range
B20: Visit dates all fall in Jan–Sep 2026 | C20: =COUNTIFS('Patient Data'!$C$2:$C$181,">="&DATE(2026,1,1),'Patient Data'!$C$2:$C$181,"<="&DATE(2026,9,30)) -> 180 | D20: 180 | E20: =IF(ABS(C20-D20)<=0,"PASS","CHECK") -> PASS | F20: Expected reporting window
B21: Blank cells in raw inputs | C21: =COUNTBLANK('Patient Data'!$A$2:$P$181) -> 0 | D21: 0 | E21: =IF(ABS(C21-D21)<=0,"PASS","CHECK") -> PASS | F21: Expected: none
B22: Records flagged for review (adult male in Maternal Health) | C22: =COUNTIF('Patient Data'!$W$2:$W$181,"Review") -> 14 | D22: 0 | E22: =IF(ABS(C22-D22)<=0,"PASS","FLAG") -> FLAG | F22: Kept in analysis; flagged, not deleted
B23: Overall | E23: =IF(COUNTIF(E6:E22,"CHECK")=0,"NO ERRORS","REVIEW") -> NO ERRORS
B25: 2 · What this version adds to the original analysis
B26: • Live formulas (COUNTIFS, SUMIFS, AVERAGEIFS, SUMPRODUCT, SLOPE, CORREL, INDEX/MATCH) replace typed-in results, so every table recalculates when the data changes.
B27: • Interactive dashboard filters (Department, Location, Visit Type) drive all KPIs and charts.
B28: • A department scorecard with red/amber/green status against targets you can change, plus a hotspot map of waiting time by department and location.
