Workbook
Name d_Order: 'Sales Data'!$A$2:$A$121
Name d_Date: 'Sales Data'!$B$2:$B$121
Name d_Region: 'Sales Data'!$C$2:$C$121
Name d_Product: 'Sales Data'!$D$2:$D$121
Name d_Category: 'Sales Data'!$E$2:$E$121
Name d_Qty: 'Sales Data'!$F$2:$F$121
Name d_Price: 'Sales Data'!$G$2:$G$121
Name d_Rev: 'Sales Data'!$H$2:$H$121
Name d_Cost: 'Sales Data'!$I$2:$I$121
Name d_Profit: 'Sales Data'!$J$2:$J$121
Name d_Month: 'Sales Data'!$K$2:$K$121
Name d_MonthNo: 'Sales Data'!$N$2:$N$121
Name crit_R: Lists!$F$2
Name crit_P: Lists!$F$3

Sheet Dashboard
B1: SALES PERFORMANCE DASHBOARD
B3: =TEXT(MIN(d_Date),"mmm yyyy")&" – "&TEXT(MAX(d_Date),"mmm yyyy")&" | Showing: "&C5&" · "&G5&" | "&TEXT(COUNTIFS(d_Region,crit_R,d_Product,crit_P),"0")&" orders | Currency: Nigerian Naira (₦)"
B5: REGION ▸ | C5: All Regions | F5: PRODUCT ▸ | G5: All Products | J5: Tap the yellow cells to filter every KPI and chart
B7: TOTAL REVENUE | D7: TOTAL PROFIT | F7: PROFIT MARGIN | H7: ORDERS | J7: UNITS SOLD | L7: AVG ORDER VALUE
B8: =SUMIFS(d_Rev,d_Region,crit_R,d_Product,crit_P) | D8: =SUMIFS(d_Profit,d_Region,crit_R,d_Product,crit_P) | F8: =IFERROR(D8/B8,0) | H8: =COUNTIFS(d_Region,crit_R,d_Product,crit_P) | J8: =SUMIFS(d_Qty,d_Region,crit_R,d_Product,crit_P) | L8: =IFERROR(B8/H8,0)
B9: =TEXT(IFERROR(B8/SUM(d_Rev),0),"0.0%")&" of company revenue" | D9: =TEXT(IFERROR(D8/SUM(d_Profit),0),"0.0%")&" of company profit" | F9: ="Company average "&TEXT(SUM(d_Profit)/SUM(d_Rev),"0.0%") | H9: =TEXT(IFERROR(H8/COUNTA(d_Order),0),"0.0%")&" of all orders" | J9: =TEXT(IFERROR(J8/H8,0),"0.0")&" units per order" | L9: ="Company avg ₦"&TEXT(SUM(d_Rev)/COUNTA(d_Order)/1000,"#,##0")&"K"
B43: KEY TAKEAWAYS (company-wide, auto-generated on the Insights sheet)
B44: =Insights!C5
B45: =Insights!C6
B46: =Insights!C7
B47: =Insights!C8
B48: =Insights!C9
B50: Prepared by Williams Favour Ifunanya | Portfolio project: Excel data analysis | Sample dataset for demonstration

Sheet Analysis
B1: DEEP-DIVE ANALYSIS | Company-wide (unfiltered)
B4: 1 · PRODUCT PERFORMANCE (sorted by revenue)
B5: Product | C5: Category | D5: Revenue | E5: Profit | F5: Margin % | G5: Units | H5: Orders | I5: Revenue Share | J5: Cumulative Share | K5: Revenue Rank
B6: Laptop | C6: =INDEX(d_Category,MATCH(B6,d_Product,0)) | D6: =SUMIFS(d_Rev,d_Product,B6) | E6: =SUMIFS(d_Profit,d_Product,B6) | F6: =IFERROR(E6/D6,0) | G6: =SUMIFS(d_Qty,d_Product,B6) | H6: =COUNTIFS(d_Product,B6) | I6: =D6/$D$11 | J6: =SUM($D$6:D6)/$D$11 | K6: =RANK(D6,$D$6:$D$10)
B7: Tablet | C7: =INDEX(d_Category,MATCH(B7,d_Product,0)) | D7: =SUMIFS(d_Rev,d_Product,B7) | E7: =SUMIFS(d_Profit,d_Product,B7) | F7: =IFERROR(E7/D7,0) | G7: =SUMIFS(d_Qty,d_Product,B7) | H7: =COUNTIFS(d_Product,B7) | I7: =D7/$D$11 | J7: =SUM($D$6:D7)/$D$11 | K7: =RANK(D7,$D$6:$D$10)
B8: Phone | C8: =INDEX(d_Category,MATCH(B8,d_Product,0)) | D8: =SUMIFS(d_Rev,d_Product,B8) | E8: =SUMIFS(d_Profit,d_Product,B8) | F8: =IFERROR(E8/D8,0) | G8: =SUMIFS(d_Qty,d_Product,B8) | H8: =COUNTIFS(d_Product,B8) | I8: =D8/$D$11 | J8: =SUM($D$6:D8)/$D$11 | K8: =RANK(D8,$D$6:$D$10)
B9: Smartwatch | C9: =INDEX(d_Category,MATCH(B9,d_Product,0)) | D9: =SUMIFS(d_Rev,d_Product,B9) | E9: =SUMIFS(d_Profit,d_Product,B9) | F9: =IFERROR(E9/D9,0) | G9: =SUMIFS(d_Qty,d_Product,B9) | H9: =COUNTIFS(d_Product,B9) | I9: =D9/$D$11 | J9: =SUM($D$6:D9)/$D$11 | K9: =RANK(D9,$D$6:$D$10)
B10: Headphones | C10: =INDEX(d_Category,MATCH(B10,d_Product,0)) | D10: =SUMIFS(d_Rev,d_Product,B10) | E10: =SUMIFS(d_Profit,d_Product,B10) | F10: =IFERROR(E10/D10,0) | G10: =SUMIFS(d_Qty,d_Product,B10) | H10: =COUNTIFS(d_Product,B10) | I10: =D10/$D$11 | J10: =SUM($D$6:D10)/$D$11 | K10: =RANK(D10,$D$6:$D$10)
B11: Total | D11: =SUM(D6:D10) | E11: =SUM(E6:E10) | F11: =IFERROR(E11/D11,0) | G11: =SUM(G6:G10) | H11: =SUM(H6:H10) | I11: =SUM(I6:I10)
B13: 2 · REGION PERFORMANCE (sorted by revenue)
B14: Region | C14: Top Product | D14: Revenue | E14: Profit | F14: Margin % | G14: Units | H14: Orders | I14: Revenue Share | J14: Avg Order Value | K14: Revenue Rank
B15: Abuja | C15: =INDEX($C$36:$G$36,MATCH(MAX(C37:G37),C37:G37,0)) | D15: =SUMIFS(d_Rev,d_Region,B15) | E15: =SUMIFS(d_Profit,d_Region,B15) | F15: =IFERROR(E15/D15,0) | G15: =SUMIFS(d_Qty,d_Region,B15) | H15: =COUNTIFS(d_Region,B15) | I15: =D15/$D$20 | J15: =IFERROR(D15/H15,0) | K15: =RANK(D15,$D$15:$D$19)
B16: Lagos | C16: =INDEX($C$36:$G$36,MATCH(MAX(C38:G38),C38:G38,0)) | D16: =SUMIFS(d_Rev,d_Region,B16) | E16: =SUMIFS(d_Profit,d_Region,B16) | F16: =IFERROR(E16/D16,0) | G16: =SUMIFS(d_Qty,d_Region,B16) | H16: =COUNTIFS(d_Region,B16) | I16: =D16/$D$20 | J16: =IFERROR(D16/H16,0) | K16: =RANK(D16,$D$15:$D$19)
B17: Ibadan | C17: =INDEX($C$36:$G$36,MATCH(MAX(C39:G39),C39:G39,0)) | D17: =SUMIFS(d_Rev,d_Region,B17) | E17: =SUMIFS(d_Profit,d_Region,B17) | F17: =IFERROR(E17/D17,0) | G17: =SUMIFS(d_Qty,d_Region,B17) | H17: =COUNTIFS(d_Region,B17) | I17: =D17/$D$20 | J17: =IFERROR(D17/H17,0) | K17: =RANK(D17,$D$15:$D$19)
B18: Kano | C18: =INDEX($C$36:$G$36,MATCH(MAX(C40:G40),C40:G40,0)) | D18: =SUMIFS(d_Rev,d_Region,B18) | E18: =SUMIFS(d_Profit,d_Region,B18) | F18: =IFERROR(E18/D18,0) | G18: =SUMIFS(d_Qty,d_Region,B18) | H18: =COUNTIFS(d_Region,B18) | I18: =D18/$D$20 | J18: =IFERROR(D18/H18,0) | K18: =RANK(D18,$D$15:$D$19)
B19: Port Harcourt | C19: =INDEX($C$36:$G$36,MATCH(MAX(C41:G41),C41:G41,0)) | D19: =SUMIFS(d_Rev,d_Region,B19) | E19: =SUMIFS(d_Profit,d_Region,B19) | F19: =IFERROR(E19/D19,0) | G19: =SUMIFS(d_Qty,d_Region,B19) | H19: =COUNTIFS(d_Region,B19) | I19: =D19/$D$20 | J19: =IFERROR(D19/H19,0) | K19: =RANK(D19,$D$15:$D$19)
B20: Total | D20: =SUM(D15:D19) | E20: =SUM(E15:E19) | F20: =IFERROR(E20/D20,0) | G20: =SUM(G15:G19) | H20: =SUM(H15:H19) | I20: =SUM(I15:I19) | J20: =IFERROR(D20/H20,0)
B22: 3 · MONTHLY TREND
B23: Month | C23: Month No | D23: Revenue | E23: Profit | F23: Margin % | G23: Units | H23: Orders | I23: MoM Revenue Δ | J23: Cumulative Revenue | K23: vs Monthly Avg
B24: 46023 | C24: =MONTH(B24) | D24: =SUMIFS(d_Rev,d_MonthNo,C24) | E24: =SUMIFS(d_Profit,d_MonthNo,C24) | F24: =IFERROR(E24/D24,0) | G24: =SUMIFS(d_Qty,d_MonthNo,C24) | H24: =COUNTIFS(d_MonthNo,C24) | I24: — | J24: =SUM($D$24:D24) | K24: =IFERROR(D24/AVERAGE($D$24:$D$32)-1,0)
B25: 46054 | C25: =MONTH(B25) | D25: =SUMIFS(d_Rev,d_MonthNo,C25) | E25: =SUMIFS(d_Profit,d_MonthNo,C25) | F25: =IFERROR(E25/D25,0) | G25: =SUMIFS(d_Qty,d_MonthNo,C25) | H25: =COUNTIFS(d_MonthNo,C25) | I25: =IFERROR(D25/D24-1,0) | J25: =SUM($D$24:D25) | K25: =IFERROR(D25/AVERAGE($D$24:$D$32)-1,0)
B26: 46082 | C26: =MONTH(B26) | D26: =SUMIFS(d_Rev,d_MonthNo,C26) | E26: =SUMIFS(d_Profit,d_MonthNo,C26) | F26: =IFERROR(E26/D26,0) | G26: =SUMIFS(d_Qty,d_MonthNo,C26) | H26: =COUNTIFS(d_MonthNo,C26) | I26: =IFERROR(D26/D25-1,0) | J26: =SUM($D$24:D26) | K26: =IFERROR(D26/AVERAGE($D$24:$D$32)-1,0)
B27: 46113 | C27: =MONTH(B27) | D27: =SUMIFS(d_Rev,d_MonthNo,C27) | E27: =SUMIFS(d_Profit,d_MonthNo,C27) | F27: =IFERROR(E27/D27,0) | G27: =SUMIFS(d_Qty,d_MonthNo,C27) | H27: =COUNTIFS(d_MonthNo,C27) | I27: =IFERROR(D27/D26-1,0) | J27: =SUM($D$24:D27) | K27: =IFERROR(D27/AVERAGE($D$24:$D$32)-1,0)
B28: 46143 | C28: =MONTH(B28) | D28: =SUMIFS(d_Rev,d_MonthNo,C28) | E28: =SUMIFS(d_Profit,d_MonthNo,C28) | F28: =IFERROR(E28/D28,0) | G28: =SUMIFS(d_Qty,d_MonthNo,C28) | H28: =COUNTIFS(d_MonthNo,C28) | I28: =IFERROR(D28/D27-1,0) | J28: =SUM($D$24:D28) | K28: =IFERROR(D28/AVERAGE($D$24:$D$32)-1,0)
B29: 46174 | C29: =MONTH(B29) | D29: =SUMIFS(d_Rev,d_MonthNo,C29) | E29: =SUMIFS(d_Profit,d_MonthNo,C29) | F29: =IFERROR(E29/D29,0) | G29: =SUMIFS(d_Qty,d_MonthNo,C29) | H29: =COUNTIFS(d_MonthNo,C29) | I29: =IFERROR(D29/D28-1,0) | J29: =SUM($D$24:D29) | K29: =IFERROR(D29/AVERAGE($D$24:$D$32)-1,0)
B30: 46204 | C30: =MONTH(B30) | D30: =SUMIFS(d_Rev,d_MonthNo,C30) | E30: =SUMIFS(d_Profit,d_MonthNo,C30) | F30: =IFERROR(E30/D30,0) | G30: =SUMIFS(d_Qty,d_MonthNo,C30) | H30: =COUNTIFS(d_MonthNo,C30) | I30: =IFERROR(D30/D29-1,0) | J30: =SUM($D$24:D30) | K30: =IFERROR(D30/AVERAGE($D$24:$D$32)-1,0)
B31: 46235 | C31: =MONTH(B31) | D31: =SUMIFS(d_Rev,d_MonthNo,C31) | E31: =SUMIFS(d_Profit,d_MonthNo,C31) | F31: =IFERROR(E31/D31,0) | G31: =SUMIFS(d_Qty,d_MonthNo,C31) | H31: =COUNTIFS(d_MonthNo,C31) | I31: =IFERROR(D31/D30-1,0) | J31: =SUM($D$24:D31) | K31: =IFERROR(D31/AVERAGE($D$24:$D$32)-1,0)
B32: 46266 | C32: =MONTH(B32) | D32: =SUMIFS(d_Rev,d_MonthNo,C32) | E32: =SUMIFS(d_Profit,d_MonthNo,C32) | F32: =IFERROR(E32/D32,0) | G32: =SUMIFS(d_Qty,d_MonthNo,C32) | H32: =COUNTIFS(d_MonthNo,C32) | I32: =IFERROR(D32/D31-1,0) | J32: =SUM($D$24:D32) | K32: =IFERROR(D32/AVERAGE($D$24:$D$32)-1,0)
B33: Total | D33: =SUM(D24:D32) | E33: =SUM(E24:E32) | F33: =IFERROR(E33/D33,0) | G33: =SUM(G24:G32) | H33: =SUM(H24:H32)
B35: 4 · REVENUE HEATMAP — REGION × PRODUCT
B36: Region | C36: Laptop | D36: Tablet | E36: Phone | F36: Smartwatch | G36: Headphones | H36: Total
B37: Abuja | C37: =SUMIFS(d_Rev,d_Region,$B37,d_Product,C$36) | D37: =SUMIFS(d_Rev,d_Region,$B37,d_Product,D$36) | E37: =SUMIFS(d_Rev,d_Region,$B37,d_Product,E$36) | F37: =SUMIFS(d_Rev,d_Region,$B37,d_Product,F$36) | G37: =SUMIFS(d_Rev,d_Region,$B37,d_Product,G$36) | H37: =SUM(C37:G37)
B38: Lagos | C38: =SUMIFS(d_Rev,d_Region,$B38,d_Product,C$36) | D38: =SUMIFS(d_Rev,d_Region,$B38,d_Product,D$36) | E38: =SUMIFS(d_Rev,d_Region,$B38,d_Product,E$36) | F38: =SUMIFS(d_Rev,d_Region,$B38,d_Product,F$36) | G38: =SUMIFS(d_Rev,d_Region,$B38,d_Product,G$36) | H38: =SUM(C38:G38)
B39: Ibadan | C39: =SUMIFS(d_Rev,d_Region,$B39,d_Product,C$36) | D39: =SUMIFS(d_Rev,d_Region,$B39,d_Product,D$36) | E39: =SUMIFS(d_Rev,d_Region,$B39,d_Product,E$36) | F39: =SUMIFS(d_Rev,d_Region,$B39,d_Product,F$36) | G39: =SUMIFS(d_Rev,d_Region,$B39,d_Product,G$36) | H39: =SUM(C39:G39)
B40: Kano | C40: =SUMIFS(d_Rev,d_Region,$B40,d_Product,C$36) | D40: =SUMIFS(d_Rev,d_Region,$B40,d_Product,D$36) | E40: =SUMIFS(d_Rev,d_Region,$B40,d_Product,E$36) | F40: =SUMIFS(d_Rev,d_Region,$B40,d_Product,F$36) | G40: =SUMIFS(d_Rev,d_Region,$B40,d_Product,G$36) | H40: =SUM(C40:G40)
B41: Port Harcourt | C41: =SUMIFS(d_Rev,d_Region,$B41,d_Product,C$36) | D41: =SUMIFS(d_Rev,d_Region,$B41,d_Product,D$36) | E41: =SUMIFS(d_Rev,d_Region,$B41,d_Product,E$36) | F41: =SUMIFS(d_Rev,d_Region,$B41,d_Product,F$36) | G41: =SUMIFS(d_Rev,d_Region,$B41,d_Product,G$36) | H41: =SUM(C41:G41)
B42: Total | C42: =SUM(C37:C41) | D42: =SUM(D37:D41) | E42: =SUM(E37:E41) | F42: =SUM(F37:F41) | G42: =SUM(G37:G41) | H42: =SUM(H37:H41)
B44: 5 · PROFIT MARGIN HEATMAP — REGION × PRODUCT
B45: Region | C45: Laptop | D45: Tablet | E45: Phone | F45: Smartwatch | G45: Headphones | H45: All Products
B46: Abuja | C46: =IFERROR(SUMIFS(d_Profit,d_Region,$B46,d_Product,C$45)/SUMIFS(d_Rev,d_Region,$B46,d_Product,C$45),0) | D46: =IFERROR(SUMIFS(d_Profit,d_Region,$B46,d_Product,D$45)/SUMIFS(d_Rev,d_Region,$B46,d_Product,D$45),0) | E46: =IFERROR(SUMIFS(d_Profit,d_Region,$B46,d_Product,E$45)/SUMIFS(d_Rev,d_Region,$B46,d_Product,E$45),0) | F46: =IFERROR(SUMIFS(d_Profit,d_Region,$B46,d_Product,F$45)/SUMIFS(d_Rev,d_Region,$B46,d_Product,F$45),0) | G46: =IFERROR(SUMIFS(d_Profit,d_Region,$B46,d_Product,G$45)/SUMIFS(d_Rev,d_Region,$B46,d_Product,G$45),0) | H46: =IFERROR(SUMIFS(d_Profit,d_Region,$B46)/SUMIFS(d_Rev,d_Region,$B46),0)
...

Sheet Insights
B1: INSIGHTS & RECOMMENDATIONS | Generated live from the data
B4: KEY FINDINGS
B5: F1 | C5: =INDEX(Analysis!$B$6:$B$10,MATCH(MAX(Analysis!$D$6:$D$10),Analysis!$D$6:$D$10,0))&" is the revenue engine, contributing "&TEXT(MAX(Analysis!$I$6:$I$10),"0.0%")&" of total revenue (₦"&TEXT(MAX(Analysis!$D$6:$D$10)/1000000,"#,##0.0")&"M of ₦"&TEXT(Analysis!$D$11/1000000,"#,##0.0")&"M)."
B6: F2 | C6: ="Revenue is concentrated: the top two products ("&Analysis!B6&" and "&Analysis!B7&") deliver "&TEXT(Analysis!J7,"0.0%")&" of sales, so a demand or supply shock in either line hits the whole business."
B7: F3 | C7: ="Margin gap: "&INDEX(Analysis!$B$6:$B$10,MATCH(MIN(Analysis!$F$6:$F$10),Analysis!$F$6:$F$10,0))&" has the thinnest margin ("&TEXT(MIN(Analysis!$F$6:$F$10),"0.0%")&") while "&INDEX(Analysis!$B$6:$B$10,MATCH(MAX(Analysis!$F$6:$F$10),Analysis!$F$6:$F$10,0))&" is the most profitable per naira sold ("&TEXT(MAX(Analysis!$F$6:$F$10),"0.0%")&"). Company average: "&TEXT(Analysis!F11,"0.0%")&"."
B8: F4 | C8: =Analysis!B15&" is the strongest region at ₦"&TEXT(Analysis!D15/1000000,"#,##0.0")&"M ("&TEXT(Analysis!I15,"0.0%")&"); together with "&Analysis!B16&" it generates "&TEXT(Analysis!I15+Analysis!I16,"0.0%")&" of revenue."
B9: F5 | C9: =INDEX(Analysis!$B$15:$B$19,MATCH(MAX(Analysis!$F$15:$F$19),Analysis!$F$15:$F$19,0))&" earns the best regional margin ("&TEXT(MAX(Analysis!$F$15:$F$19),"0.0%")&") yet ranks "&INDEX(Analysis!$K$15:$K$19,MATCH(MAX(Analysis!$F$15:$F$19),Analysis!$F$15:$F$19,0))&" of 5 on revenue, while "&INDEX(Analysis!$B$15:$B$19,MATCH(MIN(Analysis!$F$15:$F$19),Analysis!$F$15:$F$19,0))&" has the weakest margin ("&TEXT(MIN(Analysis!$F$15:$F$19),"0.0%")&")."
B10: F6 | C10: ="Revenue peaked in "&TEXT(INDEX(Analysis!$B$24:$B$32,MATCH(MAX(Analysis!$D$24:$D$32),Analysis!$D$24:$D$32,0)),"mmmm")&" (₦"&TEXT(MAX(Analysis!$D$24:$D$32)/1000000,"#,##0.0")&"M) and was weakest in "&TEXT(INDEX(Analysis!$B$24:$B$32,MATCH(MIN(Analysis!$D$24:$D$32),Analysis!$D$24:$D$32,0)),"mmmm")&" (₦"&TEXT(MIN(Analysis!$D$24:$D$32)/1000000,"#,##0.0")&"M). The latest month moved "&TEXT(Analysis!I32,"+0.0%;-0.0%")&" versus the month before."
B11: F7 | C11: =Analysis!B10&" is volume-heavy but value-light: "&TEXT(Analysis!G10/Analysis!G11,"0.0%")&" of units sold but only "&TEXT(Analysis!I10,"0.0%")&" of revenue."
B12: F8 | C12: =Analysis!B40&" has a distinctive demand profile: "&Analysis!D36&" makes up "&TEXT(Analysis!D40/Analysis!H40,"0%")&" of its revenue, versus "&TEXT(Analysis!D42/Analysis!H42,"0%")&" company-wide."
B15: RECOMMENDATIONS
B16: # | C16: Recommendation | D16: Evidence from the data | E16: Illustrative profit upside
B17: 1 | C17: ="Protect "&Analysis!B6&" margins: renegotiate supplier cost, introduce tiered pricing or bundle accessories to lift margin on the top-selling line." | D17: ="Largest revenue line ("&TEXT(Analysis!I6,"0.0%")&" of sales) with a "&TEXT(Analysis!F6,"0.0%")&" margin vs "&TEXT(Analysis!F11,"0.0%")&" company average." | E17: =Analysis!D6*$E$27
B18: 2 | C18: ="Lift "&INDEX(Analysis!$B$15:$B$19,MATCH(MIN(Analysis!$F$15:$F$19),Analysis!$F$15:$F$19,0))&" margins toward the company average: review discounting, delivery cost and product mix." | D18: =INDEX(Analysis!$B$15:$B$19,MATCH(MIN(Analysis!$F$15:$F$19),Analysis!$F$15:$F$19,0))&" margin is "&TEXT(MIN(Analysis!$F$15:$F$19),"0.0%")&" vs "&TEXT(Analysis!F20,"0.0%")&" company-wide, on ₦"&TEXT(INDEX(Analysis!$D$15:$D$19,MATCH(MIN(Analysis!$F$15:$F$19),Analysis!$F$15:$F$19,0))/1000000,"#,##0.0")&"M revenue." | E18: =INDEX(Analysis!$D$15:$D$19,MATCH(MIN(Analysis!$F$15:$F$19),Analysis!$F$15:$F$19,0))*(Analysis!F20-MIN(Analysis!$F$15:$F$19))*$E$28
B19: 3 | C19: ="Prioritise "&INDEX(Analysis!$B$6:$B$10,MATCH(MAX(Analysis!$F$6:$F$10),Analysis!$F$6:$F$10,0))&" in marketing and inventory planning: it turns revenue into profit most efficiently." | D19: =INDEX(Analysis!$B$6:$B$10,MATCH(MAX(Analysis!$F$6:$F$10),Analysis!$F$6:$F$10,0))&" earns a "&TEXT(MAX(Analysis!$F$6:$F$10),"0.0%")&" margin, the best of all product lines." | E19: =INDEX(Analysis!$D$6:$D$10,MATCH(MAX(Analysis!$F$6:$F$10),Analysis!$F$6:$F$10,0))*$E$29*MAX(Analysis!$F$6:$F$10)
B20: 4 | C20: ="Scale what works in "&INDEX(Analysis!$B$15:$B$19,MATCH(MAX(Analysis!$F$15:$F$19),Analysis!$F$15:$F$19,0))&": replicate its pricing and cost discipline and expand reach in this high-margin market." | D20: =INDEX(Analysis!$B$15:$B$19,MATCH(MAX(Analysis!$F$15:$F$19),Analysis!$F$15:$F$19,0))&" has the best margin ("&TEXT(MAX(Analysis!$F$15:$F$19),"0.0%")&") but ranks "&INDEX(Analysis!$K$15:$K$19,MATCH(MAX(Analysis!$F$15:$F$19),Analysis!$F$15:$F$19,0))&" of 5 on revenue." | E20: =INDEX(Analysis!$D$15:$D$19,MATCH(MAX(Analysis!$F$15:$F$19),Analysis!$F$15:$F$19,0))*$E$29*MAX(Analysis!$F$15:$F$19)
B21: 5 | C21: ="Grow "&Analysis!B10&" through bundling and attach-selling with "&Analysis!B6&" and "&Analysis!B8&" purchases (high volume, low ticket size)." | D21: =Analysis!B10&" = "&TEXT(Analysis!G10/Analysis!G11,"0.0%")&" of units but "&TEXT(Analysis!I10,"0.0%")&" of revenue." | E21: =Analysis!E10*$E$29
B22: 6 | C22: ="Investigate the "&TEXT(Analysis!B32,"mmmm")&" revenue dip: check stock-outs, promotions and sales coverage, and add a monthly early-warning KPI." | D22: ="Revenue in "&TEXT(Analysis!B32,"mmmm")&" was "&TEXT(ABS(Analysis!K32),"0%")&IF(Analysis!K32<0," below"," above")&" the monthly average ("&TEXT(Analysis!I32,"+0.0%;-0.0%")&" vs prior month)." | E22: =MAX(0,AVERAGE(Analysis!$D$24:$D$32)-Analysis!D32)*Analysis!F33
B23: Upside figures are illustrative scenarios built on the assumptions below. They overlap, so they should not be added together.
B25: ASSUMPTIONS (editable — yellow cells)
B26: Source: analyst assumptions (not from the dataset). Change them to test other scenarios.
B27: Margin improvement on the top-selling product (percentage points) | E27: 0.01
B28: Share of the margin gap closed in the weakest-margin region | E28: 0.5
B29: Illustrative revenue growth for targeted products / regions | E29: 0.1

Sheet Sales Data
A1: Order ID | B1: Date | C1: Region | D1: Product | E1: Category | F1: Quantity | G1: Unit Price | H1: Revenue | I1: Cost | J1: Profit | K1: Month | L1: Margin % | M1: Quarter | N1: Month No
A2: ORD-1001 | B2: 46023 | C2: Kano | D2: Headphones | E2: Accessories | F2: 5 | G2: 41581.1 | H2: 207905.48 | I2: 160405.73 | J2: 47499.74 | K2: Jan | L2: =IFERROR(J2/H2,0) | M2: ="Q"&ROUNDUP(MONTH(B2)/3,0) | N2: =MONTH(B2)
A3: ORD-1002 | B3: 46025 | C3: Kano | D3: Phone | E3: Mobile | F3: 3 | G3: 253118.31 | H3: 759354.94 | I3: 532334.21 | J3: 227020.74 | K3: Jan | L3: =IFERROR(J3/H3,0) | M3: ="Q"&ROUNDUP(MONTH(B3)/3,0) | N3: =MONTH(B3)
A4: ORD-1003 | B4: 46027 | C4: Ibadan | D4: Headphones | E4: Accessories | F4: 3 | G4: 39822.31 | H4: 119466.94 | I4: 97172.04 | J4: 22294.9 | K4: Jan | L4: =IFERROR(J4/H4,0) | M4: ="Q"&ROUNDUP(MONTH(B4)/3,0) | N4: =MONTH(B4)
A5: ORD-1004 | B5: 46029 | C5: Kano | D5: Phone | E5: Mobile | F5: 4 | G5: 258724.78 | H5: 1034899.1 | I5: 690208.69 | J5: 344690.45 | K5: Jan | L5: =IFERROR(J5/H5,0) | M5: ="Q"&ROUNDUP(MONTH(B5)/3,0) | N5: =MONTH(B5)
A6: ORD-1005 | B6: 46032 | C6: Lagos | D6: Headphones | E6: Accessories | F6: 1 | G6: 42745.27 | H6: 42745.27 | I6: 31401.01 | J6: 11344.27 | K6: Jan | L6: =IFERROR(J6/H6,0) | M6: ="Q"&ROUNDUP(MONTH(B6)/3,0) | N6: =MONTH(B6)
A7: ORD-1006 | B7: 46034 | C7: Port Harcourt | D7: Headphones | E7: Accessories | F7: 4 | G7: 43556.71 | H7: 174226.83 | I7: 122017.22 | J7: 52209.61 | K7: Jan | L7: =IFERROR(J7/H7,0) | M7: ="Q"&ROUNDUP(MONTH(B7)/3,0) | N7: =MONTH(B7)
A8: ORD-1007 | B8: 46036 | C8: Port Harcourt | D8: Headphones | E8: Accessories | F8: 4 | G8: 45998.08 | H8: 183992.31 | I8: 112275.62 | J8: 71716.69 | K8: Jan | L8: =IFERROR(J8/H8,0) | M8: ="Q"&ROUNDUP(MONTH(B8)/3,0) | N8: =MONTH(B8)
A9: ORD-1008 | B9: 46039 | C9: Ibadan | D9: Smartwatch | E9: Wearables | F9: 1 | G9: 76127.05 | H9: 76127.05 | I9: 61568.12 | J9: 14558.93 | K9: Jan | L9: =IFERROR(J9/H9,0) | M9: ="Q"&ROUNDUP(MONTH(B9)/3,0) | N9: =MONTH(B9)
A10: ORD-1009 | B10: 46041 | C10: Ibadan | D10: Phone | E10: Mobile | F10: 2 | G10: 266870.05 | H10: 533740.09 | I10: 331712.99 | J10: 202027.1 | K10: Jan | L10: =IFERROR(J10/H10,0) | M10: ="Q"&ROUNDUP(MONTH(B10)/3,0) | N10: =MONTH(B10)
A11: ORD-1010 | B11: 46043 | C11: Port Harcourt | D11: Headphones | E11: Accessories | F11: 4 | G11: 40918.01 | H11: 163672.05 | I11: 116033.49 | J11: 47638.56 | K11: Jan | L11: =IFERROR(J11/H11,0) | M11: ="Q"&ROUNDUP(MONTH(B11)/3,0) | N11: =MONTH(B11)
A12: ORD-1011 | B12: 46045 | C12: Lagos | D12: Laptop | E12: Computing | F12: 4 | G12: 480343.06 | H12: 1921372.3 | I12: 1472116.1 | J12: 449256.2 | K12: Jan | L12: =IFERROR(J12/H12,0) | M12: ="Q"&ROUNDUP(MONTH(B12)/3,0) | N12: =MONTH(B12)
A13: ORD-1012 | B13: 46048 | C13: Ibadan | D13: Headphones | E13: Accessories | F13: 6 | G13: 39938.18 | H13: 239629.1 | I13: 188181.37 | J13: 51447.73 | K13: Jan | L13: =IFERROR(J13/H13,0) | M13: ="Q"&ROUNDUP(MONTH(B13)/3,0) | N13: =MONTH(B13)
... A121: ORD-1120 | B121: 46295 | C121: Kano | D121: Tablet | E121: Mobile | F121: 5 | G121: 210088.25 | H121: 1050441.3 | I121: 726548.82 | J121: 323892.43 | K121: Sep | L121: =IFERROR(J121/H121,0) | M121: ="Q"&ROUNDUP(MONTH(B121)/3,0) | N121: =MONTH(B121)

Sheet Data Checks
B1: DATA QUALITY & RECONCILIATION CHECKS
B4: # | C4: Check | D4: Result | E4: Expected | F4: Status
B5: 1 | C5: Records loaded | D5: =COUNTA(d_Order) | E5: 120 | F5: =IF(D5=E5,"PASS","FAIL")
B6: 2 | C6: Blank cells in the 11 source columns | D6: =COUNTBLANK('Sales Data'!A2:K121) | E6: 0 | F6: =IF(D6=E6,"PASS","FAIL")
B7: 3 | C7: Duplicate Order IDs | D7: =SUMPRODUCT((COUNTIF(d_Order,d_Order)>1)*1) | E7: 0 | F7: =IF(D7=E7,"PASS","FAIL")
B8: 4 | C8: Rows where Revenue ≠ Quantity × Unit Price (tolerance ₦1) | D8: =SUMPRODUCT((ABS(d_Qty*d_Price-d_Rev)>1)*1) | E8: 0 | F8: =IF(D8=E8,"PASS","FAIL")
B9: 5 | C9: Rows where Profit ≠ Revenue − Cost (tolerance ₦1) | D9: =SUMPRODUCT((ABS(d_Rev-d_Cost-d_Profit)>1)*1) | E9: 0 | F9: =IF(D9=E9,"PASS","FAIL")
B10: 6 | C10: Zero or negative quantities / prices | D10: =COUNTIF(d_Qty,"<=0")+COUNTIF(d_Price,"<=0") | E10: 0 | F10: =IF(D10=E10,"PASS","FAIL")
B11: 7 | C11: Month label does not match the order date | D11: =SUMPRODUCT((TEXT(d_Date,"mmm")<>d_Month)*1) | E11: 0 | F11: =IF(D11=E11,"PASS","FAIL")
B12: 8 | C12: Order dates still carrying a time-of-day stamp | D12: =SUMPRODUCT((d_Date<>INT(d_Date))*1) | E12: 0 | F12: =IF(D12=E12,"PASS","FAIL")
B13: 9 | C13: Revenue: product, region and month totals vs raw data (₦ difference) | D13: =ROUND(ABS(Analysis!D11-SUM(d_Rev))+ABS(Analysis!D20-SUM(d_Rev))+ABS(Analysis!D33-SUM(d_Rev)),0) | E13: 0 | F13: =IF(D13=E13,"PASS","FAIL")
B14: 10 | C14: Profit: product, region and month totals vs raw data (₦ difference) | D14: =ROUND(ABS(Analysis!E11-SUM(d_Profit))+ABS(Analysis!E20-SUM(d_Profit))+ABS(Analysis!E33-SUM(d_Profit)),0) | E14: 0 | F14: =IF(D14=E14,"PASS","FAIL")
B15: 11 | C15: Order counts: product, region and month totals vs raw data | D15: =ABS(Analysis!H11-COUNTA(d_Order))+ABS(Analysis!H20-COUNTA(d_Order))+ABS(Analysis!H33-COUNTA(d_Order)) | E15: 0 | F15: =IF(D15=E15,"PASS","FAIL")
B17: =IF(COUNTIF(F5:F15,"FAIL")=0,"✔ ALL "&COUNTA(F5:F15)&" CHECKS PASSED","⚠ "&COUNTIF(F5:F15,"FAIL")&" CHECK(S) FAILED — review above")
B19: DATA CLEANING LOG
B20: 1. | C20: 102 of 120 order dates carried spurious time-of-day stamps (e.g. 03-Jan-2026 06:51); normalised to whole dates so daily/monthly grouping is exact.
B21: 2. | C21: Added helper columns to the sales table: Margin %, Quarter and Month No (all formulas).
B22: 3. | C22: Converted the data range into an Excel Table (SalesTable) and created named ranges (d_Rev, d_Region, …) so every formula reads clearly.
B23: 4. | C23: Replaced every hard-coded number in the original Dashboard / Analysis sheets with live formulas that recalculate from the raw data.
B24: 5. | C24: Validated Revenue = Qty × Price and Profit = Revenue − Cost for all rows (max difference ₦0.03, rounding only).

Sheet Read Me
B1: SALES DATA ANALYSIS & INTERACTIVE DASHBOARD | Project Read Me
B4: PROJECT OVERVIEW
B5: Prepared by | C5: Williams Favour Ifunanya
B6: Tool | C6: Microsoft Excel (formulas, named ranges, data validation, conditional formatting, charts)
B7: Objective | C7: Turn raw sales records into a decision-ready, interactive performance dashboard that shows what sells, where, when and how profitably.
B8: Dataset | C8: 120 sales orders · Jan–Sep 2026 · 5 regions (Abuja, Lagos, Ibadan, Kano, Port Harcourt) · 5 products · 11 source fields · values in Nigerian Naira (₦).
B9: Business questions | C9: Which products and regions drive revenue and profit? Where are margins strongest or weakest? How does revenue move month to month? Where is the biggest profit opportunity?
B11: HOW TO USE
B12: Filter the dashboard | C12: On the Dashboard, tap the yellow Region / Product cells and pick a value. Every KPI card and chart updates.
B13: Run scenarios | C13: Analysis → section 7 (What-If Simulator) and Insights → Assumptions: change the yellow cells to test margin or growth scenarios.
B14: Colour code | C14: Blue text = input you can change · Black = formula · Yellow fill = editable cell.
B16: SHEET GUIDE
B17: Dashboard | C17: Filterable KPI cards, 4 charts and auto-generated key takeaways.
B18: Analysis | C18: Product, region and monthly performance; region × product revenue and margin heatmaps; top 10 orders; what-if simulator.
B19: Insights | C19: Eight formula-generated findings and six recommendations with illustrative profit upside.
B20: Sales Data | C20: Cleaned transaction table (SalesTable) with helper columns.
B21: Data Checks | C21: 11 automated validation and reconciliation checks plus the cleaning log.
B22: Chart Data / Lists | C22: Supporting tables that feed the charts and dropdowns.
B24: EXCEL SKILLS DEMONSTRATED
B25: Formulas | C25: SUMIFS, COUNTIFS, INDEX/MATCH, RANK, LARGE, SUMPRODUCT, IFERROR, TEXT, wildcard criteria for “All” filters
B26: Modelling | C26: Named ranges, Excel Table, input/assumption cells, scenario (what-if) analysis, reconciliation checks
B27: Visualisation | C27: Interactive dashboard, KPI cards, charts, data bars, colour-scale heatmaps, dropdown controls
B28: Analysis | C28: Pareto / concentration analysis, margin analysis, month-on-month growth, ranking, regional × product mix
B30: HEADLINE RESULTS
B31: Scale | C31: ₦95.4M revenue and ₦27.2M profit at a 28.6% margin across 120 orders.
B32: Product mix | C32: Laptops generate 48.7% of revenue but earn the thinnest margin (27.1%); each +1 point of laptop margin is worth about ₦464,659 in profit.
B33: Regions | C33: Abuja leads on revenue (₦26.3M); Port Harcourt has the best margin (33.0%) on the smallest revenue base; Ibadan is weakest on margin (25.2%).
B35: CV BULLETS (copy & paste)
B36: Bullet 1 | C36: Built an interactive Excel sales dashboard (dropdown filters, KPI cards, 4 charts) analysing ₦95.4M revenue across 120 orders, 5 regions and 5 product lines using SUMIFS, INDEX/MATCH, named ranges and data validation.
B37: Bullet 2 | C37: Cleaned and validated the dataset (102 timestamped dates normalised) and built 11 automated reconciliation checks, with every dashboard figure formula-driven rather than hard-coded.
B38: Bullet 3 | C38: Identified that Laptops drive 48.7% of revenue at the lowest margin (27.1%) and quantified the profit upside of margin improvements through a scenario simulator and region × product heatmaps.
B39: Bullet 4 | C39: Translated analysis into six prioritised, data-backed business recommendations covering pricing, regional margin gaps, product bundling and monthly demand monitoring.
B41: PORTFOLIO SUMMARY
B42: Short description | C42: An end-to-end Excel analytics project: raw sales data was cleaned, validated and modelled into a filterable dashboard with automated insights and a what-if simulator, surfacing a 49% revenue dependence on one product line and clear margin-improvement opportunities.
B44: IMPORTANT NOTE
B45: Data disclaimer | C45: This is a portfolio project built on a sample dataset created for demonstration purposes. It does not represent a real company.

Sheet Chart Data
A1: CHART DATA — feeds Dashboard charts (responds to dropdown filters). Values in ₦ million.
A3: Product | B3: Revenue (₦M) | C3: Profit (₦M) | D3: Margin %
A4: Laptop | B4: =SUMIFS(d_Rev,d_Product,A4,d_Product,crit_P,d_Region,crit_R)/1000000 | C4: =SUMIFS(d_Profit,d_Product,A4,d_Product,crit_P,d_Region,crit_R)/1000000 | D4: =IFERROR(C4/B4,0)
A5: Tablet | B5: =SUMIFS(d_Rev,d_Product,A5,d_Product,crit_P,d_Region,crit_R)/1000000 | C5: =SUMIFS(d_Profit,d_Product,A5,d_Product,crit_P,d_Region,crit_R)/1000000 | D5: =IFERROR(C5/B5,0)
A6: Phone | B6: =SUMIFS(d_Rev,d_Product,A6,d_Product,crit_P,d_Region,crit_R)/1000000 | C6: =SUMIFS(d_Profit,d_Product,A6,d_Product,crit_P,d_Region,crit_R)/1000000 | D6: =IFERROR(C6/B6,0)
A7: Smartwatch | B7: =SUMIFS(d_Rev,d_Product,A7,d_Product,crit_P,d_Region,crit_R)/1000000 | C7: =SUMIFS(d_Profit,d_Product,A7,d_Product,crit_P,d_Region,crit_R)/1000000 | D7: =IFERROR(C7/B7,0)
A8: Headphones | B8: =SUMIFS(d_Rev,d_Product,A8,d_Product,crit_P,d_Region,crit_R)/1000000 | C8: =SUMIFS(d_Profit,d_Product,A8,d_Product,crit_P,d_Region,crit_R)/1000000 | D8: =IFERROR(C8/B8,0)
A11: Region | B11: Revenue (₦M) | C11: Profit (₦M) | D11: Margin %
A12: Abuja | B12: =SUMIFS(d_Rev,d_Region,A12,d_Region,crit_R,d_Product,crit_P)/1000000 | C12: =SUMIFS(d_Profit,d_Region,A12,d_Region,crit_R,d_Product,crit_P)/1000000 | D12: =IFERROR(C12/B12,0)
A13: Lagos | B13: =SUMIFS(d_Rev,d_Region,A13,d_Region,crit_R,d_Product,crit_P)/1000000 | C13: =SUMIFS(d_Profit,d_Region,A13,d_Region,crit_R,d_Product,crit_P)/1000000 | D13: =IFERROR(C13/B13,0)
A14: Ibadan | B14: =SUMIFS(d_Rev,d_Region,A14,d_Region,crit_R,d_Product,crit_P)/1000000 | C14: =SUMIFS(d_Profit,d_Region,A14,d_Region,crit_R,d_Product,crit_P)/1000000 | D14: =IFERROR(C14/B14,0)
A15: Kano | B15: =SUMIFS(d_Rev,d_Region,A15,d_Region,crit_R,d_Product,crit_P)/1000000 | C15: =SUMIFS(d_Profit,d_Region,A15,d_Region,crit_R,d_Product,crit_P)/1000000 | D15: =IFERROR(C15/B15,0)
A16: Port Harcourt | B16: =SUMIFS(d_Rev,d_Region,A16,d_Region,crit_R,d_Product,crit_P)/1000000 | C16: =SUMIFS(d_Profit,d_Region,A16,d_Region,crit_R,d_Product,crit_P)/1000000 | D16: =IFERROR(C16/B16,0)
A19: Month | B19: Revenue (₦M) | C19: Profit (₦M) | D19: Margin % | E19: Month No
A20: Jan | B20: =SUMIFS(d_Rev,d_MonthNo,E20,d_Region,crit_R,d_Product,crit_P)/1000000 | C20: =SUMIFS(d_Profit,d_MonthNo,E20,d_Region,crit_R,d_Product,crit_P)/1000000 | D20: =IFERROR(C20/B20,0) | E20: 1
A21: Feb | B21: =SUMIFS(d_Rev,d_MonthNo,E21,d_Region,crit_R,d_Product,crit_P)/1000000 | C21: =SUMIFS(d_Profit,d_MonthNo,E21,d_Region,crit_R,d_Product,crit_P)/1000000 | D21: =IFERROR(C21/B21,0) | E21: 2
A22: Mar | B22: =SUMIFS(d_Rev,d_MonthNo,E22,d_Region,crit_R,d_Product,crit_P)/1000000 | C22: =SUMIFS(d_Profit,d_MonthNo,E22,d_Region,crit_R,d_Product,crit_P)/1000000 | D22: =IFERROR(C22/B22,0) | E22: 3
A23: Apr | B23: =SUMIFS(d_Rev,d_MonthNo,E23,d_Region,crit_R,d_Product,crit_P)/1000000 | C23: =SUMIFS(d_Profit,d_MonthNo,E23,d_Region,crit_R,d_Product,crit_P)/1000000 | D23: =IFERROR(C23/B23,0) | E23: 4
A24: May | B24: =SUMIFS(d_Rev,d_MonthNo,E24,d_Region,crit_R,d_Product,crit_P)/1000000 | C24: =SUMIFS(d_Profit,d_MonthNo,E24,d_Region,crit_R,d_Product,crit_P)/1000000 | D24: =IFERROR(C24/B24,0) | E24: 5
A25: Jun | B25: =SUMIFS(d_Rev,d_MonthNo,E25,d_Region,crit_R,d_Product,crit_P)/1000000 | C25: =SUMIFS(d_Profit,d_MonthNo,E25,d_Region,crit_R,d_Product,crit_P)/1000000 | D25: =IFERROR(C25/B25,0) | E25: 6
A26: Jul | B26: =SUMIFS(d_Rev,d_MonthNo,E26,d_Region,crit_R,d_Product,crit_P)/1000000 | C26: =SUMIFS(d_Profit,d_MonthNo,E26,d_Region,crit_R,d_Product,crit_P)/1000000 | D26: =IFERROR(C26/B26,0) | E26: 7
A27: Aug | B27: =SUMIFS(d_Rev,d_MonthNo,E27,d_Region,crit_R,d_Product,crit_P)/1000000 | C27: =SUMIFS(d_Profit,d_MonthNo,E27,d_Region,crit_R,d_Product,crit_P)/1000000 | D27: =IFERROR(C27/B27,0) | E27: 8
A28: Sep | B28: =SUMIFS(d_Rev,d_MonthNo,E28,d_Region,crit_R,d_Product,crit_P)/1000000 | C28: =SUMIFS(d_Profit,d_MonthNo,E28,d_Region,crit_R,d_Product,crit_P)/1000000 | D28: =IFERROR(C28/B28,0) | E28: 9

Sheet Lists
A1: Regions | C1: Products | E1: Filter criteria (feed Dashboard formulas)
A2: All Regions | C2: All Products | E2: Region criterion | F2: =IF(Dashboard!C5="All Regions","*",Dashboard!C5)
A3: Abuja | C3: Laptop | E3: Product criterion | F3: =IF(Dashboard!G5="All Products","*",Dashboard!G5)
A4: Lagos | C4: Tablet
A5: Ibadan | C5: Phone | E5: "*" = wildcard that matches every value when "All" is selected.
A6: Kano | C6: Smartwatch
A7: Port Harcourt | C7: Headphones
