Workbook

Sheet Dashboard
B2: CUSTOMER CHURN ANALYSIS | T2: Analyst: Williams Favour
B3: Where are we losing customers, and what is it costing us? | T3: ="Subscription business · "&k_Total&" customers · 5 regions · 3 plans" -> Subscription business · 150 customers · 5 regions · 3 plans
B6: REGION | D6: All | G6: ◂ Pick a region, or All | K6: PLAN | M6: All | P6: ◂ Pick a plan, or All | T6: CONTRACT | V6: All | Y6: ◂ Pick a contract, or All
B8: TOTAL CUSTOMERS | F8: CHURNED CUSTOMERS | K8: CHURN RATE | O8: REVENUE AT RISK | T8: MRR LOST PER MONTH | X8: HIGHEST-RISK SEGMENT
B9: =k_N -> 150 | F9: =k_Churned -> 43 | K9: =k_Rate -> 0.28666667 | O9: =k_Rev -> 9919700 | T9: =k_MRR -> 509600 | X9: =top_Label -> Basic · Monthly
B10: =IF(k_Filtered=0,"Full dataset","Filtered view of "&k_Total&" in dataset") -> Full dataset | F10: ="Retained: "&TEXT(k_Retained,"#,##0") -> Retained: 107 | K10: =IF(k_N=0,"No customers match",IF(k_N<30,"Small sample (n = "&k_N&"): read with care","±"&TEXT(k_MOE,"0.0")&" pp margin of error (95%)")) -> ±7.2 pp margin of error (95%) | O10: Lifetime billings, churned customers | T10: =IF(k_MRRall=0,"",TEXT(k_MRR/k_MRRall,"0.0%")&" of monthly billings") -> 25.9% of monthly billings | X10: =IF(top_Label="n/a","Segments need "&t_MinN&"+ customers",TEXT(top_Rate,"0.0%")&" churn · n = "&top_N) -> 42.9% churn · n = 35
B12: Churn by contract type | K12: Churn by plan | T12: Churn by region
B13: Region + Plan filters applied · dashed line = overall rate | K13: Region + Contract filters applied · dashed line = overall rate | T13: Plan + Contract filters applied · dashed line = overall rate
B31: Churn by tenure group | K31: Risk heatmap: plan × contract | T31: What the data says
B32: All three filters applied · months as a customer | K32: Region filter applied · n = customers in segment | T32: Full sample · live formulas, not typed text
K33: Contract | M33: Basic | O33: Standard | Q33: Premium | T33: 1 | U33: ="Contract is the biggest lever: monthly customers churn at "&TEXT(Analysis!$E$24,"0%")&" vs "&TEXT(Analysis!$E$26,"0%")&" on annual ("&IFERROR(TEXT(Analysis!$E$24/Analysis!$E$26,"0.0")&"x higher","n/a")&")." -> Contract is the biggest lever: monthly customers churn at 35% vs 15% on annual (2.4x higher).
K34: Monthly | M34: =IF('Chart Data'!C51=0,"–",'Chart Data'!E51) -> 0.42857143 | O34: =IF('Chart Data'!C52=0,"–",'Chart Data'!E52) -> 0.30769231 | Q34: =IF('Chart Data'!C53=0,"–",'Chart Data'!E53) -> 0.21428571
M36: ="n = "&'Chart Data'!C51 -> n = 35 | O36: ="n = "&'Chart Data'!C52 -> n = 26 | Q36: ="n = "&'Chart Data'!C53 -> n = 14 | T36: 2 | U36: ="Hotspot: "&Analysis!$L$17&" churns at "&TEXT(Analysis!$N$17,"0%")&" (n = "&Analysis!$O$17&"). Target this segment first." -> Hotspot: Basic · Monthly churns at 43% (n = 35). Target this segment first.
K37: Quarterly | M37: =IF('Chart Data'!C54=0,"–",'Chart Data'!E54) -> 0.31578947 | O37: =IF('Chart Data'!C55=0,"–",'Chart Data'!E55) -> 0.26666667 | Q37: =IF('Chart Data'!C56=0,"–",'Chart Data'!E56) -> 0.28571429
M39: ="n = "&'Chart Data'!C54 -> n = 19 | O39: ="n = "&'Chart Data'!C55 -> n = 15 | Q39: ="n = "&'Chart Data'!C56 -> n = 7 | T39: 3 | U39: ="Two risk windows: months 0-6 ("&TEXT(Analysis!$E$47,"0%")&") and 25+ ("&TEXT(Analysis!$E$50,"0%")&"), vs "&TEXT(Analysis!$E$49,"0%")&" in months 13-24." -> Two risk windows: months 0-6 (38%) and 25+ (34%), vs 21% in months 13-24.
K40: Annual | M40: =IF('Chart Data'!C57=0,"–",'Chart Data'!E57) -> 0.21052632 | O40: =IF('Chart Data'!C58=0,"–",'Chart Data'!E58) -> 0.1 | Q40: =IF('Chart Data'!C59=0,"–",'Chart Data'!E59) -> 0
M42: ="n = "&'Chart Data'!C57 -> n = 19 | O42: ="n = "&'Chart Data'!C58 -> n = 10 | Q42: ="n = "&'Chart Data'!C59 -> n = 5 | T42: 4 | U42: ="Basic churns at "&TEXT(Analysis!$E$31,"0%")&" vs Premium "&TEXT(Analysis!$E$33,"0%")&" (Premium n = "&Analysis!$C$33&", directional only)." -> Basic churns at 34% vs Premium 19% (Premium n = 26, directional only).
K44: Risk tier | M44: ="High ≥ "&TEXT(t_High,"0%") -> High ≥ 35% | O44: Medium | Q44: ="Low < "&TEXT(t_Low,"0%") -> Low < 25%
T45: 5 | U45: ="Support volume shows no clear link to churn: churned and retained customers average "&TEXT(m_SupCh,"0.0")&" vs "&TEXT(m_SupRet,"0.0")&" contacts." -> Support volume shows no clear link to churn: churned and retained customers average 1.7 vs 1.7 contacts.
K46: ="Small groups swing wildly: segments under "&t_MinN&" customers are never named the highest risk." -> Small groups swing wildly: segments under 10 customers are never named the highest risk.
B50: Churn rate = churned ÷ customers · Revenue at risk = lifetime billings of churned customers · MRR lost = monthly charges of churned customers
B51: Synthetic dataset created for portfolio practice · n = 150, so small gaps can be noise (see Analysis for margins of error) · Built in Excel with formulas, named ranges, dropdown filters and conditional formatting

Sheet Analysis
B2: ANALYSIS WORKINGS
B3: Full-sample, formula-driven calculations behind the Dashboard. Blue = editable input · Black = formula · Green = link to another sheet
B6: KEY METRICS | K6: SEGMENT HOTSPOTS · PLAN × CONTRACT
B7: Total customers | C7: =COUNTA(d_Churned) -> 150 | D7: Rows in Customer Data | K7: Plan · Contract | L7: Customers | M7: Churned | N7: Churn rate | O7: Revenue at risk | P7: Ranked rate* | Q7: Rank
B8: Churned customers | C8: =COUNTIF(d_Churned,"Yes") -> 43 | D8: Churned = Yes | K8: Basic · Monthly | L8: =COUNTIFS(d_Plan,"Basic",d_Contract,"Monthly") -> 35 | M8: =COUNTIFS(d_Plan,"Basic",d_Contract,"Monthly",d_Churned,"Yes") -> 15 | N8: =IF(L8=0,0,M8/L8) -> 0.42857143 | O8: =SUMIFS(d_Total,d_Plan,"Basic",d_Contract,"Monthly",d_Churned,"Yes") -> 2250300 | P8: =IF(L8>=t_MinN,N8,-1) -> 0.42857143 | Q8: =IF(P8<0,"–",RANK(P8,$P$8:$P$16)) -> 1
B9: Retained customers | C9: =C7-C8 -> 107 | K9: Standard · Monthly | L9: =COUNTIFS(d_Plan,"Standard",d_Contract,"Monthly") -> 26 | M9: =COUNTIFS(d_Plan,"Standard",d_Contract,"Monthly",d_Churned,"Yes") -> 8 | N9: =IF(L9=0,0,M9/L9) -> 0.30769231 | O9: =SUMIFS(d_Total,d_Plan,"Standard",d_Contract,"Monthly",d_Churned,"Yes") -> 2981000 | P9: =IF(L9>=t_MinN,N9,-1) -> 0.30769231 | Q9: =IF(P9<0,"–",RANK(P9,$P$8:$P$16)) -> 3
B10: Churn rate | C10: =C8/C7 -> 0.28666667 | D10: Churned ÷ total customers | K10: Premium · Monthly | L10: =COUNTIFS(d_Plan,"Premium",d_Contract,"Monthly") -> 14 | M10: =COUNTIFS(d_Plan,"Premium",d_Contract,"Monthly",d_Churned,"Yes") -> 3 | N10: =IF(L10=0,0,M10/L10) -> 0.21428571 | O10: =SUMIFS(d_Total,d_Plan,"Premium",d_Contract,"Monthly",d_Churned,"Yes") -> 1593600 | P10: =IF(L10>=t_MinN,N10,-1) -> 0.21428571 | Q10: =IF(P10<0,"–",RANK(P10,$P$8:$P$16)) -> 5
B11: 95% margin of error (± pp) | C11: =1.96*SQRT(C10*(1-C10)/C7)*100 -> 7.2367788 | D11: Sampling uncertainty on the churn rate at this sample size | K11: Basic · Quarterly | L11: =COUNTIFS(d_Plan,"Basic",d_Contract,"Quarterly") -> 19 | M11: =COUNTIFS(d_Plan,"Basic",d_Contract,"Quarterly",d_Churned,"Yes") -> 6 | N11: =IF(L11=0,0,M11/L11) -> 0.31578947 | O11: =SUMIFS(d_Total,d_Plan,"Basic",d_Contract,"Quarterly",d_Churned,"Yes") -> 831300 | P11: =IF(L11>=t_MinN,N11,-1) -> 0.31578947 | Q11: =IF(P11<0,"–",RANK(P11,$P$8:$P$16)) -> 2
B12: Avg monthly charges (₦) | C12: =AVERAGE(d_Monthly) -> 13128.667 | K12: Standard · Quarterly | L12: =COUNTIFS(d_Plan,"Standard",d_Contract,"Quarterly") -> 15 | M12: =COUNTIFS(d_Plan,"Standard",d_Contract,"Quarterly",d_Churned,"Yes") -> 4 | N12: =IF(L12=0,0,M12/L12) -> 0.26666667 | O12: =SUMIFS(d_Total,d_Plan,"Standard",d_Contract,"Quarterly",d_Churned,"Yes") -> 751800 | P12: =IF(L12>=t_MinN,N12,-1) -> 0.26666667 | Q12: =IF(P12<0,"–",RANK(P12,$P$8:$P$16)) -> 4
B13: Avg monthly charges: churned (₦) | C13: =AVERAGEIFS(d_Monthly,d_Churned,"Yes") -> 11851.163 | D13: Churned customers pay less on average | K13: Premium · Quarterly | L13: =COUNTIFS(d_Plan,"Premium",d_Contract,"Quarterly") -> 7 | M13: =COUNTIFS(d_Plan,"Premium",d_Contract,"Quarterly",d_Churned,"Yes") -> 2 | N13: =IF(L13=0,0,M13/L13) -> 0.28571429 | O13: =SUMIFS(d_Total,d_Plan,"Premium",d_Contract,"Quarterly",d_Churned,"Yes") -> 626700 | P13: =IF(L13>=t_MinN,N13,-1) -> -1 | Q13: =IF(P13<0,"–",RANK(P13,$P$8:$P$16)) -> –
B14: Avg monthly charges: retained (₦) | C14: =AVERAGEIFS(d_Monthly,d_Churned,"No") -> 13642.056 | K14: Basic · Annual | L14: =COUNTIFS(d_Plan,"Basic",d_Contract,"Annual") -> 19 | M14: =COUNTIFS(d_Plan,"Basic",d_Contract,"Annual",d_Churned,"Yes") -> 4 | N14: =IF(L14=0,0,M14/L14) -> 0.21052632 | O14: =SUMIFS(d_Total,d_Plan,"Basic",d_Contract,"Annual",d_Churned,"Yes") -> 839700 | P14: =IF(L14>=t_MinN,N14,-1) -> 0.21052632 | Q14: =IF(P14<0,"–",RANK(P14,$P$8:$P$16)) -> 6
B15: Avg tenure (months) | C15: =AVERAGE(d_Tenure) -> 19.333333 | K15: Standard · Annual | L15: =COUNTIFS(d_Plan,"Standard",d_Contract,"Annual") -> 10 | M15: =COUNTIFS(d_Plan,"Standard",d_Contract,"Annual",d_Churned,"Yes") -> 1 | N15: =IF(L15=0,0,M15/L15) -> 0.1 | O15: =SUMIFS(d_Total,d_Plan,"Standard",d_Contract,"Annual",d_Churned,"Yes") -> 45300 | P15: =IF(L15>=t_MinN,N15,-1) -> 0.1 | Q15: =IF(P15<0,"–",RANK(P15,$P$8:$P$16)) -> 7
B16: Avg support contacts: churned | C16: =AVERAGEIFS(d_Support,d_Churned,"Yes") -> 1.6744186 | D16: Compared with retained below | K16: Premium · Annual | L16: =COUNTIFS(d_Plan,"Premium",d_Contract,"Annual") -> 5 | M16: =COUNTIFS(d_Plan,"Premium",d_Contract,"Annual",d_Churned,"Yes") -> 0 | N16: =IF(L16=0,0,M16/L16) -> 0 | O16: =SUMIFS(d_Total,d_Plan,"Premium",d_Contract,"Annual",d_Churned,"Yes") -> 0 | P16: =IF(L16>=t_MinN,N16,-1) -> -1 | Q16: =IF(P16<0,"–",RANK(P16,$P$8:$P$16)) -> –
B17: Avg support contacts: retained | C17: =AVERAGEIFS(d_Support,d_Churned,"No") -> 1.6915888 | K17: Highest-risk segment | L17: =IF(MAX(P8:P16)<0,"n/a",INDEX(K8:K16,MATCH(MAX(P8:P16),P8:P16,0))) -> Basic · Monthly | N17: =MAX(0,MAX(P8:P16)) -> 0.42857143 | O17: =IF(MAX(P8:P16)<0,0,INDEX(L8:L16,MATCH(MAX(P8:P16),P8:P16,0))) -> 35
B18: Monthly recurring revenue (₦) | C18: =SUM(d_Monthly) -> 1969300 | D18: Sum of monthly charges, all customers | K18: * Only segments with at least the minimum number of customers (set on Chart Data) are ranked, so a tiny group cannot top the list.
B19: MRR lost to churn (₦ / month) | C19: =SUMIFS(d_Monthly,d_Churned,"Yes") -> 509600 | D19: Sum of monthly charges, churned customers
B20: Revenue at risk (₦) | C20: =SUMIFS(d_Total,d_Churned,"Yes") -> 9919700 | D20: Lifetime billings (Total Charges) of churned customers
K21: BUSINESS INSIGHTS · every number is a live formula
B22: CHURN BY CONTRACT TYPE | K22: ="Contract type is the biggest lever: monthly customers churn at "&TEXT(Analysis!$E$24,"0.0%")&" versus "&TEXT(Analysis!$E$26,"0.0%")&" on annual contracts ("&IFERROR(TEXT(Analysis!$E$24/Analysis!$E$26,"0.0")&"x higher","n/a")&")." -> Contract type is the biggest lever: monthly customers churn at 34.7% versus 14.7% on annual contracts (2.4x higher).
B23: Category | C23: Customers | D23: Churned | E23: Churn rate | F23: vs overall | G23: Share of churn
B24: Monthly | C24: =COUNTIFS(d_Contract,$B24) -> 75 | D24: =COUNTIFS(d_Contract,$B24,d_Churned,"Yes") -> 26 | E24: =IF(C24=0,0,D24/C24) -> 0.34666667 | F24: =(E24-m_Rate)*100 -> 6 | G24: =IF(m_Churned=0,0,D24/m_Churned) -> 0.60465116 | K24: ="Hotspot: "&Analysis!$L$17&" customers churn at "&TEXT(Analysis!$N$17,"0.0%")&" (n = "&Analysis!$O$17&"), the first segment to target with retention offers." -> Hotspot: Basic · Monthly customers churn at 42.9% (n = 35), the first segment to target with retention offers.
B25: Quarterly | C25: =COUNTIFS(d_Contract,$B25) -> 41 | D25: =COUNTIFS(d_Contract,$B25,d_Churned,"Yes") -> 12 | E25: =IF(C25=0,0,D25/C25) -> 0.29268293 | F25: =(E25-m_Rate)*100 -> 0.60162602 | G25: =IF(m_Churned=0,0,D25/m_Churned) -> 0.27906977
B26: Annual | C26: =COUNTIFS(d_Contract,$B26) -> 34 | D26: =COUNTIFS(d_Contract,$B26,d_Churned,"Yes") -> 5 | E26: =IF(C26=0,0,D26/C26) -> 0.14705882 | F26: =(E26-m_Rate)*100 -> -13.960784 | G26: =IF(m_Churned=0,0,D26/m_Churned) -> 0.11627907 | K26: ="Tenure shows two risk windows: the first 6 months ("&TEXT(Analysis!$E$47,"0.0%")&") and 25+ months ("&TEXT(Analysis!$E$50,"0.0%")&"), against "&TEXT(Analysis!$E$49,"0.0%")&" for months 13-24." -> Tenure shows two risk windows: the first 6 months (37.5%) and 25+ months (34.0%), against 21.4% for months 13-24.
B27: Total | C27: =SUM(C24:C26) -> 150 | D27: =SUM(D24:D26) -> 43 | E27: =IF(C27=0,0,D27/C27) -> 0.28666667 | G27: =SUM(G24:G26) -> 1 | H27: =IF(C27=m_N,"✓ ties","✗ check") -> ✓ ties
K28: ="Basic plan churns at "&TEXT(Analysis!$E$31,"0.0%")&" versus "&TEXT(Analysis!$E$33,"0.0%")&" on Premium (Premium n = "&Analysis!$C$33&", so read the gap as directional)." -> Basic plan churns at 34.2% versus 19.2% on Premium (Premium n = 26, so read the gap as directional).
B29: CHURN BY PLAN
B30: Category | C30: Customers | D30: Churned | E30: Churn rate | F30: vs overall | G30: Share of churn | K30: ="Highest-churn region is "&INDEX(B38:B42,MATCH(MAX(E38:E42),E38:E42,0))&" at "&TEXT(MAX(E38:E42),"0.0%")&"; the lowest is "&TEXT(MIN(E38:E42),"0.0%")&"." -> Highest-churn region is Kano at 34.6%; the lowest is 23.1%.
B31: Basic | C31: =COUNTIFS(d_Plan,$B31) -> 73 | D31: =COUNTIFS(d_Plan,$B31,d_Churned,"Yes") -> 25 | E31: =IF(C31=0,0,D31/C31) -> 0.34246575 | F31: =(E31-m_Rate)*100 -> 5.5799087 | G31: =IF(m_Churned=0,0,D31/m_Churned) -> 0.58139535
B32: Standard | C32: =COUNTIFS(d_Plan,$B32) -> 51 | D32: =COUNTIFS(d_Plan,$B32,d_Churned,"Yes") -> 13 | E32: =IF(C32=0,0,D32/C32) -> 0.25490196 | F32: =(E32-m_Rate)*100 -> -3.1764706 | G32: =IF(m_Churned=0,0,D32/m_Churned) -> 0.30232558 | K32: ="Support volume shows no clear link to churn: rates sit between "&TEXT(MIN($E$78:$E$82),"0.0%")&" and "&TEXT(MAX($E$78:$E$82),"0.0%")&" for 0-4 contacts, and churned vs retained customers average "&TEXT(m_SupCh,"0.0")&" vs "&TEXT(m_SupRet,"0.0")&" contacts." -> Support volume shows no clear link to churn: rates sit between 21.7% and 34.6% for 0-4 contacts, and churned vs retained customers average 1.7 vs 1.7 contacts.
B33: Premium | C33: =COUNTIFS(d_Plan,$B33) -> 26 | D33: =COUNTIFS(d_Plan,$B33,d_Churned,"Yes") -> 5 | E33: =IF(C33=0,0,D33/C33) -> 0.19230769 | F33: =(E33-m_Rate)*100 -> -9.4358974 | G33: =IF(m_Churned=0,0,D33/m_Churned) -> 0.11627907
B34: Total | C34: =SUM(C31:C33) -> 150 | D34: =SUM(D31:D33) -> 43 | E34: =IF(C34=0,0,D34/C34) -> 0.28666667 | G34: =SUM(G31:G33) -> 1 | H34: =IF(C34=m_N,"✓ ties","✗ check") -> ✓ ties | K34: ="Caution: with "&m_N&" customers the overall churn rate carries a margin of error of about ±"&TEXT(m_MOE,"0.0")&" pp, so gaps of a few customers between segments may be noise." -> Caution: with 150 customers the overall churn rate carries a margin of error of about ±7.2 pp, so gaps of a few customers between segments may be noise.
B36: CHURN BY REGION
B37: Category | C37: Customers | D37: Churned | E37: Churn rate | F37: vs overall | G37: Share of churn | K37: RECOMMENDATIONS
B38: Abuja | C38: =COUNTIFS(d_Region,$B38) -> 31 | D38: =COUNTIFS(d_Region,$B38,d_Churned,"Yes") -> 10 | E38: =IF(C38=0,0,D38/C38) -> 0.32258065 | F38: =(E38-m_Rate)*100 -> 3.5913978 | G38: =IF(m_Churned=0,0,D38/m_Churned) -> 0.23255814 | K38: 1. Put Basic + Monthly customers first: offer a loyalty discount or a free plan upgrade ahead of the typical churn point.
B39: Lagos | C39: =COUNTIFS(d_Region,$B39) -> 31 | D39: =COUNTIFS(d_Region,$B39,d_Churned,"Yes") -> 9 | E39: =IF(C39=0,0,D39/C39) -> 0.29032258 | F39: =(E39-m_Rate)*100 -> 0.3655914 | G39: =IF(m_Churned=0,0,D39/m_Churned) -> 0.20930233
B40: Port Harcourt | C40: =COUNTIFS(d_Region,$B40) -> 36 | D40: =COUNTIFS(d_Region,$B40,d_Churned,"Yes") -> 9 | E40: =IF(C40=0,0,D40/C40) -> 0.25 | F40: =(E40-m_Rate)*100 -> -3.6666667 | G40: =IF(m_Churned=0,0,D40/m_Churned) -> 0.20930233 | K40: 2. Convert monthly customers to quarterly or annual contracts with an incentive; annual contracts churn at a fraction of the monthly rate.
B41: Kano | C41: =COUNTIFS(d_Region,$B41) -> 26 | D41: =COUNTIFS(d_Region,$B41,d_Churned,"Yes") -> 9 | E41: =IF(C41=0,0,D41/C41) -> 0.34615385 | F41: =(E41-m_Rate)*100 -> 5.9487179 | G41: =IF(m_Churned=0,0,D41/m_Churned) -> 0.20930233
B42: Ibadan | C42: =COUNTIFS(d_Region,$B42) -> 26 | D42: =COUNTIFS(d_Region,$B42,d_Churned,"Yes") -> 6 | E42: =IF(C42=0,0,D42/C42) -> 0.23076923 | F42: =(E42-m_Rate)*100 -> -5.5897436 | G42: =IF(m_Churned=0,0,D42/m_Churned) -> 0.13953488 | K42: 3. Build a structured onboarding journey for months 0-6 and a renewal check-in around month 24 to cover the second risk window.
B43: Total | C43: =SUM(C38:C42) -> 150 | D43: =SUM(D38:D42) -> 43 | E43: =IF(C43=0,0,D43/C43) -> 0.28666667 | G43: =SUM(G38:G42) -> 1 | H43: =IF(C43=m_N,"✓ ties","✗ check") -> ✓ ties
K44: 4. Do not use support volume as a churn trigger; record ticket outcomes and satisfaction so the next analysis can test quality, not quantity.
...

Sheet Customer Data
A1: Customer ID | B1: Gender | C1: Age | D1: Age Group | E1: Region | F1: Plan | G1: Contract Type | H1: Tenure (Months) | I1: Monthly Charges (₦) | J1: Total Charges (₦) | K1: Payment Method | L1: Support Interactions | M1: Churned | N1: Signup Date
A2: CUST-0001 | B2: Female | C2: 20 | D2: 18-24 | E2: Port Harcourt | F2: Basic | G2: Monthly | H2: 7 | I2: 8700 | J2: 60900 | K2: Direct Debit | L2: 2 | M2: Yes | N2: 46142
A3: CUST-0002 | B3: Female | C3: 54 | D3: 45-54 | E3: Lagos | F3: Standard | G3: Quarterly | H3: 27 | I3: 13900 | J3: 375300 | K3: USSD | L3: 1 | M3: Yes | N3: 46104
A4: CUST-0003 | B4: Male | C4: 40 | D4: 35-44 | E4: Port Harcourt | F4: Basic | G4: Annual | H4: 22 | I4: 8000 | J4: 176000 | K4: USSD | L4: 1 | M4: No | N4: 46258
A5: CUST-0004 | B5: Female | C5: 43 | D5: 35-44 | E5: Abuja | F5: Standard | G5: Annual | H5: 24 | I5: 14700 | J5: 352800 | K5: Card | L5: 3 | M5: No | N5: 46171
A6: CUST-0005 | B6: Female | C6: 33 | D6: 25-34 | E6: Abuja | F6: Basic | G6: Monthly | H6: 24 | I6: 8000 | J6: 192000 | K6: Card | L6: 0 | M6: Yes | N6: 46148
A7: CUST-0006 | B7: Female | C7: 48 | D7: 45-54 | E7: Kano | F7: Basic | G7: Annual | H7: 36 | I7: 8100 | J7: 291600 | K7: USSD | L7: 4 | M7: No | N7: 46140
A8: CUST-0007 | B8: Female | C8: 39 | D8: 35-44 | E8: Kano | F8: Basic | G8: Monthly | H8: 21 | I8: 8100 | J8: 170100 | K8: Direct Debit | L8: 0 | M8: Yes | N8: 46157
A9: CUST-0008 | B9: Male | C9: 56 | D9: 55+ | E9: Kano | F9: Basic | G9: Annual | H9: 9 | I9: 8500 | J9: 76500 | K9: Card | L9: 2 | M9: No | N9: 46101
A10: CUST-0009 | B10: Female | C10: 62 | D10: 55+ | E10: Kano | F10: Standard | G10: Monthly | H10: 30 | I10: 14600 | J10: 438000 | K10: Card | L10: 5 | M10: Yes | N10: 46159
A11: CUST-0010 | B11: Male | C11: 26 | D11: 25-34 | E11: Port Harcourt | F11: Basic | G11: Monthly | H11: 17 | I11: 9100 | J11: 154700 | K11: Bank Transfer | L11: 1 | M11: Yes | N11: 46175
A12: CUST-0011 | B12: Female | C12: 28 | D12: 25-34 | E12: Port Harcourt | F12: Standard | G12: Quarterly | H12: 34 | I12: 15500 | J12: 527000 | K12: Card | L12: 0 | M12: No | N12: 46180
A13: CUST-0012 | B13: Female | C13: 22 | D13: 18-24 | E13: Lagos | F13: Premium | G13: Annual | H13: 6 | I13: 24400 | J13: 146400 | K13: Card | L13: 1 | M13: No | N13: 46087
... A151: CUST-0150 | B151: Male | C151: 49 | D151: 45-54 | E151: Ibadan | F151: Standard | G151: Quarterly | H151: 33 | I151: 13700 | J151: 452100 | K151: USSD | L151: 2 | M151: No | N151: 46176

Sheet Read Me
B2: Project 2: Customer Churn Analysis
B3: Portfolio project · Excel business analysis
B6: Project type | C6: Portfolio / sample business analysis
B7: Tool | C7: Microsoft Excel
B8: Business problem | C8: A subscription business wants to understand customer churn and identify factors associated with customers leaving.
B9: Objectives | C9: Measure churn, compare churn across plans, contracts, regions and tenure groups, estimate revenue at risk, and provide retention recommendations.
B10: Skills demonstrated | C10: Excel data preparation, descriptive analysis, KPI reporting, interactive dashboard design (dropdown filters, dynamic charts, conditional-format heatmap), churn-rate analysis, insight generation.
B11: Dataset | C11: 150 synthetic customer records created for portfolio practice. This is synthetic data and is not presented as real client work.
B12: How to use the dashboard | C12: On the Dashboard, change the yellow dropdowns (Region, Plan, Contract). KPIs, charts and the heatmap recalculate. Each chart ignores the filter it already slices by, so categories stay comparable.
B13: Data notes | C13: Customer Data is unchanged from the source. Signup Date is not used because dates fall in 2026 while tenure reaches 36 months, so the two fields are inconsistent. With n = 150, small segment differences are descriptive, not statistically tested.
B14: AI disclosure | C14: AI assistance supported project structuring, synthetic-data generation logic, workbook design and quality checking. The final workbook was reviewed for consistency.
B16: WORKBOOK MAP
B17: Dashboard | C17: Interactive one-page view: filters, KPI strip, four charts, risk heatmap, findings.
B18: Analysis | C18: Full-sample formula tables, insights, recommendations, retention what-if, caveats.
B19: Customer Data | C19: Source records (150 rows), formatted only.
B20: Chart Data | C20: Helper calculations that feed the filtered charts. Blue cells are adjustable assumptions.

Sheet Chart Data
B1: CHART DATA · engine behind the Dashboard filters and charts
B2: Do not overwrite formulas here. Blue cells are inputs; green cells link to other sheets. Each chart honours the two filters it does not itself slice by.
B4: FILTER SELECTIONS
B5: Region | C5: =Dashboard!$D$6 -> All | D5: =IF(C5="All","*",C5) -> *
B6: Plan | C6: =Dashboard!$M$6 -> All | D6: =IF(C6="All","*",C6) -> *
B7: Contract | C7: =Dashboard!$V$6 -> All | D7: =IF(C7="All","*",C7) -> *
B9: KPIs FOR THE CURRENT VIEW | F9: ASSUMPTIONS
B10: Customers in view | C10: =COUNTIFS(d_Region,f_Region,d_Plan,f_Plan,d_Contract,f_Contract) -> 150 | F10: High-risk tier at or above | H10: 0.35
B11: Churned customers | C11: =COUNTIFS(d_Region,f_Region,d_Plan,f_Plan,d_Contract,f_Contract,d_Churned,"Yes") -> 43 | F11: Low-risk tier below | H11: 0.25
B12: Retained customers | C12: =C10-C11 -> 107 | F12: Min. customers to rank a segment | H12: 10
B13: Churn rate | C13: =IF(C10=0,0,C11/C10) -> 0.28666667
B14: Revenue at risk (₦) | C14: =SUMIFS(d_Total,d_Region,f_Region,d_Plan,f_Plan,d_Contract,f_Contract,d_Churned,"Yes") -> 9919700 | F14: Tier thresholds are judgement calls set around the overall churn rate; change them and the heatmap recolours.
B15: MRR lost (₦ / month) | C15: =SUMIFS(d_Monthly,d_Region,f_Region,d_Plan,f_Plan,d_Contract,f_Contract,d_Churned,"Yes") -> 509600
B16: MRR in view (₦ / month) | C16: =SUMIFS(d_Monthly,d_Region,f_Region,d_Plan,f_Plan,d_Contract,f_Contract) -> 1969300
B17: 95% margin of error (± pp) | C17: =IF(C10=0,0,1.96*SQRT(C13*(1-C13)/C10)*100) -> 7.2367788
B18: Customers in dataset | C18: =COUNTA(d_Churned) -> 150
B19: Any filter active? (1 = yes) | C19: =IF(AND(C5="All",C6="All",C7="All"),0,1) -> 0
B22: CONTRACT CHART · honours Region + Plan filters
B23: Category | C23: Customers | D23: Churned | E23: Churn rate | F23: Highlight | G23: Other | H23: Benchmark | I23: Axis label
B24: =Analysis!B24 -> Monthly | C24: =COUNTIFS(d_Contract,$B24,d_Region,f_Region,d_Plan,f_Plan) -> 75 | D24: =COUNTIFS(d_Contract,$B24,d_Region,f_Region,d_Plan,f_Plan,d_Churned,"Yes") -> 26 | E24: =IF(C24=0,0,D24/C24) -> 0.34666667 | F24: =IF(AND(C24>0,E24=MAX($E$24:$E$26)),E24,0) -> 0.34666667 | G24: =E24-F24 -> 0 | H24: =k_Rate -> 0.28666667 | I24: =B24&CHAR(10)&"n="&C24 -> Monthly n=75
B25: =Analysis!B25 -> Quarterly | C25: =COUNTIFS(d_Contract,$B25,d_Region,f_Region,d_Plan,f_Plan) -> 41 | D25: =COUNTIFS(d_Contract,$B25,d_Region,f_Region,d_Plan,f_Plan,d_Churned,"Yes") -> 12 | E25: =IF(C25=0,0,D25/C25) -> 0.29268293 | F25: =IF(AND(C25>0,E25=MAX($E$24:$E$26)),E25,0) -> 0 | G25: =E25-F25 -> 0.29268293 | H25: =k_Rate -> 0.28666667 | I25: =B25&CHAR(10)&"n="&C25 -> Quarterly n=41
B26: =Analysis!B26 -> Annual | C26: =COUNTIFS(d_Contract,$B26,d_Region,f_Region,d_Plan,f_Plan) -> 34 | D26: =COUNTIFS(d_Contract,$B26,d_Region,f_Region,d_Plan,f_Plan,d_Churned,"Yes") -> 5 | E26: =IF(C26=0,0,D26/C26) -> 0.14705882 | F26: =IF(AND(C26>0,E26=MAX($E$24:$E$26)),E26,0) -> 0 | G26: =E26-F26 -> 0.14705882 | H26: =k_Rate -> 0.28666667 | I26: =B26&CHAR(10)&"n="&C26 -> Annual n=34
B28: PLAN CHART · honours Region + Contract filters
B29: Category | C29: Customers | D29: Churned | E29: Churn rate | F29: Highlight | G29: Other | H29: Benchmark | I29: Axis label
B30: =Analysis!B31 -> Basic | C30: =COUNTIFS(d_Plan,$B30,d_Region,f_Region,d_Contract,f_Contract) -> 73 | D30: =COUNTIFS(d_Plan,$B30,d_Region,f_Region,d_Contract,f_Contract,d_Churned,"Yes") -> 25 | E30: =IF(C30=0,0,D30/C30) -> 0.34246575 | F30: =IF(AND(C30>0,E30=MAX($E$30:$E$32)),E30,0) -> 0.34246575 | G30: =E30-F30 -> 0 | H30: =k_Rate -> 0.28666667 | I30: =B30&CHAR(10)&"n="&C30 -> Basic n=73
B31: =Analysis!B32 -> Standard | C31: =COUNTIFS(d_Plan,$B31,d_Region,f_Region,d_Contract,f_Contract) -> 51 | D31: =COUNTIFS(d_Plan,$B31,d_Region,f_Region,d_Contract,f_Contract,d_Churned,"Yes") -> 13 | E31: =IF(C31=0,0,D31/C31) -> 0.25490196 | F31: =IF(AND(C31>0,E31=MAX($E$30:$E$32)),E31,0) -> 0 | G31: =E31-F31 -> 0.25490196 | H31: =k_Rate -> 0.28666667 | I31: =B31&CHAR(10)&"n="&C31 -> Standard n=51
B32: =Analysis!B33 -> Premium | C32: =COUNTIFS(d_Plan,$B32,d_Region,f_Region,d_Contract,f_Contract) -> 26 | D32: =COUNTIFS(d_Plan,$B32,d_Region,f_Region,d_Contract,f_Contract,d_Churned,"Yes") -> 5 | E32: =IF(C32=0,0,D32/C32) -> 0.19230769 | F32: =IF(AND(C32>0,E32=MAX($E$30:$E$32)),E32,0) -> 0 | G32: =E32-F32 -> 0.19230769 | H32: =k_Rate -> 0.28666667 | I32: =B32&CHAR(10)&"n="&C32 -> Premium n=26
B34: REGION CHART · honours Plan + Contract filters
B35: Category | C35: Customers | D35: Churned | E35: Churn rate | F35: Highlight | G35: Other | H35: Benchmark | I35: Axis label
B36: =Analysis!B38 -> Abuja | C36: =COUNTIFS(d_Region,$B36,d_Plan,f_Plan,d_Contract,f_Contract) -> 31 | D36: =COUNTIFS(d_Region,$B36,d_Plan,f_Plan,d_Contract,f_Contract,d_Churned,"Yes") -> 10 | E36: =IF(C36=0,0,D36/C36) -> 0.32258065 | F36: =IF(AND(C36>0,E36=MAX($E$36:$E$40)),E36,0) -> 0 | G36: =E36-F36 -> 0.32258065 | H36: =k_Rate -> 0.28666667 | I36: =B36&CHAR(10)&"n="&C36 -> Abuja n=31
B37: =Analysis!B39 -> Lagos | C37: =COUNTIFS(d_Region,$B37,d_Plan,f_Plan,d_Contract,f_Contract) -> 31 | D37: =COUNTIFS(d_Region,$B37,d_Plan,f_Plan,d_Contract,f_Contract,d_Churned,"Yes") -> 9 | E37: =IF(C37=0,0,D37/C37) -> 0.29032258 | F37: =IF(AND(C37>0,E37=MAX($E$36:$E$40)),E37,0) -> 0 | G37: =E37-F37 -> 0.29032258 | H37: =k_Rate -> 0.28666667 | I37: =B37&CHAR(10)&"n="&C37 -> Lagos n=31
B38: =Analysis!B40 -> Port Harcourt | C38: =COUNTIFS(d_Region,$B38,d_Plan,f_Plan,d_Contract,f_Contract) -> 36 | D38: =COUNTIFS(d_Region,$B38,d_Plan,f_Plan,d_Contract,f_Contract,d_Churned,"Yes") -> 9 | E38: =IF(C38=0,0,D38/C38) -> 0.25 | F38: =IF(AND(C38>0,E38=MAX($E$36:$E$40)),E38,0) -> 0 | G38: =E38-F38 -> 0.25 | H38: =k_Rate -> 0.28666667 | I38: =B38&CHAR(10)&"n="&C38 -> Port Harcourt n=36
B39: =Analysis!B41 -> Kano | C39: =COUNTIFS(d_Region,$B39,d_Plan,f_Plan,d_Contract,f_Contract) -> 26 | D39: =COUNTIFS(d_Region,$B39,d_Plan,f_Plan,d_Contract,f_Contract,d_Churned,"Yes") -> 9 | E39: =IF(C39=0,0,D39/C39) -> 0.34615385 | F39: =IF(AND(C39>0,E39=MAX($E$36:$E$40)),E39,0) -> 0.34615385 | G39: =E39-F39 -> 0 | H39: =k_Rate -> 0.28666667 | I39: =B39&CHAR(10)&"n="&C39 -> Kano n=26
B40: =Analysis!B42 -> Ibadan | C40: =COUNTIFS(d_Region,$B40,d_Plan,f_Plan,d_Contract,f_Contract) -> 26 | D40: =COUNTIFS(d_Region,$B40,d_Plan,f_Plan,d_Contract,f_Contract,d_Churned,"Yes") -> 6 | E40: =IF(C40=0,0,D40/C40) -> 0.23076923 | F40: =IF(AND(C40>0,E40=MAX($E$36:$E$40)),E40,0) -> 0 | G40: =E40-F40 -> 0.23076923 | H40: =k_Rate -> 0.28666667 | I40: =B40&CHAR(10)&"n="&C40 -> Ibadan n=26
B42: TENURE CHART · honours all three filters
B43: Category | C43: Customers | D43: Churned | E43: Churn rate | F43: Highlight | G43: Other | H43: Benchmark | I43: Axis label
B44: =Analysis!B47 -> 0-6 | C44: =COUNTIFS(d_Tenure,">="&Analysis!$H$47,d_Tenure,"<="&Analysis!$I$47,d_Region,f_Region,d_Plan,f_Plan,d_Contract,f_Contract) -> 24 | D44: =COUNTIFS(d_Tenure,">="&Analysis!$H$47,d_Tenure,"<="&Analysis!$I$47,d_Region,f_Region,d_Plan,f_Plan,d_Contract,f_Contract,d_Churned,"Yes") -> 9 | E44: =IF(C44=0,0,D44/C44) -> 0.375 | F44: =IF(AND(C44>0,E44=MAX($E$44:$E$47)),E44,0) -> 0.375 | G44: =E44-F44 -> 0 | H44: =k_Rate -> 0.28666667 | I44: =B44&CHAR(10)&"n="&C44 -> 0-6 n=24
B45: =Analysis!B48 -> 7-12 | C45: =COUNTIFS(d_Tenure,">="&Analysis!$H$48,d_Tenure,"<="&Analysis!$I$48,d_Region,f_Region,d_Plan,f_Plan,d_Contract,f_Contract) -> 20 | D45: =COUNTIFS(d_Tenure,">="&Analysis!$H$48,d_Tenure,"<="&Analysis!$I$48,d_Region,f_Region,d_Plan,f_Plan,d_Contract,f_Contract,d_Churned,"Yes") -> 5 | E45: =IF(C45=0,0,D45/C45) -> 0.25 | F45: =IF(AND(C45>0,E45=MAX($E$44:$E$47)),E45,0) -> 0 | G45: =E45-F45 -> 0.25 | H45: =k_Rate -> 0.28666667 | I45: =B45&CHAR(10)&"n="&C45 -> 7-12 n=20
B46: =Analysis!B49 -> 13-24 | C46: =COUNTIFS(d_Tenure,">="&Analysis!$H$49,d_Tenure,"<="&Analysis!$I$49,d_Region,f_Region,d_Plan,f_Plan,d_Contract,f_Contract) -> 56 | D46: =COUNTIFS(d_Tenure,">="&Analysis!$H$49,d_Tenure,"<="&Analysis!$I$49,d_Region,f_Region,d_Plan,f_Plan,d_Contract,f_Contract,d_Churned,"Yes") -> 12 | E46: =IF(C46=0,0,D46/C46) -> 0.21428571 | F46: =IF(AND(C46>0,E46=MAX($E$44:$E$47)),E46,0) -> 0 | G46: =E46-F46 -> 0.21428571 | H46: =k_Rate -> 0.28666667 | I46: =B46&CHAR(10)&"n="&C46 -> 13-24 n=56
B47: =Analysis!B50 -> 25+ | C47: =COUNTIFS(d_Tenure,">="&Analysis!$H$50,d_Tenure,"<="&Analysis!$I$50,d_Region,f_Region,d_Plan,f_Plan,d_Contract,f_Contract) -> 50 | D47: =COUNTIFS(d_Tenure,">="&Analysis!$H$50,d_Tenure,"<="&Analysis!$I$50,d_Region,f_Region,d_Plan,f_Plan,d_Contract,f_Contract,d_Churned,"Yes") -> 17 | E47: =IF(C47=0,0,D47/C47) -> 0.34 | F47: =IF(AND(C47>0,E47=MAX($E$44:$E$47)),E47,0) -> 0 | G47: =E47-F47 -> 0.34 | H47: =k_Rate -> 0.28666667 | I47: =B47&CHAR(10)&"n="&C47 -> 25+ n=50
...
