Workbook

Sheet Executive Summary
B2: WHERE THE NAIRA HIDES
B3: Sales Intelligence Workbook · Williams Favour Ifunanya · Favour's Analytics & Research
B4: Portfolio project · Synthetic data (160 orders, Jan–Sep 2026) · Excel + AI-assisted workflow with human validation
B6: NET REVENUE | C6: TOTAL PROFIT | D6: PROFIT MARGIN | E6: AVG ORDER VALUE | F6: AVG RATING
B7: =SUM('Sales Data'!$L$2:$L$161) -> 134241011 | C7: =SUM('Sales Data'!$N$2:$N$161) -> 32951647 | D7: =SUM('Sales Data'!$N$2:$N$161)/SUM('Sales Data'!$L$2:$L$161) -> 0.24546632 | E7: =SUM('Sales Data'!$L$2:$L$161)/COUNTA('Sales Data'!$A$2:$A$161) -> 839006.32 | F7: =AVERAGE('Sales Data'!$Q$2:$Q$161) -> 4.081875
B9: THE BUSINESS QUESTION
B10: A small electronics business needs to know where profit is made and lost across products, regions, channels and months, and which decisions are worth acting on first.
B12: WHAT THE DATA SAYS (live formulas)
B13: ="1. Concentration: "&INDEX(Insights!B7:B11,MATCH(MAX(Insights!E7:E11),Insights!E7:E11,0))&" alone brings "&TEXT(MAX(Insights!F7:F11),"0%")&" of net revenue; the top two products bring "&TEXT(LARGE(Insights!F7:F11,1)+LARGE(Insights!F7:F11,2),"0%")&"." -> 1. Concentration: Laptop alone brings 49% of net revenue; the top two products bring 81%.
B14: ="2. Hidden margin: "&INDEX(Insights!B7:B11,MATCH(MAX(Insights!H7:H11),Insights!H7:H11,0))&" earns the best margin ("&TEXT(MAX(Insights!H7:H11),"0%")&") yet makes up only "&TEXT(INDEX(Insights!F7:F11,MATCH(MAX(Insights!H7:H11),Insights!H7:H11,0)),"0%")&" of revenue." -> 2. Hidden margin: Accessories earns the best margin (38%) yet makes up only 4% of revenue.
B15: ="3. Discounts: ₦"&TEXT(Insights!E30/1000000,"0.0")&"M given away ("&TEXT(Insights!E30/Insights!D30,"0.0%")&" of gross sales). Correlation with ratings is "&TEXT(Insights!D31,"0.00")&", so deeper discounts are not buying happier customers." -> 3. Discounts: ₦7.6M given away (5.4% of gross sales). Correlation with ratings is -0.07, so deeper discounts are not buying happier customers.
B16: ="4. Rhythm: "&INDEX(Insights!B47:B55,MATCH(MAX(Insights!D47:D55),Insights!D47:D55,0))&" is the peak month and "&INDEX(Insights!B47:B55,MATCH(MIN(Insights!D47:D55),Insights!D47:D55,0))&" the trough, a "&TEXT(MAX(Insights!D47:D55)/MIN(Insights!D47:D55),"0.0")&"x swing." -> 4. Rhythm: Jun is the peak month and Apr the trough, a 3.0x swing.
B17: ="5. Geography: "&INDEX(Insights!B16:B20,MATCH(MAX(Insights!H16:H20),Insights!H16:H20,0))&" is the top region, and "&TEXT(INDEX(Insights!J16:J20,MATCH(MAX(Insights!H16:H20),Insights!H16:H20,0)),"0%")&" of its revenue comes from "&INDEX(Insights!I16:I20,MATCH(MAX(Insights!H16:H20),Insights!H16:H20,0))&"s." -> 5. Geography: Kano is the top region, and 60% of its revenue comes from Laptops.
B18: ="6. Channel: "&INDEX(Insights!B40:B43,MATCH(MAX(Insights!F40:F43),Insights!F40:F43,0))&" has the highest order value (₦"&TEXT(MAX(Insights!F40:F43)/1000,"#,##0")&"K) from only "&INDEX(Insights!C40:C43,MATCH(MAX(Insights!F40:F43),Insights!F40:F43,0))&" orders, so there may be room to scale it." -> 6. Channel: Referral has the highest order value (₦1,044K) from only 22 orders, so there may be room to scale it.
B20: THREE RECOMMENDATIONS (tested in the What-If Lab)
B21: ="Cap discounts at "&TEXT('What-If Lab'!C5,"0%") -> Cap discounts at 5% | C21: ="Scenario profit change: ₦"&TEXT('What-If Lab'!C15/1000000,"0.00")&"M, assuming "&TEXT('What-If Lab'!C6,"0%")&" of affected orders are lost." -> Scenario profit change: ₦0.74M, assuming 10% of affected orders are lost.
B22: Make accessories the attach play | C22: ="A "&TEXT('What-If Lab'!C7,"0%")&" uplift adds about ₦"&TEXT('What-If Lab'!C16/1000000,"0.00")&"M profit from existing customers." -> A 25% uplift adds about ₦0.53M profit from existing customers.
B23: De-risk concentration and slow months | C23: Push under-sold products in the most laptop-dependent region and time campaigns and stock ahead of the weakest months.
B25: WORKBOOK GUIDE (tap to jump)
B26: Dashboard | C26: Interactive KPIs and charts with Region, Product, Channel filters
B27: Insights | C27: Product, region, discount, segment, channel, month and order-size analysis
B28: What-If Lab | C28: Change the levers and see the profit impact and sensitivity
B29: Sales Data | C29: 160 transactions with calculated columns (filters on)
B30: Quality & Method | C30: Reconciliation checks, improvements, limitations, AI disclosure
B32: Data note: synthetic dataset created for demonstration and portfolio practice; not real client work. AI assisted with structure, drafting and checks; the analyst validated all outputs.

Sheet Dashboard
B2: SALES INTELLIGENCE DASHBOARD
B3: Synthetic dataset · 160 orders · Jan–Sep 2026 · Use the yellow dropdowns to filter every KPI and chart
B5: REGION | C5: All | E5: PRODUCT | F5: All | H5: CHANNEL | I5: All | P5: filter helpers → | Q5: =IF($C$5="All","*",$C$5) -> *
Q6: =IF($F$5="All","*",$F$5) -> *
B7: NET REVENUE | D7: TOTAL PROFIT | F7: PROFIT MARGIN | H7: AVG ORDER VALUE | J7: ORDERS | L7: AVG RATING | Q7: =IF($I$5="All","*",$I$5) -> *
B8: =SUMIFS('Sales Data'!$L$2:$L$161,'Sales Data'!$D$2:$D$161,$Q$5,'Sales Data'!$G$2:$G$161,$Q$6,'Sales Data'!$E$2:$E$161,$Q$7) -> 134241011 | D8: =SUMIFS('Sales Data'!$N$2:$N$161,'Sales Data'!$D$2:$D$161,$Q$5,'Sales Data'!$G$2:$G$161,$Q$6,'Sales Data'!$E$2:$E$161,$Q$7) -> 32951647 | F8: =IF(B8=0,0,D8/B8) -> 0.24546632 | H8: =IF(J8=0,0,B8/J8) -> 839006.32 | J8: =COUNTIFS('Sales Data'!$D$2:$D$161,$Q$5,'Sales Data'!$G$2:$G$161,$Q$6,'Sales Data'!$E$2:$E$161,$Q$7) -> 160 | L8: =IFERROR(AVERAGEIFS('Sales Data'!$Q$2:$Q$161,'Sales Data'!$D$2:$D$161,$Q$5,'Sales Data'!$G$2:$G$161,$Q$6,'Sales Data'!$E$2:$E$161,$Q$7),0) -> 4.081875
B9: ="Share of total: "&TEXT(IF(SUM('Sales Data'!$L$2:$L$161)=0,0,B8/SUM('Sales Data'!$L$2:$L$161)),"0%") -> Share of total: 100% | D9: ="Share of total: "&TEXT(IF(SUM('Sales Data'!$N$2:$N$161)=0,0,D8/SUM('Sales Data'!$N$2:$N$161)),"0%") -> Share of total: 100% | F9: ="Overall: "&TEXT(SUM('Sales Data'!$N$2:$N$161)/SUM('Sales Data'!$L$2:$L$161),"0.0%") -> Overall: 24.5% | H9: ="Overall: ₦"&TEXT(SUM('Sales Data'!$L$2:$L$161)/COUNTA('Sales Data'!$A$2:$A$161),"#,##0") -> Overall: ₦839,006 | J9: ="Share of orders: "&TEXT(J8/COUNTA('Sales Data'!$A$2:$A$161),"0%") -> Share of orders: 100% | L9: ="Overall: "&TEXT(AVERAGE('Sales Data'!$Q$2:$Q$161),"0.00")&" / 5" -> Overall: 4.08 / 5
B43: WHAT THE DATA SAYS (updates with your filters)
B44: =IF(MAX(C54:C62)=0,"No orders match this filter.","Rhythm: "&INDEX(B54:B62,MATCH(MAX(C54:C62),C54:C62,0))&" is the strongest month (₦"&TEXT(MAX(C54:C62)/1000000,"0.0")&"M) and "&INDEX(B54:B62,MATCH(MIN(C54:C62),C54:C62,0))&" the weakest (₦"&TEXT(MIN(C54:C62)/1000000,"0.0")&"M).") -> Rhythm: Jun is the strongest month (₦22.9M) and Apr the weakest (₦7.5M).
B45: =IF(SUM(H54:H58)=0,"","Mix: "&INDEX(G54:G58,MATCH(MAX(H54:H58),H54:H58,0))&" leads with "&TEXT(MAX(H54:H58)/SUM(H54:H58),"0%")&" of revenue; "&INDEX(G54:G58,MATCH(MAX(J54:J58),J54:J58,0))&" has the best margin ("&TEXT(MAX(J54:J58),"0%")&").") -> Mix: Laptop leads with 49% of revenue; Accessories has the best margin (38%).
B46: =IF(SUM(C65:C69)=0,"","Geography: "&INDEX(B65:B69,MATCH(MAX(C65:C69),C65:C69,0))&" is the top region with "&TEXT(MAX(C65:C69)/SUM(C65:C69),"0%")&" of revenue in this view.") -> Geography: Kano is the top region with 26% of revenue in this view.
B47: =IF(SUM(H65:H68)=0,"","Channel: "&INDEX(G65:G68,MATCH(MAX(H65:H68),H65:H68,0))&" brings the most revenue ("&TEXT(MAX(H65:H68)/SUM(H65:H68),"0%")&" of this view).") -> Channel: Online brings the most revenue (36% of this view).
B52: CHART DATA (filter-driven · feeds the charts above)
B53: Month | C53: Net Revenue | D53: Profit | E53: Margin | G53: Product | H53: Net Revenue | I53: Profit | J53: Margin
A54: 1 | B54: Jan | C54: =SUMIFS('Sales Data'!$L$2:$L$161,'Sales Data'!$D$2:$D$161,$Q$5,'Sales Data'!$G$2:$G$161,$Q$6,'Sales Data'!$E$2:$E$161,$Q$7,'Sales Data'!$C$2:$C$161,$A54) -> 17854867 | D54: =SUMIFS('Sales Data'!$N$2:$N$161,'Sales Data'!$D$2:$D$161,$Q$5,'Sales Data'!$G$2:$G$161,$Q$6,'Sales Data'!$E$2:$E$161,$Q$7,'Sales Data'!$C$2:$C$161,$A54) -> 4362595.3 | E54: =IF(C54=0,0,D54/C54) -> 0.24433647 | G54: Accessories | H54: =SUMIFS('Sales Data'!$L$2:$L$161,'Sales Data'!$D$2:$D$161,$Q$5,'Sales Data'!$E$2:$E$161,$Q$7,'Sales Data'!$G$2:$G$161,G54) -> 5583778 | I54: =SUMIFS('Sales Data'!$N$2:$N$161,'Sales Data'!$D$2:$D$161,$Q$5,'Sales Data'!$E$2:$E$161,$Q$7,'Sales Data'!$G$2:$G$161,G54) -> 2121835.6 | J54: =IF(H54=0,0,I54/H54) -> 0.38
A55: 2 | B55: Feb | C55: =SUMIFS('Sales Data'!$L$2:$L$161,'Sales Data'!$D$2:$D$161,$Q$5,'Sales Data'!$G$2:$G$161,$Q$6,'Sales Data'!$E$2:$E$161,$Q$7,'Sales Data'!$C$2:$C$161,$A55) -> 12097380 | D55: =SUMIFS('Sales Data'!$N$2:$N$161,'Sales Data'!$D$2:$D$161,$Q$5,'Sales Data'!$G$2:$G$161,$Q$6,'Sales Data'!$E$2:$E$161,$Q$7,'Sales Data'!$C$2:$C$161,$A55) -> 2978729.3 | E55: =IF(C55=0,0,D55/C55) -> 0.24622929 | G55: Laptop | H55: =SUMIFS('Sales Data'!$L$2:$L$161,'Sales Data'!$D$2:$D$161,$Q$5,'Sales Data'!$E$2:$E$161,$Q$7,'Sales Data'!$G$2:$G$161,G55) -> 65978459 | I55: =SUMIFS('Sales Data'!$N$2:$N$161,'Sales Data'!$D$2:$D$161,$Q$5,'Sales Data'!$E$2:$E$161,$Q$7,'Sales Data'!$G$2:$G$161,G55) -> 15834830 | J55: =IF(H55=0,0,I55/H55) -> 0.24
A56: 3 | B56: Mar | C56: =SUMIFS('Sales Data'!$L$2:$L$161,'Sales Data'!$D$2:$D$161,$Q$5,'Sales Data'!$G$2:$G$161,$Q$6,'Sales Data'!$E$2:$E$161,$Q$7,'Sales Data'!$C$2:$C$161,$A56) -> 16999140 | D56: =SUMIFS('Sales Data'!$N$2:$N$161,'Sales Data'!$D$2:$D$161,$Q$5,'Sales Data'!$G$2:$G$161,$Q$6,'Sales Data'!$E$2:$E$161,$Q$7,'Sales Data'!$C$2:$C$161,$A56) -> 4178289.5 | E56: =IF(C56=0,0,D56/C56) -> 0.24579417 | G56: Monitor | H56: =SUMIFS('Sales Data'!$L$2:$L$161,'Sales Data'!$D$2:$D$161,$Q$5,'Sales Data'!$E$2:$E$161,$Q$7,'Sales Data'!$G$2:$G$161,G56) -> 10056238 | I56: =SUMIFS('Sales Data'!$N$2:$N$161,'Sales Data'!$D$2:$D$161,$Q$5,'Sales Data'!$E$2:$E$161,$Q$7,'Sales Data'!$G$2:$G$161,G56) -> 3016871.4 | J56: =IF(H56=0,0,I56/H56) -> 0.3
A57: 4 | B57: Apr | C57: =SUMIFS('Sales Data'!$L$2:$L$161,'Sales Data'!$D$2:$D$161,$Q$5,'Sales Data'!$G$2:$G$161,$Q$6,'Sales Data'!$E$2:$E$161,$Q$7,'Sales Data'!$C$2:$C$161,$A57) -> 7524347 | D57: =SUMIFS('Sales Data'!$N$2:$N$161,'Sales Data'!$D$2:$D$161,$Q$5,'Sales Data'!$G$2:$G$161,$Q$6,'Sales Data'!$E$2:$E$161,$Q$7,'Sales Data'!$C$2:$C$161,$A57) -> 1807814.7 | E57: =IF(C57=0,0,D57/C57) -> 0.240262 | G57: Smartphone | H57: =SUMIFS('Sales Data'!$L$2:$L$161,'Sales Data'!$D$2:$D$161,$Q$5,'Sales Data'!$E$2:$E$161,$Q$7,'Sales Data'!$G$2:$G$161,G57) -> 42593731 | I57: =SUMIFS('Sales Data'!$N$2:$N$161,'Sales Data'!$D$2:$D$161,$Q$5,'Sales Data'!$E$2:$E$161,$Q$7,'Sales Data'!$G$2:$G$161,G57) -> 9370620.8 | J57: =IF(H57=0,0,I57/H57) -> 0.22
A58: 5 | B58: May | C58: =SUMIFS('Sales Data'!$L$2:$L$161,'Sales Data'!$D$2:$D$161,$Q$5,'Sales Data'!$G$2:$G$161,$Q$6,'Sales Data'!$E$2:$E$161,$Q$7,'Sales Data'!$C$2:$C$161,$A58) -> 12970356 | D58: =SUMIFS('Sales Data'!$N$2:$N$161,'Sales Data'!$D$2:$D$161,$Q$5,'Sales Data'!$G$2:$G$161,$Q$6,'Sales Data'!$E$2:$E$161,$Q$7,'Sales Data'!$C$2:$C$161,$A58) -> 3245399 | E58: =IF(C58=0,0,D58/C58) -> 0.25021665 | G58: Tablet | H58: =SUMIFS('Sales Data'!$L$2:$L$161,'Sales Data'!$D$2:$D$161,$Q$5,'Sales Data'!$E$2:$E$161,$Q$7,'Sales Data'!$G$2:$G$161,G58) -> 10028805 | I58: =SUMIFS('Sales Data'!$N$2:$N$161,'Sales Data'!$D$2:$D$161,$Q$5,'Sales Data'!$E$2:$E$161,$Q$7,'Sales Data'!$G$2:$G$161,G58) -> 2607489.3 | J58: =IF(H58=0,0,I58/H58) -> 0.26
A59: 6 | B59: Jun | C59: =SUMIFS('Sales Data'!$L$2:$L$161,'Sales Data'!$D$2:$D$161,$Q$5,'Sales Data'!$G$2:$G$161,$Q$6,'Sales Data'!$E$2:$E$161,$Q$7,'Sales Data'!$C$2:$C$161,$A59) -> 22937260 | D59: =SUMIFS('Sales Data'!$N$2:$N$161,'Sales Data'!$D$2:$D$161,$Q$5,'Sales Data'!$G$2:$G$161,$Q$6,'Sales Data'!$E$2:$E$161,$Q$7,'Sales Data'!$C$2:$C$161,$A59) -> 5543836.1 | E59: =IF(C59=0,0,D59/C59) -> 0.24169566
A60: 7 | B60: Jul | C60: =SUMIFS('Sales Data'!$L$2:$L$161,'Sales Data'!$D$2:$D$161,$Q$5,'Sales Data'!$G$2:$G$161,$Q$6,'Sales Data'!$E$2:$E$161,$Q$7,'Sales Data'!$C$2:$C$161,$A60) -> 12298898 | D60: =SUMIFS('Sales Data'!$N$2:$N$161,'Sales Data'!$D$2:$D$161,$Q$5,'Sales Data'!$G$2:$G$161,$Q$6,'Sales Data'!$E$2:$E$161,$Q$7,'Sales Data'!$C$2:$C$161,$A60) -> 3054556.8 | E60: =IF(C60=0,0,D60/C60) -> 0.24836021
A61: 8 | B61: Aug | C61: =SUMIFS('Sales Data'!$L$2:$L$161,'Sales Data'!$D$2:$D$161,$Q$5,'Sales Data'!$G$2:$G$161,$Q$6,'Sales Data'!$E$2:$E$161,$Q$7,'Sales Data'!$C$2:$C$161,$A61) -> 18390684 | D61: =SUMIFS('Sales Data'!$N$2:$N$161,'Sales Data'!$D$2:$D$161,$Q$5,'Sales Data'!$G$2:$G$161,$Q$6,'Sales Data'!$E$2:$E$161,$Q$7,'Sales Data'!$C$2:$C$161,$A61) -> 4440462.1 | E61: =IF(C61=0,0,D61/C61) -> 0.24145171
A62: 9 | B62: Sep | C62: =SUMIFS('Sales Data'!$L$2:$L$161,'Sales Data'!$D$2:$D$161,$Q$5,'Sales Data'!$G$2:$G$161,$Q$6,'Sales Data'!$E$2:$E$161,$Q$7,'Sales Data'!$C$2:$C$161,$A62) -> 13168079 | D62: =SUMIFS('Sales Data'!$N$2:$N$161,'Sales Data'!$D$2:$D$161,$Q$5,'Sales Data'!$G$2:$G$161,$Q$6,'Sales Data'!$E$2:$E$161,$Q$7,'Sales Data'!$C$2:$C$161,$A62) -> 3339964.5 | E62: =IF(C62=0,0,D62/C62) -> 0.25364099
B64: Region | C64: Net Revenue | D64: Profit | E64: Margin | G64: Channel | H64: Net Revenue | I64: Profit | J64: Margin
B65: Abuja | C65: =SUMIFS('Sales Data'!$L$2:$L$161,'Sales Data'!$G$2:$G$161,$Q$6,'Sales Data'!$E$2:$E$161,$Q$7,'Sales Data'!$D$2:$D$161,B65) -> 32393721 | D65: =SUMIFS('Sales Data'!$N$2:$N$161,'Sales Data'!$G$2:$G$161,$Q$6,'Sales Data'!$E$2:$E$161,$Q$7,'Sales Data'!$D$2:$D$161,B65) -> 7849497.9 | E65: =IF(C65=0,0,D65/C65) -> 0.24231541 | G65: Online | H65: =SUMIFS('Sales Data'!$L$2:$L$161,'Sales Data'!$D$2:$D$161,$Q$5,'Sales Data'!$G$2:$G$161,$Q$6,'Sales Data'!$E$2:$E$161,G65) -> 48640713 | I65: =SUMIFS('Sales Data'!$N$2:$N$161,'Sales Data'!$D$2:$D$161,$Q$5,'Sales Data'!$G$2:$G$161,$Q$6,'Sales Data'!$E$2:$E$161,G65) -> 11933062 | J65: =IF(H65=0,0,I65/H65) -> 0.24533073
B66: Ibadan | C66: =SUMIFS('Sales Data'!$L$2:$L$161,'Sales Data'!$G$2:$G$161,$Q$6,'Sales Data'!$E$2:$E$161,$Q$7,'Sales Data'!$D$2:$D$161,B66) -> 17277519 | D66: =SUMIFS('Sales Data'!$N$2:$N$161,'Sales Data'!$G$2:$G$161,$Q$6,'Sales Data'!$E$2:$E$161,$Q$7,'Sales Data'!$D$2:$D$161,B66) -> 4284288.3 | E66: =IF(C66=0,0,D66/C66) -> 0.24796895 | G66: Referral | H66: =SUMIFS('Sales Data'!$L$2:$L$161,'Sales Data'!$D$2:$D$161,$Q$5,'Sales Data'!$G$2:$G$161,$Q$6,'Sales Data'!$E$2:$E$161,G66) -> 22963625 | I66: =SUMIFS('Sales Data'!$N$2:$N$161,'Sales Data'!$D$2:$D$161,$Q$5,'Sales Data'!$G$2:$G$161,$Q$6,'Sales Data'!$E$2:$E$161,G66) -> 5471775.6 | J66: =IF(H66=0,0,I66/H66) -> 0.23828013
B67: Kano | C67: =SUMIFS('Sales Data'!$L$2:$L$161,'Sales Data'!$G$2:$G$161,$Q$6,'Sales Data'!$E$2:$E$161,$Q$7,'Sales Data'!$D$2:$D$161,B67) -> 35509711 | D67: =SUMIFS('Sales Data'!$N$2:$N$161,'Sales Data'!$G$2:$G$161,$Q$6,'Sales Data'!$E$2:$E$161,$Q$7,'Sales Data'!$D$2:$D$161,B67) -> 8740976.7 | E67: =IF(C67=0,0,D67/C67) -> 0.24615736 | G67: Retail Store | H67: =SUMIFS('Sales Data'!$L$2:$L$161,'Sales Data'!$D$2:$D$161,$Q$5,'Sales Data'!$G$2:$G$161,$Q$6,'Sales Data'!$E$2:$E$161,G67) -> 35202963 | I67: =SUMIFS('Sales Data'!$N$2:$N$161,'Sales Data'!$D$2:$D$161,$Q$5,'Sales Data'!$G$2:$G$161,$Q$6,'Sales Data'!$E$2:$E$161,G67) -> 8798601.1 | J67: =IF(H67=0,0,I67/H67) -> 0.24993922
B68: Lagos | C68: =SUMIFS('Sales Data'!$L$2:$L$161,'Sales Data'!$G$2:$G$161,$Q$6,'Sales Data'!$E$2:$E$161,$Q$7,'Sales Data'!$D$2:$D$161,B68) -> 22474912 | D68: =SUMIFS('Sales Data'!$N$2:$N$161,'Sales Data'!$G$2:$G$161,$Q$6,'Sales Data'!$E$2:$E$161,$Q$7,'Sales Data'!$D$2:$D$161,B68) -> 5424885.2 | E68: =IF(C68=0,0,D68/C68) -> 0.24137515 | G68: WhatsApp | H68: =SUMIFS('Sales Data'!$L$2:$L$161,'Sales Data'!$D$2:$D$161,$Q$5,'Sales Data'!$G$2:$G$161,$Q$6,'Sales Data'!$E$2:$E$161,G68) -> 27433710 | I68: =SUMIFS('Sales Data'!$N$2:$N$161,'Sales Data'!$D$2:$D$161,$Q$5,'Sales Data'!$G$2:$G$161,$Q$6,'Sales Data'!$E$2:$E$161,G68) -> 6748208.9 | J68: =IF(H68=0,0,I68/H68) -> 0.24598237
B69: Port Harcourt | C69: =SUMIFS('Sales Data'!$L$2:$L$161,'Sales Data'!$G$2:$G$161,$Q$6,'Sales Data'!$E$2:$E$161,$Q$7,'Sales Data'!$D$2:$D$161,B69) -> 26585148 | D69: =SUMIFS('Sales Data'!$N$2:$N$161,'Sales Data'!$G$2:$G$161,$Q$6,'Sales Data'!$E$2:$E$161,$Q$7,'Sales Data'!$D$2:$D$161,B69) -> 6651999.3 | E69: =IF(C69=0,0,D69/C69) -> 0.25021487

Sheet Insights
B2: INSIGHTS · Where the money is made and lost
B3: Whole-dataset analysis (not filtered). Every number is a live formula on the Sales Data tab.
B5: 1 · Product profitability
B6: Product | C6: Orders | D6: Units | E6: Net Revenue | F6: Revenue Share | G6: Profit | H6: Profit Margin | I6: Avg Rating | J6: Profit / Order
B7: Accessories | C7: =COUNTIFS('Sales Data'!$G$2:$G$161,$B7) -> 34 | D7: =SUMIFS('Sales Data'!$H$2:$H$161,'Sales Data'!$G$2:$G$161,$B7) -> 91 | E7: =SUMIFS('Sales Data'!$L$2:$L$161,'Sales Data'!$G$2:$G$161,$B7) -> 5583778 | F7: =E7/$E$12 -> 0.041595172 | G7: =SUMIFS('Sales Data'!$N$2:$N$161,'Sales Data'!$G$2:$G$161,$B7) -> 2121835.6 | H7: =G7/E7 -> 0.38 | I7: =AVERAGEIFS('Sales Data'!$Q$2:$Q$161,'Sales Data'!$G$2:$G$161,$B7) -> 4.0264706 | J7: =G7/C7 -> 62406.931
B8: Laptop | C8: =COUNTIFS('Sales Data'!$G$2:$G$161,$B8) -> 47 | D8: =SUMIFS('Sales Data'!$H$2:$H$161,'Sales Data'!$G$2:$G$161,$B8) -> 134 | E8: =SUMIFS('Sales Data'!$L$2:$L$161,'Sales Data'!$G$2:$G$161,$B8) -> 65978459 | F8: =E8/$E$12 -> 0.49149257 | G8: =SUMIFS('Sales Data'!$N$2:$N$161,'Sales Data'!$G$2:$G$161,$B8) -> 15834830 | H8: =G8/E8 -> 0.24 | I8: =AVERAGEIFS('Sales Data'!$Q$2:$Q$161,'Sales Data'!$G$2:$G$161,$B8) -> 4.106383 | J8: =G8/C8 -> 336911.28
B9: Monitor | C9: =COUNTIFS('Sales Data'!$G$2:$G$161,$B9) -> 18 | D9: =SUMIFS('Sales Data'!$H$2:$H$161,'Sales Data'!$G$2:$G$161,$B9) -> 58 | E9: =SUMIFS('Sales Data'!$L$2:$L$161,'Sales Data'!$G$2:$G$161,$B9) -> 10056238 | F9: =E9/$E$12 -> 0.074911817 | G9: =SUMIFS('Sales Data'!$N$2:$N$161,'Sales Data'!$G$2:$G$161,$B9) -> 3016871.4 | H9: =G9/E9 -> 0.3 | I9: =AVERAGEIFS('Sales Data'!$Q$2:$Q$161,'Sales Data'!$G$2:$G$161,$B9) -> 3.9777778 | J9: =G9/C9 -> 167603.97
B10: Smartphone | C10: =COUNTIFS('Sales Data'!$G$2:$G$161,$B10) -> 43 | D10: =SUMIFS('Sales Data'!$H$2:$H$161,'Sales Data'!$G$2:$G$161,$B10) -> 146 | E10: =SUMIFS('Sales Data'!$L$2:$L$161,'Sales Data'!$G$2:$G$161,$B10) -> 42593731 | F10: =E10/$E$12 -> 0.31729298 | G10: =SUMIFS('Sales Data'!$N$2:$N$161,'Sales Data'!$G$2:$G$161,$B10) -> 9370620.8 | H10: =G10/E10 -> 0.22 | I10: =AVERAGEIFS('Sales Data'!$Q$2:$Q$161,'Sales Data'!$G$2:$G$161,$B10) -> 4.0790698 | J10: =G10/C10 -> 217921.41
B11: Tablet | C11: =COUNTIFS('Sales Data'!$G$2:$G$161,$B11) -> 18 | D11: =SUMIFS('Sales Data'!$H$2:$H$161,'Sales Data'!$G$2:$G$161,$B11) -> 51 | E11: =SUMIFS('Sales Data'!$L$2:$L$161,'Sales Data'!$G$2:$G$161,$B11) -> 10028805 | F11: =E11/$E$12 -> 0.07470746 | G11: =SUMIFS('Sales Data'!$N$2:$N$161,'Sales Data'!$G$2:$G$161,$B11) -> 2607489.3 | H11: =G11/E11 -> 0.26 | I11: =AVERAGEIFS('Sales Data'!$Q$2:$Q$161,'Sales Data'!$G$2:$G$161,$B11) -> 4.2333333 | J11: =G11/C11 -> 144860.52
B12: Total | C12: =SUM(C7:C11) -> 160 | D12: =SUM(D7:D11) -> 480 | E12: =SUM(E7:E11) -> 134241011 | F12: =SUM(F7:F11) -> 1 | G12: =SUM(G7:G11) -> 32951647 | H12: =G12/E12 -> 0.24546632 | I12: =AVERAGE('Sales Data'!$Q$2:$Q$161) -> 4.081875 | J12: =G12/C12 -> 205947.8
B14: 2 · Region × Product heatmap (net revenue)
B15: Region | C15: Accessories | D15: Laptop | E15: Monitor | F15: Smartphone | G15: Tablet | H15: Total | I15: Top Product | J15: Top Product Share
B16: Abuja | C16: =SUMIFS('Sales Data'!$L$2:$L$161,'Sales Data'!$D$2:$D$161,$B16,'Sales Data'!$G$2:$G$161,C$15) -> 917370 | D16: =SUMIFS('Sales Data'!$L$2:$L$161,'Sales Data'!$D$2:$D$161,$B16,'Sales Data'!$G$2:$G$161,D$15) -> 15368903 | E16: =SUMIFS('Sales Data'!$L$2:$L$161,'Sales Data'!$D$2:$D$161,$B16,'Sales Data'!$G$2:$G$161,E$15) -> 1852521 | F16: =SUMIFS('Sales Data'!$L$2:$L$161,'Sales Data'!$D$2:$D$161,$B16,'Sales Data'!$G$2:$G$161,F$15) -> 11241919 | G16: =SUMIFS('Sales Data'!$L$2:$L$161,'Sales Data'!$D$2:$D$161,$B16,'Sales Data'!$G$2:$G$161,G$15) -> 3013008 | H16: =SUM(C16:G16) -> 32393721 | I16: =INDEX($C$15:$G$15,MATCH(MAX(C16:G16),C16:G16,0)) -> Laptop | J16: =MAX(C16:G16)/H16 -> 0.4744408
B17: Ibadan | C17: =SUMIFS('Sales Data'!$L$2:$L$161,'Sales Data'!$D$2:$D$161,$B17,'Sales Data'!$G$2:$G$161,C$15) -> 1082435 | D17: =SUMIFS('Sales Data'!$L$2:$L$161,'Sales Data'!$D$2:$D$161,$B17,'Sales Data'!$G$2:$G$161,D$15) -> 8595044 | E17: =SUMIFS('Sales Data'!$L$2:$L$161,'Sales Data'!$D$2:$D$161,$B17,'Sales Data'!$G$2:$G$161,E$15) -> 856060 | F17: =SUMIFS('Sales Data'!$L$2:$L$161,'Sales Data'!$D$2:$D$161,$B17,'Sales Data'!$G$2:$G$161,F$15) -> 5002510 | G17: =SUMIFS('Sales Data'!$L$2:$L$161,'Sales Data'!$D$2:$D$161,$B17,'Sales Data'!$G$2:$G$161,G$15) -> 1741470 | H17: =SUM(C17:G17) -> 17277519 | I17: =INDEX($C$15:$G$15,MATCH(MAX(C17:G17),C17:G17,0)) -> Laptop | J17: =MAX(C17:G17)/H17 -> 0.4974698
B18: Kano | C18: =SUMIFS('Sales Data'!$L$2:$L$161,'Sales Data'!$D$2:$D$161,$B18,'Sales Data'!$G$2:$G$161,C$15) -> 2183153 | D18: =SUMIFS('Sales Data'!$L$2:$L$161,'Sales Data'!$D$2:$D$161,$B18,'Sales Data'!$G$2:$G$161,D$15) -> 21244073 | E18: =SUMIFS('Sales Data'!$L$2:$L$161,'Sales Data'!$D$2:$D$161,$B18,'Sales Data'!$G$2:$G$161,E$15) -> 1734979 | F18: =SUMIFS('Sales Data'!$L$2:$L$161,'Sales Data'!$D$2:$D$161,$B18,'Sales Data'!$G$2:$G$161,F$15) -> 9951106 | G18: =SUMIFS('Sales Data'!$L$2:$L$161,'Sales Data'!$D$2:$D$161,$B18,'Sales Data'!$G$2:$G$161,G$15) -> 396400 | H18: =SUM(C18:G18) -> 35509711 | I18: =INDEX($C$15:$G$15,MATCH(MAX(C18:G18),C18:G18,0)) -> Laptop | J18: =MAX(C18:G18)/H18 -> 0.59826094
B19: Lagos | C19: =SUMIFS('Sales Data'!$L$2:$L$161,'Sales Data'!$D$2:$D$161,$B19,'Sales Data'!$G$2:$G$161,C$15) -> 392640 | D19: =SUMIFS('Sales Data'!$L$2:$L$161,'Sales Data'!$D$2:$D$161,$B19,'Sales Data'!$G$2:$G$161,D$15) -> 9587519 | E19: =SUMIFS('Sales Data'!$L$2:$L$161,'Sales Data'!$D$2:$D$161,$B19,'Sales Data'!$G$2:$G$161,E$15) -> 1804640 | F19: =SUMIFS('Sales Data'!$L$2:$L$161,'Sales Data'!$D$2:$D$161,$B19,'Sales Data'!$G$2:$G$161,F$15) -> 8653598 | G19: =SUMIFS('Sales Data'!$L$2:$L$161,'Sales Data'!$D$2:$D$161,$B19,'Sales Data'!$G$2:$G$161,G$15) -> 2036515 | H19: =SUM(C19:G19) -> 22474912 | I19: =INDEX($C$15:$G$15,MATCH(MAX(C19:G19),C19:G19,0)) -> Laptop | J19: =MAX(C19:G19)/H19 -> 0.42658761
B20: Port Harcourt | C20: =SUMIFS('Sales Data'!$L$2:$L$161,'Sales Data'!$D$2:$D$161,$B20,'Sales Data'!$G$2:$G$161,C$15) -> 1008180 | D20: =SUMIFS('Sales Data'!$L$2:$L$161,'Sales Data'!$D$2:$D$161,$B20,'Sales Data'!$G$2:$G$161,D$15) -> 11182920 | E20: =SUMIFS('Sales Data'!$L$2:$L$161,'Sales Data'!$D$2:$D$161,$B20,'Sales Data'!$G$2:$G$161,E$15) -> 3808038 | F20: =SUMIFS('Sales Data'!$L$2:$L$161,'Sales Data'!$D$2:$D$161,$B20,'Sales Data'!$G$2:$G$161,F$15) -> 7744598 | G20: =SUMIFS('Sales Data'!$L$2:$L$161,'Sales Data'!$D$2:$D$161,$B20,'Sales Data'!$G$2:$G$161,G$15) -> 2841412 | H20: =SUM(C20:G20) -> 26585148 | I20: =INDEX($C$15:$G$15,MATCH(MAX(C20:G20),C20:G20,0)) -> Laptop | J20: =MAX(C20:G20)/H20 -> 0.42064539
B21: Total | C21: =SUM(C16:C20) -> 5583778 | D21: =SUM(D16:D20) -> 65978459 | E21: =SUM(E16:E20) -> 10056238 | F21: =SUM(F16:F20) -> 42593731 | G21: =SUM(G16:G20) -> 10028805 | H21: =SUM(H16:H20) -> 134241011
B23: 3 · Discount effectiveness: what did the discounts buy?
B24: Discount Tier | C24: Orders | D24: Gross Revenue | E24: Discount Given | F24: Net Revenue | G24: Profit Margin | H24: Avg Rating | I24: Avg Order (Net)
B25: 0 | C25: =COUNTIFS('Sales Data'!$K$2:$K$161,$B25) -> 37 | D25: =SUMIFS('Sales Data'!$J$2:$J$161,'Sales Data'!$K$2:$K$161,$B25) -> 26240600 | E25: =SUMIFS('Sales Data'!$P$2:$P$161,'Sales Data'!$K$2:$K$161,$B25) -> 0 | F25: =SUMIFS('Sales Data'!$L$2:$L$161,'Sales Data'!$K$2:$K$161,$B25) -> 26240600 | G25: =SUMIFS('Sales Data'!$N$2:$N$161,'Sales Data'!$K$2:$K$161,$B25)/F25 -> 0.24532884 | H25: =AVERAGEIFS('Sales Data'!$Q$2:$Q$161,'Sales Data'!$K$2:$K$161,$B25) -> 4.0864865 | I25: =F25/C25 -> 709205.41
B26: 0.03 | C26: =COUNTIFS('Sales Data'!$K$2:$K$161,$B26) -> 25 | D26: =SUMIFS('Sales Data'!$J$2:$J$161,'Sales Data'!$K$2:$K$161,$B26) -> 24064800 | E26: =SUMIFS('Sales Data'!$P$2:$P$161,'Sales Data'!$K$2:$K$161,$B26) -> 721944 | F26: =SUMIFS('Sales Data'!$L$2:$L$161,'Sales Data'!$K$2:$K$161,$B26) -> 23342856 | G26: =SUMIFS('Sales Data'!$N$2:$N$161,'Sales Data'!$K$2:$K$161,$B26)/F26 -> 0.24314351 | H26: =AVERAGEIFS('Sales Data'!$Q$2:$Q$161,'Sales Data'!$K$2:$K$161,$B26) -> 4.172 | I26: =F26/C26 -> 933714.24
B27: 0.05 | C27: =COUNTIFS('Sales Data'!$K$2:$K$161,$B27) -> 38 | D27: =SUMIFS('Sales Data'!$J$2:$J$161,'Sales Data'!$K$2:$K$161,$B27) -> 31362700 | E27: =SUMIFS('Sales Data'!$P$2:$P$161,'Sales Data'!$K$2:$K$161,$B27) -> 1568135 | F27: =SUMIFS('Sales Data'!$L$2:$L$161,'Sales Data'!$K$2:$K$161,$B27) -> 29794565 | G27: =SUMIFS('Sales Data'!$N$2:$N$161,'Sales Data'!$K$2:$K$161,$B27)/F27 -> 0.25075201 | H27: =AVERAGEIFS('Sales Data'!$Q$2:$Q$161,'Sales Data'!$K$2:$K$161,$B27) -> 4.1236842 | I27: =F27/C27 -> 784067.5
B28: 0.08 | C28: =COUNTIFS('Sales Data'!$K$2:$K$161,$B28) -> 31 | D28: =SUMIFS('Sales Data'!$J$2:$J$161,'Sales Data'!$K$2:$K$161,$B28) -> 35337500 | E28: =SUMIFS('Sales Data'!$P$2:$P$161,'Sales Data'!$K$2:$K$161,$B28) -> 2827000 | F28: =SUMIFS('Sales Data'!$L$2:$L$161,'Sales Data'!$K$2:$K$161,$B28) -> 32510500 | G28: =SUMIFS('Sales Data'!$N$2:$N$161,'Sales Data'!$K$2:$K$161,$B28)/F28 -> 0.23817123 | H28: =AVERAGEIFS('Sales Data'!$Q$2:$Q$161,'Sales Data'!$K$2:$K$161,$B28) -> 3.9903226 | I28: =F28/C28 -> 1048725.8
B29: 0.1 | C29: =COUNTIFS('Sales Data'!$K$2:$K$161,$B29) -> 29 | D29: =SUMIFS('Sales Data'!$J$2:$J$161,'Sales Data'!$K$2:$K$161,$B29) -> 24836100 | E29: =SUMIFS('Sales Data'!$P$2:$P$161,'Sales Data'!$K$2:$K$161,$B29) -> 2483610 | F29: =SUMIFS('Sales Data'!$L$2:$L$161,'Sales Data'!$K$2:$K$161,$B29) -> 22352490 | G29: =SUMIFS('Sales Data'!$N$2:$N$161,'Sales Data'!$K$2:$K$161,$B29)/F29 -> 0.25161825 | H29: =AVERAGEIFS('Sales Data'!$Q$2:$Q$161,'Sales Data'!$K$2:$K$161,$B29) -> 4.0413793 | I29: =F29/C29 -> 770775.52
B30: Total | C30: =SUM(C25:C29) -> 160 | D30: =SUM(D25:D29) -> 141841700 | E30: =SUM(E25:E29) -> 7600689 | F30: =SUM(F25:F29) -> 134241011 | G30: =SUM('Sales Data'!$N$2:$N$161)/F30 -> 0.24546632 | H30: =AVERAGE('Sales Data'!$Q$2:$Q$161) -> 4.081875 | I30: =F30/C30 -> 839006.32
B31: Correlation: discount vs rating | D31: =CORREL('Sales Data'!$K$2:$K$161,'Sales Data'!$Q$2:$Q$161) -> -0.066589272 | E31: Near zero = deeper discounts do not buy happier customers (small sample, association only).
B33: 4 · Customer segment and sales channel
B34: Customer Segment | C34: Orders | D34: Net Revenue | E34: Revenue Share | F34: Avg Order Value | G34: Profit Margin | H34: Avg Rating
B35: New Customer | C35: =COUNTIFS('Sales Data'!$F$2:$F$161,$B35) -> 66 | D35: =SUMIFS('Sales Data'!$L$2:$L$161,'Sales Data'!$F$2:$F$161,$B35) -> 57466476 | E35: =D35/SUM('Sales Data'!$L$2:$L$161) -> 0.42808435 | F35: =D35/C35 -> 870704.18 | G35: =SUMIFS('Sales Data'!$N$2:$N$161,'Sales Data'!$F$2:$F$161,$B35)/D35 -> 0.2433995 | H35: =AVERAGEIFS('Sales Data'!$Q$2:$Q$161,'Sales Data'!$F$2:$F$161,$B35) -> 4.0590909
B36: Returning Customer | C36: =COUNTIFS('Sales Data'!$F$2:$F$161,$B36) -> 71 | D36: =SUMIFS('Sales Data'!$L$2:$L$161,'Sales Data'!$F$2:$F$161,$B36) -> 52494027 | E36: =D36/SUM('Sales Data'!$L$2:$L$161) -> 0.39104314 | F36: =D36/C36 -> 739352.49 | G36: =SUMIFS('Sales Data'!$N$2:$N$161,'Sales Data'!$F$2:$F$161,$B36)/D36 -> 0.24998753 | H36: =AVERAGEIFS('Sales Data'!$Q$2:$Q$161,'Sales Data'!$F$2:$F$161,$B36) -> 4.1253521
B37: VIP | C37: =COUNTIFS('Sales Data'!$F$2:$F$161,$B37) -> 23 | D37: =SUMIFS('Sales Data'!$L$2:$L$161,'Sales Data'!$F$2:$F$161,$B37) -> 24280508 | E37: =D37/SUM('Sales Data'!$L$2:$L$161) -> 0.18087251 | F37: =D37/C37 -> 1055674.3 | G37: =SUMIFS('Sales Data'!$N$2:$N$161,'Sales Data'!$F$2:$F$161,$B37)/D37 -> 0.24058325 | H37: =AVERAGEIFS('Sales Data'!$Q$2:$Q$161,'Sales Data'!$F$2:$F$161,$B37) -> 4.0130435
B39: Sales Channel | C39: Orders | D39: Net Revenue | E39: Revenue Share | F39: Avg Order Value | G39: Profit Margin | H39: Avg Rating
B40: Online | C40: =COUNTIFS('Sales Data'!$E$2:$E$161,$B40) -> 58 | D40: =SUMIFS('Sales Data'!$L$2:$L$161,'Sales Data'!$E$2:$E$161,$B40) -> 48640713 | E40: =D40/SUM('Sales Data'!$L$2:$L$161) -> 0.3623387 | F40: =D40/C40 -> 838632.98 | G40: =SUMIFS('Sales Data'!$N$2:$N$161,'Sales Data'!$E$2:$E$161,$B40)/D40 -> 0.24533073 | H40: =AVERAGEIFS('Sales Data'!$Q$2:$Q$161,'Sales Data'!$E$2:$E$161,$B40) -> 4.0448276
B41: Referral | C41: =COUNTIFS('Sales Data'!$E$2:$E$161,$B41) -> 22 | D41: =SUMIFS('Sales Data'!$L$2:$L$161,'Sales Data'!$E$2:$E$161,$B41) -> 22963625 | E41: =D41/SUM('Sales Data'!$L$2:$L$161) -> 0.17106266 | F41: =D41/C41 -> 1043801.1 | G41: =SUMIFS('Sales Data'!$N$2:$N$161,'Sales Data'!$E$2:$E$161,$B41)/D41 -> 0.23828013 | H41: =AVERAGEIFS('Sales Data'!$Q$2:$Q$161,'Sales Data'!$E$2:$E$161,$B41) -> 4.15
B42: Retail Store | C42: =COUNTIFS('Sales Data'!$E$2:$E$161,$B42) -> 49 | D42: =SUMIFS('Sales Data'!$L$2:$L$161,'Sales Data'!$E$2:$E$161,$B42) -> 35202963 | E42: =D42/SUM('Sales Data'!$L$2:$L$161) -> 0.26223702 | F42: =D42/C42 -> 718427.82 | G42: =SUMIFS('Sales Data'!$N$2:$N$161,'Sales Data'!$E$2:$E$161,$B42)/D42 -> 0.24993922 | H42: =AVERAGEIFS('Sales Data'!$Q$2:$Q$161,'Sales Data'!$E$2:$E$161,$B42) -> 4.0897959
B43: WhatsApp | C43: =COUNTIFS('Sales Data'!$E$2:$E$161,$B43) -> 31 | D43: =SUMIFS('Sales Data'!$L$2:$L$161,'Sales Data'!$E$2:$E$161,$B43) -> 27433710 | E43: =D43/SUM('Sales Data'!$L$2:$L$161) -> 0.20436162 | F43: =D43/C43 -> 884958.39 | G43: =SUMIFS('Sales Data'!$N$2:$N$161,'Sales Data'!$E$2:$E$161,$B43)/D43 -> 0.24598237 | H43: =AVERAGEIFS('Sales Data'!$Q$2:$Q$161,'Sales Data'!$E$2:$E$161,$B43) -> 4.0903226
B45: 5 · Monthly performance (all nine months, rebuilt from transactions)
B46: Month | C46: Orders | D46: Net Revenue | E46: Profit | F46: Profit Margin | G46: MoM Change | H46: vs Monthly Average
A47: 1 | B47: Jan | C47: =COUNTIFS('Sales Data'!$C$2:$C$161,$A47) -> 22 | D47: =SUMIFS('Sales Data'!$L$2:$L$161,'Sales Data'!$C$2:$C$161,$A47) -> 17854867 | E47: =SUMIFS('Sales Data'!$N$2:$N$161,'Sales Data'!$C$2:$C$161,$A47) -> 4362595.3 | F47: =E47/D47 -> 0.24433647 | H47: =D47/AVERAGE($D$47:$D$55)-1 -> 0.19705448
...

Sheet What-If Lab
B2: WHAT-IF LAB · Test the recommendations
B3: Change the yellow cells (blue text = your inputs). Everything below recalculates. Scenarios are illustrative, not forecasts.
B4: 1 · Levers & assumptions
B5: Discount cap (max discount allowed) | C5: 0.05 | D5: Orders above the cap are re-priced at the cap
B6: Order volume lost where the discount is cut | C6: 0.1 | D6: Conservative default: 1 in 10 affected orders walks away
B7: Accessories sales uplift (bundling / attach) | C7: 0.25 | D7: Applied to current accessories revenue and profit
B8: Large-order threshold (net ₦) | C8: 1500000 | D8: Used for Order Tier on Sales Data
B9: Medium-order threshold (net ₦) | C9: 500000 | D9: Orders below this are tagged Small
B11: 2 · Scenario result
B12: Base net revenue | C12: =SUM('Sales Data'!$L$2:$L$161) -> 134241011
B13: Base profit | C13: =SUM('Sales Data'!$N$2:$N$161) -> 32951647
B14: Base profit margin | C14: =IF(C12=0,0,C13/C12) -> 0.24546632
B15: Profit change · discount cap | C15: =SUMPRODUCT(('Sales Data'!$K$2:$K$161>$C$5+0.0001)*(('Sales Data'!$J$2:$J$161*(1-$C$5)-'Sales Data'!$M$2:$M$161)*(1-$C$6)-'Sales Data'!$N$2:$N$161)) -> 735000.97
B16: Profit change · accessories uplift | C16: =SUMIFS('Sales Data'!$N$2:$N$161,'Sales Data'!$G$2:$G$161,"Accessories")*$C$7 -> 530458.91
B17: Scenario profit | C17: =C13+C15+C16 -> 34217107 | D17: ← headline
B18: Profit improvement | C18: =IF(C13=0,0,C17/C13-1) -> 0.038403539
B19: Net revenue change | C19: =SUMPRODUCT(('Sales Data'!$K$2:$K$161>$C$5+0.0001)*('Sales Data'!$J$2:$J$161*(1-$C$5)*(1-$C$6)-'Sales Data'!$L$2:$L$161))+SUMIFS('Sales Data'!$L$2:$L$161,'Sales Data'!$G$2:$G$161,"Accessories")*$C$7 -> -2018617.5
B20: Scenario profit margin | C20: =IF((C12+C19)=0,0,C17/(C12+C19)) -> 0.25878451
B22: 3 · Sensitivity: profit change from a discount cap (₦) — how wrong can the volume assumption be?
B23: Discount cap ↓ | Order volume lost → | C23: 0 | D23: 0.05 | E23: 0.1 | F23: 0.2
B24: 0.1 | C24: =SUMPRODUCT(('Sales Data'!$K$2:$K$161>$B24+0.0001)*(('Sales Data'!$J$2:$J$161*(1-$B24)-'Sales Data'!$M$2:$M$161)*(1-C$23)-'Sales Data'!$N$2:$N$161)) -> 0 | D24: =SUMPRODUCT(('Sales Data'!$K$2:$K$161>$B24+0.0001)*(('Sales Data'!$J$2:$J$161*(1-$B24)-'Sales Data'!$M$2:$M$161)*(1-D$23)-'Sales Data'!$N$2:$N$161)) -> 0 | E24: =SUMPRODUCT(('Sales Data'!$K$2:$K$161>$B24+0.0001)*(('Sales Data'!$J$2:$J$161*(1-$B24)-'Sales Data'!$M$2:$M$161)*(1-E$23)-'Sales Data'!$N$2:$N$161)) -> 0 | F24: =SUMPRODUCT(('Sales Data'!$K$2:$K$161>$B24+0.0001)*(('Sales Data'!$J$2:$J$161*(1-$B24)-'Sales Data'!$M$2:$M$161)*(1-F$23)-'Sales Data'!$N$2:$N$161)) -> 0
B25: 0.08 | C25: =SUMPRODUCT(('Sales Data'!$K$2:$K$161>$B25+0.0001)*(('Sales Data'!$J$2:$J$161*(1-$B25)-'Sales Data'!$M$2:$M$161)*(1-C$23)-'Sales Data'!$N$2:$N$161)) -> 496722 | D25: =SUMPRODUCT(('Sales Data'!$K$2:$K$161>$B25+0.0001)*(('Sales Data'!$J$2:$J$161*(1-$B25)-'Sales Data'!$M$2:$M$161)*(1-D$23)-'Sales Data'!$N$2:$N$161)) -> 190671.18 | E25: =SUMPRODUCT(('Sales Data'!$K$2:$K$161>$B25+0.0001)*(('Sales Data'!$J$2:$J$161*(1-$B25)-'Sales Data'!$M$2:$M$161)*(1-E$23)-'Sales Data'!$N$2:$N$161)) -> -115379.64 | F25: =SUMPRODUCT(('Sales Data'!$K$2:$K$161>$B25+0.0001)*(('Sales Data'!$J$2:$J$161*(1-$B25)-'Sales Data'!$M$2:$M$161)*(1-F$23)-'Sales Data'!$N$2:$N$161)) -> -727481.28
B26: 0.05 | C26: =SUMPRODUCT(('Sales Data'!$K$2:$K$161>$B26+0.0001)*(('Sales Data'!$J$2:$J$161*(1-$B26)-'Sales Data'!$M$2:$M$161)*(1-C$23)-'Sales Data'!$N$2:$N$161)) -> 2301930 | D26: =SUMPRODUCT(('Sales Data'!$K$2:$K$161>$B26+0.0001)*(('Sales Data'!$J$2:$J$161*(1-$B26)-'Sales Data'!$M$2:$M$161)*(1-D$23)-'Sales Data'!$N$2:$N$161)) -> 1518465.5 | E26: =SUMPRODUCT(('Sales Data'!$K$2:$K$161>$B26+0.0001)*(('Sales Data'!$J$2:$J$161*(1-$B26)-'Sales Data'!$M$2:$M$161)*(1-E$23)-'Sales Data'!$N$2:$N$161)) -> 735000.97 | F26: =SUMPRODUCT(('Sales Data'!$K$2:$K$161>$B26+0.0001)*(('Sales Data'!$J$2:$J$161*(1-$B26)-'Sales Data'!$M$2:$M$161)*(1-F$23)-'Sales Data'!$N$2:$N$161)) -> -831928.06
B27: 0.03 | C27: =SUMPRODUCT(('Sales Data'!$K$2:$K$161>$B27+0.0001)*(('Sales Data'!$J$2:$J$161*(1-$B27)-'Sales Data'!$M$2:$M$161)*(1-C$23)-'Sales Data'!$N$2:$N$161)) -> 4132656 | D27: =SUMPRODUCT(('Sales Data'!$K$2:$K$161>$B27+0.0001)*(('Sales Data'!$J$2:$J$161*(1-$B27)-'Sales Data'!$M$2:$M$161)*(1-D$23)-'Sales Data'!$N$2:$N$161)) -> 2884102.8 | E27: =SUMPRODUCT(('Sales Data'!$K$2:$K$161>$B27+0.0001)*(('Sales Data'!$J$2:$J$161*(1-$B27)-'Sales Data'!$M$2:$M$161)*(1-E$23)-'Sales Data'!$N$2:$N$161)) -> 1635549.7 | F27: =SUMPRODUCT(('Sales Data'!$K$2:$K$161>$B27+0.0001)*(('Sales Data'!$J$2:$J$161*(1-$B27)-'Sales Data'!$M$2:$M$161)*(1-F$23)-'Sales Data'!$N$2:$N$161)) -> -861556.66
B28: 0 | C28: =SUMPRODUCT(('Sales Data'!$K$2:$K$161>$B28+0.0001)*(('Sales Data'!$J$2:$J$161*(1-$B28)-'Sales Data'!$M$2:$M$161)*(1-C$23)-'Sales Data'!$N$2:$N$161)) -> 7600689 | D28: =SUMPRODUCT(('Sales Data'!$K$2:$K$161>$B28+0.0001)*(('Sales Data'!$J$2:$J$161*(1-$B28)-'Sales Data'!$M$2:$M$161)*(1-D$23)-'Sales Data'!$N$2:$N$161)) -> 5894951 | E28: =SUMPRODUCT(('Sales Data'!$K$2:$K$161>$B28+0.0001)*(('Sales Data'!$J$2:$J$161*(1-$B28)-'Sales Data'!$M$2:$M$161)*(1-E$23)-'Sales Data'!$N$2:$N$161)) -> 4189213 | F28: =SUMPRODUCT(('Sales Data'!$K$2:$K$161>$B28+0.0001)*(('Sales Data'!$J$2:$J$161*(1-$B28)-'Sales Data'!$M$2:$M$161)*(1-F$23)-'Sales Data'!$N$2:$N$161)) -> 777736.94
B29: Reading it: where the cell turns red, cutting discounts loses more profit than it gains, so the volume assumption is the risk to watch.

Sheet Sales Data
A1: Order ID | B1: Order Date | C1: Month No | D1: Region | E1: Sales Channel | F1: Customer Segment | G1: Product | H1: Quantity | I1: Unit Price (₦) | J1: Gross Revenue (₦) | K1: Discount | L1: Net Revenue (₦) | M1: Cost (₦) | N1: Profit (₦) | O1: Profit Margin | P1: Discount Given (₦) | Q1: Customer Rating | R1: Order Tier
A2: ORD-0001 | B2: 46144 | C2: =MONTH(B2) -> 5 | D2: Port Harcourt | E2: Online | F2: New Customer | G2: Accessories | H2: 1 | I2: 61900 | J2: =H2*I2 -> 61900 | K2: 0.1 | L2: =J2*(1-K2) -> 55710 | M2: 34540.2 | N2: =L2-M2 -> 21169.8 | O2: =IF(L2=0,0,N2/L2) -> 0.38 | P2: =J2-L2 -> 6190 | Q2: 4.6 | R2: =IF(L2>='What-If Lab'!$C$8,"Large",IF(L2>='What-If Lab'!$C$9,"Medium","Small")) -> Small
A3: ORD-0002 | B3: 46282 | C3: =MONTH(B3) -> 9 | D3: Ibadan | E3: Online | F3: New Customer | G3: Accessories | H3: 4 | I3: 60500 | J3: =H3*I3 -> 242000 | K3: 0.03 | L3: =J3*(1-K3) -> 234740 | M3: 145538.8 | N3: =L3-M3 -> 89201.2 | O3: =IF(L3=0,0,N3/L3) -> 0.38 | P3: =J3-L3 -> 7260 | Q3: 4.7 | R3: =IF(L3>='What-If Lab'!$C$8,"Large",IF(L3>='What-If Lab'!$C$9,"Medium","Small")) -> Small
A4: ORD-0003 | B4: 46138 | C4: =MONTH(B4) -> 4 | D4: Kano | E4: Online | F4: New Customer | G4: Laptop | H4: 3 | I4: 518000 | J4: =H4*I4 -> 1554000 | K4: 0.03 | L4: =J4*(1-K4) -> 1507380 | M4: 1145608.8 | N4: =L4-M4 -> 361771.2 | O4: =IF(L4=0,0,N4/L4) -> 0.24 | P4: =J4-L4 -> 46620 | Q4: 4.2 | R4: =IF(L4>='What-If Lab'!$C$8,"Large",IF(L4>='What-If Lab'!$C$9,"Medium","Small")) -> Large
A5: ORD-0004 | B5: 46191 | C5: =MONTH(B5) -> 6 | D5: Lagos | E5: WhatsApp | F5: VIP | G5: Tablet | H5: 5 | I5: 191900 | J5: =H5*I5 -> 959500 | K5: 0.03 | L5: =J5*(1-K5) -> 930715 | M5: 688729.1 | N5: =L5-M5 -> 241985.9 | O5: =IF(L5=0,0,N5/L5) -> 0.26 | P5: =J5-L5 -> 28785 | Q5: 4.3 | R5: =IF(L5>='What-If Lab'!$C$8,"Large",IF(L5>='What-If Lab'!$C$9,"Medium","Small")) -> Medium
A6: ORD-0005 | B6: 46250 | C6: =MONTH(B6) -> 8 | D6: Abuja | E6: Online | F6: Returning Customer | G6: Laptop | H6: 5 | I6: 559100 | J6: =H6*I6 -> 2795500 | K6: 0.05 | L6: =J6*(1-K6) -> 2655725 | M6: 2018351 | N6: =L6-M6 -> 637374 | O6: =IF(L6=0,0,N6/L6) -> 0.24 | P6: =J6-L6 -> 139775 | Q6: 3.2 | R6: =IF(L6>='What-If Lab'!$C$8,"Large",IF(L6>='What-If Lab'!$C$9,"Medium","Small")) -> Large
A7: ORD-0006 | B7: 46294 | C7: =MONTH(B7) -> 9 | D7: Abuja | E7: Retail Store | F7: Returning Customer | G7: Accessories | H7: 4 | I7: 67300 | J7: =H7*I7 -> 269200 | K7: 0.1 | L7: =J7*(1-K7) -> 242280 | M7: 150213.6 | N7: =L7-M7 -> 92066.4 | O7: =IF(L7=0,0,N7/L7) -> 0.38 | P7: =J7-L7 -> 26920 | Q7: 3.2 | R7: =IF(L7>='What-If Lab'!$C$8,"Large",IF(L7>='What-If Lab'!$C$9,"Medium","Small")) -> Small
A8: ORD-0007 | B8: 46049 | C8: =MONTH(B8) -> 1 | D8: Lagos | E8: Online | F8: Returning Customer | G8: Monitor | H8: 4 | I8: 166900 | J8: =H8*I8 -> 667600 | K8: 0 | L8: =J8*(1-K8) -> 667600 | M8: 467320 | N8: =L8-M8 -> 200280 | O8: =IF(L8=0,0,N8/L8) -> 0.3 | P8: =J8-L8 -> 0 | Q8: 3.9 | R8: =IF(L8>='What-If Lab'!$C$8,"Large",IF(L8>='What-If Lab'!$C$9,"Medium","Small")) -> Medium
A9: ORD-0008 | B9: 46051 | C9: =MONTH(B9) -> 1 | D9: Port Harcourt | E9: WhatsApp | F9: New Customer | G9: Smartphone | H9: 5 | I9: 329500 | J9: =H9*I9 -> 1647500 | K9: 0.08 | L9: =J9*(1-K9) -> 1515700 | M9: 1182246 | N9: =L9-M9 -> 333454 | O9: =IF(L9=0,0,N9/L9) -> 0.22 | P9: =J9-L9 -> 131800 | Q9: 4.1 | R9: =IF(L9>='What-If Lab'!$C$8,"Large",IF(L9>='What-If Lab'!$C$9,"Medium","Small")) -> Large
A10: ORD-0009 | B10: 46203 | C10: =MONTH(B10) -> 6 | D10: Kano | E10: WhatsApp | F10: Returning Customer | G10: Laptop | H10: 5 | I10: 476600 | J10: =H10*I10 -> 2383000 | K10: 0.08 | L10: =J10*(1-K10) -> 2192360 | M10: 1666193.6 | N10: =L10-M10 -> 526166.4 | O10: =IF(L10=0,0,N10/L10) -> 0.24 | P10: =J10-L10 -> 190640 | Q10: 4.9 | R10: =IF(L10>='What-If Lab'!$C$8,"Large",IF(L10>='What-If Lab'!$C$9,"Medium","Small")) -> Large
A11: ORD-0010 | B11: 46068 | C11: =MONTH(B11) -> 2 | D11: Ibadan | E11: Online | F11: Returning Customer | G11: Laptop | H11: 1 | I11: 533600 | J11: =H11*I11 -> 533600 | K11: 0.03 | L11: =J11*(1-K11) -> 517592 | M11: 393369.92 | N11: =L11-M11 -> 124222.08 | O11: =IF(L11=0,0,N11/L11) -> 0.24 | P11: =J11-L11 -> 16008 | Q11: 3.7 | R11: =IF(L11>='What-If Lab'!$C$8,"Large",IF(L11>='What-If Lab'!$C$9,"Medium","Small")) -> Medium
A12: ORD-0011 | B12: 46067 | C12: =MONTH(B12) -> 2 | D12: Kano | E12: Online | F12: New Customer | G12: Smartphone | H12: 2 | I12: 292400 | J12: =H12*I12 -> 584800 | K12: 0.03 | L12: =J12*(1-K12) -> 567256 | M12: 442459.68 | N12: =L12-M12 -> 124796.32 | O12: =IF(L12=0,0,N12/L12) -> 0.22 | P12: =J12-L12 -> 17544 | Q12: 4.3 | R12: =IF(L12>='What-If Lab'!$C$8,"Large",IF(L12>='What-If Lab'!$C$9,"Medium","Small")) -> Medium
A13: ORD-0012 | B13: 46236 | C13: =MONTH(B13) -> 8 | D13: Abuja | E13: Referral | F13: New Customer | G13: Tablet | H13: 4 | I13: 225500 | J13: =H13*I13 -> 902000 | K13: 0.1 | L13: =J13*(1-K13) -> 811800 | M13: 600732 | N13: =L13-M13 -> 211068 | O13: =IF(L13=0,0,N13/L13) -> 0.26 | P13: =J13-L13 -> 90200 | Q13: 4.4 | R13: =IF(L13>='What-If Lab'!$C$8,"Large",IF(L13>='What-If Lab'!$C$9,"Medium","Small")) -> Medium
... A161: ORD-0160 | B161: 46172 | C161: =MONTH(B161) -> 5 | D161: Kano | E161: Retail Store | F161: Returning Customer | G161: Laptop | H161: 3 | I161: 556500 | J161: =H161*I161 -> 1669500 | K161: 0.05 | L161: =J161*(1-K161) -> 1586025 | M161: 1205379 | N161: =L161-M161 -> 380646 | O161: =IF(L161=0,0,N161/L161) -> 0.24 | P161: =J161-L161 -> 83475 | Q161: 4.5 | R161: =IF(L161>='What-If Lab'!$C$8,"Large",IF(L161>='What-If Lab'!$C$9,"Medium","Small")) -> Large

Sheet Quality & Method
B2: QUALITY & METHOD · Why you can trust these numbers
B4: 1 · Automated reconciliation checks
B5: Check | C5: This workbook | D5: Reference | E5: Status | F5: Source of reference
B6: Net revenue ties to original report | C6: =SUM('Sales Data'!$L$2:$L$161) -> 134241011 | D6: 134241011 | E6: =IF(ABS(C6-D6)<=1,"PASS","CHECK") -> PASS | F6: Original file, Dashboard & Analysis tabs
B7: Total profit ties to original report | C7: =SUM('Sales Data'!$N$2:$N$161) -> 32951647 | D7: 32951647 | E7: =IF(ABS(C7-D7)<=1,"PASS","CHECK") -> PASS | F7: Original file, Dashboard tab
B8: Order count | C8: =COUNTA('Sales Data'!$A$2:$A$161) -> 160 | D8: 160 | E8: =IF(ABS(C8-D8)<=0,"PASS","CHECK") -> PASS | F8: Original file, Analysis tab (Total Orders)
B9: Average rating ties to original | C9: =AVERAGE('Sales Data'!$Q$2:$Q$161) -> 4.081875 | D9: 4.081875 | E9: =IF(ABS(C9-D9)<=0.0001,"PASS","CHECK") -> PASS | F9: Original file, Analysis tab
B10: Unique order IDs (no duplicates) | C10: =SUMPRODUCT(1/COUNTIF('Sales Data'!$A$2:$A$161,'Sales Data'!$A$2:$A$161)) -> 160 | D10: 160 | E10: =IF(ABS(C10-D10)<=0.001,"PASS","CHECK") -> PASS | F10: Expected: every ID appears once
B11: Blank cells in raw inputs | C11: =COUNTBLANK('Sales Data'!$A$2:$I$161)+COUNTBLANK('Sales Data'!$K$2:$K$161)+COUNTBLANK('Sales Data'!$M$2:$M$161)+COUNTBLANK('Sales Data'!$Q$2:$Q$161) -> 0 | D11: 0 | E11: =IF(ABS(C11-D11)<=0,"PASS","CHECK") -> PASS | F11: Expected: none
B12: Monthly totals add up to total | C12: =Insights!D56 -> 134241011 | D12: =SUM('Sales Data'!$L$2:$L$161) -> 134241011 | E12: =IF(ABS(C12-D12)<=1,"PASS","CHECK") -> PASS | F12: Insights tab vs Sales Data
B13: Region totals add up to total | C13: =Insights!H21 -> 134241011 | D13: =SUM('Sales Data'!$L$2:$L$161) -> 134241011 | E13: =IF(ABS(C13-D13)<=1,"PASS","CHECK") -> PASS | F13: Insights heatmap vs Sales Data
B14: Ratings all between 1 and 5 | C14: =COUNTIFS('Sales Data'!$Q$2:$Q$161,">=1",'Sales Data'!$Q$2:$Q$161,"<=5") -> 160 | D14: 160 | E14: =IF(ABS(C14-D14)<=0,"PASS","CHECK") -> PASS | F14: Validity range
B15: Dates all fall in Jan–Sep 2026 | C15: =COUNTIFS('Sales Data'!$B$2:$B$161,">="&DATE(2026,1,1),'Sales Data'!$B$2:$B$161,"<="&DATE(2026,9,30)) -> 160 | D15: 160 | E15: =IF(ABS(C15-D15)<=0,"PASS","CHECK") -> PASS | F15: Expected reporting window
B16: Discount values are valid tiers (0/3/5/8/10%) | C16: =SUM(Insights!C25:C29) -> 160 | D16: 160 | E16: =IF(ABS(C16-D16)<=0,"PASS","CHECK") -> PASS | F16: Every order sits in a known tier
B17: Overall | E17: =IF(COUNTIF(E6:E16,"PASS")=11,"ALL PASS","REVIEW") -> ALL PASS
B19: 2 · What I improved versus the original report
B20: • Replaced hard-coded results with live formulas (SUMIFS, COUNTIFS, AVERAGEIFS, SUMPRODUCT, INDEX/MATCH) so the workbook recalculates when data changes.
B21: • Found that the original dashboard monthly table skipped July and August (the notes sat on those rows). All nine months are now rebuilt from the transactions.
B22: • Gross, net, profit, margin and discount-given are now formulas on the raw inputs (blue = typed inputs, black = formulas) instead of pasted values.
B23: • Added interactive filters (Region, Product, Channel), a what-if model with sensitivity table, discount-effectiveness analysis and an order-size tier analysis.
B24: • Added this reconciliation panel so any reviewer can see the numbers tie to the original report.
B26: 3 · Method
B27: • 1) Audit the source data and reconcile totals. 2) Add calculated columns (month, margin, discount given, order tier). 3) Build KPI and breakdown tables. 4) Test relationships (discount vs rating, region x product). 5) Model scenarios with explicit assumptions. 6) Translate findings into three prioritised recommendations.
B29: 4 · Limitations and honest disclosure
B30: • Synthetic dataset of 160 transactions created for portfolio practice. It is not real client data and results should not be generalised.
B31: • Findings show association, not causation. A correlation of about -0.07 between discount and rating suggests no visible benefit, but a larger real dataset would be needed to prove it.
B32: • The what-if lab assumes simple behaviour (a fixed share of affected orders lost). The sensitivity table shows how conclusions change if that assumption is wrong.
B33: • AI assistance supported project structuring, synthetic-data logic, insight drafting and quality checking. The analyst validated every output.
